Workbook

Sheet Sheet1
A1: Time point | B1: A1 | C1: A2 | D1: A3 | E1: A4 | F1: A5 | G1: A6 | H1: A7 | I1: A8 | J1: A9 | K1: A10 | L1: A11 | M1: A12 | N1: B1 | O1: B2 | P1: B3 | Q1: B4 | R1: B5 | S1: B6 | T1: B7 | U1: B8 | V1: B9 | W1: B10 | X1: B11 | Y1: B12 | Z1: C1 | AA1: C2 | AB1: C3 | AC1: C4 | AD1: C5 | AE1: C6 | AF1: C7 | AG1: C8 | AH1: C9 | AI1: C10 | AJ1: C11 | AK1: C12 | AL1: D1 | AM1: D2 | AN1: D3 | AO1: D4 | AP1: D5 | AQ1: D6 | AR1: D7 | AS1: D8 | AT1: D9 | AU1: D10 | AV1: D11 | AW1: D12 | AX1: E1 | AY1: E2 | AZ1: E3 | BA1: E4 | BB1: E5 | BC1: E6 | BD1: E7 | BE1: E8 | BF1: E9 | BG1: E10 | BH1: E11 | BI1: E12 | BJ1: F1 | BK1: F2 | BL1: F3 | BM1: F4 | BN1: F5 | BO1: F6 | BP1: F7 | BQ1: F8 | BR1: F9 | BS1: F10 | BT1: F11 | BU1: F12 | BV1: G1 | BW1: G2 | BX1: G3 | BY1: G4 | BZ1: G5 | CA1: G6 | CB1: G7 | CC1: G8 | CD1: G9 | CE1: G10 | CF1: G11 | CG1: G12 | CH1: H1 | CI1: H2 | CJ1: H3 | CK1: H4 | CL1: H5 | CM1: H6 | CN1: H7 | CO1: H8 | CP1: H9 | CQ1: H10 | CR1: H11 | CS1: H12
A2: 0.020717593 | B2: 0.1608 | C2: 0.1289 | D2: 0.0873 | E2: 0.1272 | F2: 0.1348 | G2: 0.1328 | H2: 0.1415 | I2: 0.1303 | J2: 0.1399 | K2: 0.1294 | L2: 0.1326 | M2: 0.1237 | N2: 0.1558 | O2: 0.1269 | P2: 0.1591 | Q2: 0.1265 | R2: 0.1342 | S2: 0.1324 | T2: 0.1418 | U2: 0.1315 | V2: 0.143 | W2: 0.1297 | X2: 0.1314 | Y2: 0.1231 | Z2: 0.1656 | AA2: 0.1352 | AB2: 0.1698 | AC2: 0.126 | AD2: 0.1337 | AE2: 0.1343 | AF2: 0.1413 | AG2: 0.1303 | AH2: 0.1406 | AI2: 0.129 | AJ2: 0.127 | AK2: 0.1238 | AL2: 0.1632 | AM2: 0.1233 | AN2: 0.1597 | AO2: 0.1231 | AP2: 0.1376 | AQ2: 0.137 | AR2: 0.1395 | AS2: 0.1266 | AT2: 0.1446 | AU2: 0.1304 | AV2: 0.1317 | AW2: 0.129 | AX2: 0.1487 | AY2: 0.1003 | AZ2: 0.1368 | BA2: 0.1229 | BB2: 0.1182 | BC2: 0.1201 | BD2: 0.149 | BE2: 0.1859 | BF2: 0.146 | BG2: 0.0855 | BH2: 0.0864 | BI2: 0.0884 | BJ2: 0.1601 | BK2: 0.1059 | BL2: 0.1442 | BM2: 0.1176 | BN2: 0.1147 | BO2: 0.1188 | BP2: 0.1414 | BQ2: 0.1803 | BR2: 0.1393 | BS2: 0.0865 | BT2: 0.0876 | BU2: 0.09 | BV2: 0.1471 | BW2: 0.1071 | BX2: 0.1419 | BY2: 0.1197 | BZ2: 0.1194 | CA2: 0.1187 | CB2: 0.1445 | CC2: 0.1798 | CD2: 0.1423 | CE2: 0.0859 | CF2: 0.0889 | CG2: 0.0868 | CH2: 0.1566 | CI2: 0.1131 | CJ2: 0.1409 | CK2: 0.1589 | CL2: 0.1221 | CM2: 0.1195 | CN2: 0.1425 | CO2: 0.1854 | CP2: 0.138 | CQ2: 0.0872 | CR2: 0.0875 | CS2: 0.0859
A3: 0.041550926 | B3: 0.1661 | C3: 0.1303 | D3: 0.0872 | E3: 0.1268 | F3: 0.1375 | G3: 0.1408 | H3: 0.1487 | I3: 0.1331 | J3: 0.1407 | K3: 0.131 | L3: 0.1359 | M3: 0.1263 | N3: 0.1657 | O3: 0.1327 | P3: 0.1878 | Q3: 0.1282 | R3: 0.137 | S3: 0.1429 | T3: 0.1495 | U3: 0.1448 | V3: 0.148 | W3: 0.1371 | X3: 0.1392 | Y3: 0.1271 | Z3: 0.1728 | AA3: 0.1391 | AB3: 0.1985 | AC3: 0.1281 | AD3: 0.1353 | AE3: 0.1469 | AF3: 0.1474 | AG3: 0.1348 | AH3: 0.145 | AI3: 0.1402 | AJ3: 0.1311 | AK3: 0.1285 | AL3: 0.1646 | AM3: 0.127 | AN3: 0.1884 | AO3: 0.1263 | AP3: 0.1425 | AQ3: 0.1573 | AR3: 0.1487 | AS3: 0.1312 | AT3: 0.1478 | AU3: 0.1385 | AV3: 0.1439 | AW3: 0.1329 | AX3: 0.1598 | AY3: 0.1008 | AZ3: 0.146 | BA3: 0.1258 | BB3: 0.1168 | BC3: 0.1197 | BD3: 0.1627 | BE3: 0.2112 | BF3: 0.1574 | BG3: 0.0853 | BH3: 0.0864 | BI3: 0.0877 | BJ3: 0.1684 | BK3: 0.1072 | BL3: 0.1511 | BM3: 0.1194 | BN3: 0.1141 | BO3: 0.1195 | BP3: 0.1565 | BQ3: 0.2091 | BR3: 0.1498 | BS3: 0.0864 | BT3: 0.0873 | BU3: 0.0901 | BV3: 0.1567 | BW3: 0.1064 | BX3: 0.1497 | BY3: 0.1233 | BZ3: 0.1196 | CA3: 0.1191 | CB3: 0.1576 | CC3: 0.2005 | CD3: 0.155 | CE3: 0.0853 | CF3: 0.0892 | CG3: 0.0864 | CH3: 0.1701 | CI3: 0.1135 | CJ3: 0.1482 | CK3: 0.1624 | CL3: 0.1232 | CM3: 0.1198 | CN3: 0.1549 | CO3: 0.2138 | CP3: 0.144 | CQ3: 0.087 | CR3: 0.0871 | CS3: 0.0858
A4: 0.062384259 | B4: 0.1764 | C4: 0.1343 | D4: 0.0874 | E4: 0.1283 | F4: 0.1407 | G4: 0.1493 | H4: 0.155 | I4: 0.1357 | J4: 0.141 | K4: 0.1318 | L4: 0.1394 | M4: 0.1309 | N4: 0.1746 | O4: 0.1388 | P4: 0.2235 | Q4: 0.1311 | R4: 0.1392 | S4: 0.156 | T4: 0.1582 | U4: 0.1589 | V4: 0.1511 | W4: 0.1432 | X4: 0.1492 | Y4: 0.1337 | Z4: 0.1819 | AA4: 0.1445 | AB4: 0.2328 | AC4: 0.1303 | AD4: 0.1386 | AE4: 0.1637 | AF4: 0.1563 | AG4: 0.1391 | AH4: 0.1497 | AI4: 0.1469 | AJ4: 0.1387 | AK4: 0.1356 | AL4: 0.1728 | AM4: 0.1319 | AN4: 0.226 | AO4: 0.1298 | AP4: 0.1481 | AQ4: 0.1834 | AR4: 0.1579 | AS4: 0.1372 | AT4: 0.1512 | AU4: 0.1443 | AV4: 0.1597 | AW4: 0.1417 | AX4: 0.1733 | AY4: 0.1002 | AZ4: 0.1567 | BA4: 0.1294 | BB4: 0.1178 | BC4: 0.1197 | BD4: 0.1815 | BE4: 0.2418 | BF4: 0.1694 | BG4: 0.0854 | BH4: 0.0861 | BI4: 0.0875 | BJ4: 0.1844 | BK4: 0.1106 | BL4: 0.1634 | BM4: 0.1221 | BN4: 0.115 | BO4: 0.1208 | BP4: 0.1718 | BQ4: 0.2431 | BR4: 0.1607 | BS4: 0.0859 | BT4: 0.0875 | BU4: 0.0898 | BV4: 0.1741 | BW4: 0.1064 | BX4: 0.1626 | BY4: 0.1269 | BZ4: 0.1202 | CA4: 0.1199 | CB4: 0.1773 | CC4: 0.2307 | CD4: 0.1658 | CE4: 0.0862 | CF4: 0.0884 | CG4: 0.0867 | CH4: 0.1879 | CI4: 0.1154 | CJ4: 0.1612 | CK4: 0.1651 | CL4: 0.1231 | CM4: 0.1213 | CN4: 0.1686 | CO4: 0.24 | CP4: 0.1513 | CQ4: 0.0871 | CR4: 0.0872 | CS4: 0.0856
A5: 0.083217593 | B5: 0.192 | C5: 0.1381 | D5: 0.0875 | E5: 0.1304 | F5: 0.1443 | G5: 0.1619 | H5: 0.1603 | I5: 0.1378 | J5: 0.1434 | K5: 0.133 | L5: 0.1427 | M5: 0.1389 | N5: 0.19 | O5: 0.1466 | P5: 0.2618 | Q5: 0.1332 | R5: 0.1441 | S5: 0.1726 | T5: 0.168 | U5: 0.1704 | V5: 0.1557 | W5: 0.1466 | X5: 0.1566 | Y5: 0.1437 | Z5: 0.1989 | AA5: 0.1513 | AB5: 0.2721 | AC5: 0.1329 | AD5: 0.1415 | AE5: 0.1832 | AF5: 0.165 | AG5: 0.1455 | AH5: 0.1551 | AI5: 0.1531 | AJ5: 0.1482 | AK5: 0.1452 | AL5: 0.1848 | AM5: 0.1417 | AN5: 0.2641 | AO5: 0.135 | AP5: 0.1553 | AQ5: 0.2123 | AR5: 0.1694 | AS5: 0.1437 | AT5: 0.1555 | AU5: 0.15 | AV5: 0.175 | AW5: 0.1515 | AX5: 0.1864 | AY5: 0.1006 | AZ5: 0.1728 | BA5: 0.1325 | BB5: 0.1177 | BC5: 0.1208 | BD5: 0.1993 | BE5: 0.2674 | BF5: 0.1798 | BG5: 0.0853 | BH5: 0.0863 | BI5: 0.0874 | BJ5: 0.196 | BK5: 0.1171 | BL5: 0.1817 | BM5: 0.1257 | BN5: 0.1144 | BO5: 0.1209 | BP5: 0.1904 | BQ5: 0.2711 | BR5: 0.1706 | BS5: 0.0868 | BT5: 0.0872 | BU5: 0.0898 | BV5: 0.1881 | BW5: 0.1064 | BX5: 0.1816 | BY5: 0.1299 | BZ5: 0.1199 | CA5: 0.1209 | CB5: 0.1989 | CC5: 0.254 | CD5: 0.1753 | CE5: 0.0858 | CF5: 0.0894 | CG5: 0.0861 | CH5: 0.2039 | CI5: 0.115 | CJ5: 0.1788 | CK5: 0.1664 | CL5: 0.1214 | CM5: 0.1206 | CN5: 0.1877 | CO5: 0.2607 | CP5: 0.1619 | CQ5: 0.087 | CR5: 0.087 | CS5: 0.0858
A6: 0.10405093 | B6: 0.2103 | C6: 0.1463 | D6: 0.0876 | E6: 0.1332 | F6: 0.1496 | G6: 0.1725 | H6: 0.1668 | I6: 0.1394 | J6: 0.1473 | K6: 0.1351 | L6: 0.1453 | M6: 0.1479 | N6: 0.2115 | O6: 0.1568 | P6: 0.3038 | Q6: 0.1356 | R6: 0.1479 | S6: 0.1895 | T6: 0.1754 | U6: 0.1796 | V6: 0.1609 | W6: 0.149 | X6: 0.164 | Y6: 0.1553 | Z6: 0.2148 | AA6: 0.1622 | AB6: 0.3113 | AC6: 0.1362 | AD6: 0.1456 | AE6: 0.2052 | AF6: 0.1741 | AG6: 0.1512 | AH6: 0.1609 | AI6: 0.1596 | AJ6: 0.1575 | AK6: 0.1598 | AL6: 0.2015 | AM6: 0.1506 | AN6: 0.3021 | AO6: 0.1406 | AP6: 0.1643 | AQ6: 0.2437 | AR6: 0.1809 | AS6: 0.1495 | AT6: 0.1612 | AU6: 0.1573 | AV6: 0.1904 | AW6: 0.1652 | AX6: 0.1954 | AY6: 0.1011 | AZ6: 0.1904 | BA6: 0.1345 | BB6: 0.118 | BC6: 0.1217 | BD6: 0.2192 | BE6: 0.2865 | BF6: 0.1887 | BG6: 0.0852 | BH6: 0.0866 | BI6: 0.0872 | BJ6: 0.2044 | BK6: 0.1093 | BL6: 0.1992 | BM6: 0.1275 | BN6: 0.1148 | BO6: 0.1214 | BP6: 0.2113 | BQ6: 0.296 | BR6: 0.1809 | BS6: 0.0862 | BT6: 0.0872 | BU6: 0.0901 | BV6: 0.2035 | BW6: 0.1065 | BX6: 0.2003 | BY6: 0.1343 | BZ6: 0.1193 | CA6: 0.1215 | CB6: 0.221 | CC6: 0.2719 | CD6: 0.1845 | CE6: 0.086 | CF6: 0.0886 | CG6: 0.0864 | CH6: 0.2175 | CI6: 0.1162 | CJ6: 0.1963 | CK6: 0.1671 | CL6: 0.1206 | CM6: 0.1214 | CN6: 0.2079 | CO6: 0.2845 | CP6: 0.1712 | CQ6: 0.0874 | CR6: 0.0866 | CS6: 0.0859
A7: 0.12488426 | B7: 0.2362 | C7: 0.1563 | D7: 0.0872 | E7: 0.1375 | F7: 0.1584 | G7: 0.1843 | H7: 0.1744 | I7: 0.1406 | J7: 0.1525 | K7: 0.1382 | L7: 0.149 | M7: 0.1565 | N7: 0.2332 | O7: 0.1684 | P7: 0.3433 | Q7: 0.1388 | R7: 0.1531 | S7: 0.2118 | T7: 0.1839 | U7: 0.1893 | V7: 0.169 | W7: 0.152 | X7: 0.1736 | Y7: 0.1644 | Z7: 0.234 | AA7: 0.1751 | AB7: 0.3481 | AC7: 0.1396 | AD7: 0.1511 | AE7: 0.2319 | AF7: 0.186 | AG7: 0.1571 | AH7: 0.1693 | AI7: 0.168 | AJ7: 0.1682 | AK7: 0.171 | AL7: 0.2224 | AM7: 0.1628 | AN7: 0.3404 | AO7: 0.1473 | AP7: 0.1743 | AQ7: 0.2793 | AR7: 0.1936 | AS7: 0.1554 | AT7: 0.1696 | AU7: 0.1641 | AV7: 0.2053 | AW7: 0.175 | AX7: 0.2063 | AY7: 0.1012 | AZ7: 0.2038 | BA7: 0.1379 | BB7: 0.1182 | BC7: 0.1216 | BD7: 0.2345 | BE7: 0.3027 | BF7: 0.1977 | BG7: 0.0855 | BH7: 0.0864 | BI7: 0.087 | BJ7: 0.2136 | BK7: 0.1122 | BL7: 0.2148 | BM7: 0.1323 | BN7: 0.1148 | BO7: 0.1231 | BP7: 0.2247 | BQ7: 0.3211 | BR7: 0.1886 | BS7: 0.0866 | BT7: 0.0873 | BU7: 0.0901 | BV7: 0.2148 | BW7: 0.1062 | BX7: 0.2155 | BY7: 0.1387 | BZ7: 0.1189 | CA7: 0.1221 | CB7: 0.2386 | CC7: 0.2898 | CD7: 0.1899 | CE7: 0.0856 | CF7: 0.0891 | CG7: 0.0866 | CH7: 0.2308 | CI7: 0.1167 | CJ7: 0.212 | CK7: 0.1676 | CL7: 0.122 | CM7: 0.1218 | CN7: 0.2251 | CO7: 0.3079 | CP7: 0.1783 | CQ7: 0.0867 | CR7: 0.0874 | CS7: 0.0859
A8: 0.14571759 | B8: 0.2626 | C8: 0.1627 | D8: 0.0877 | E8: 0.1413 | F8: 0.1678 | G8: 0.199 | H8: 0.1824 | I8: 0.142 | J8: 0.1582 | K8: 0.1442 | L8: 0.1541 | M8: 0.1714 | N8: 0.2575 | O8: 0.1836 | P8: 0.3795 | Q8: 0.1414 | R8: 0.1587 | S8: 0.2365 | T8: 0.1913 | U8: 0.1979 | V8: 0.1791 | W8: 0.1571 | X8: 0.1849 | Y8: 0.1802 | Z8: 0.2559 | AA8: 0.19 | AB8: 0.3844 | AC8: 0.1427 | AD8: 0.1571 | AE8: 0.2606 | AF8: 0.1987 | AG8: 0.163 | AH8: 0.1801 | AI8: 0.1748 | AJ8: 0.1785 | AK8: 0.1888 | AL8: 0.2444 | AM8: 0.178 | AN8: 0.375 | AO8: 0.1543 | AP8: 0.187 | AQ8: 0.3144 | AR8: 0.2062 | AS8: 0.1591 | AT8: 0.1783 | AU8: 0.1705 | AV8: 0.2195 | AW8: 0.1939 | AX8: 0.2212 | AY8: 0.1018 | AZ8: 0.2148 | BA8: 0.1416 | BB8: 0.1171 | BC8: 0.1218 | BD8: 0.2555 | BE8: 0.3215 | BF8: 0.2077 | BG8: 0.0852 | BH8: 0.0866 | BI8: 0.0872 | BJ8: 0.2302 | BK8: 0.1163 | BL8: 0.2271 | BM8: 0.1371 | BN8: 0.1155 | BO8: 0.1224 | BP8: 0.2516 | BQ8: 0.347 | BR8: 0.1964 | BS8: 0.0861 | BT8: 0.0875 | BU8: 0.0902 | BV8: 0.2268 | BW8: 0.1063 | BX8: 0.2273 | BY8: 0.1437 | BZ8: 0.1201 | CA8: 0.1231 | CB8: 0.2559 | CC8: 0.3076 | CD8: 0.1959 | CE8: 0.0859 | CF8: 0.0885 | CG8: 0.087 | CH8: 0.2483 | CI8: 0.118 | CJ8: 0.2232 | CK8: 0.1702 | CL8: 0.1222 | CM8: 0.1214 | CN8: 0.2472 | CO8: 0.3299 | CP8: 0.188 | CQ8: 0.087 | CR8: 0.0872 | CS8: 0.0858
A9: 0.16655093 | B9: 0.2902 | C9: 0.1801 | D9: 0.0876 | E9: 0.1454 | F9: 0.1769 | G9: 0.2134 | H9: 0.1858 | I9: 0.1426 | J9: 0.1637 | K9: 0.1477 | L9: 0.1587 | M9: 0.1851 | N9: 0.2844 | O9: 0.197 | P9: 0.4038 | Q9: 0.1434 | R9: 0.1648 | S9: 0.2524 | T9: 0.2001 | U9: 0.2041 | V9: 0.1918 | W9: 0.161 | X9: 0.1941 | Y9: 0.1965 | Z9: 0.2822 | AA9: 0.2061 | AB9: 0.4125 | AC9: 0.146 | AD9: 0.1638 | AE9: 0.283 | AF9: 0.2066 | AG9: 0.1691 | AH9: 0.1953 | AI9: 0.1809 | AJ9: 0.1857 | AK9: 0.2047 | AL9: 0.2726 | AM9: 0.193 | AN9: 0.4032 | AO9: 0.1611 | AP9: 0.2 | AQ9: 0.337 | AR9: 0.2174 | AS9: 0.1662 | AT9: 0.1937 | AU9: 0.1769 | AV9: 0.2308 | AW9: 0.2102 | AX9: 0.2376 | AY9: 0.1026 | AZ9: 0.2229 | BA9: 0.1463 | BB9: 0.1185 | BC9: 0.1226 | BD9: 0.2781 | BE9: 0.3377 | BF9: 0.2153 | BG9: 0.0854 | BH9: 0.0869 | BI9: 0.087 | BJ9: 0.2429 | BK9: 0.1169 | BL9: 0.2343 | BM9: 0.1409 | BN9: 0.1136 | BO9: 0.1239 | BP9: 0.2768 | BQ9: 0.3638 | BR9: 0.2023 | BS9: 0.0862 | BT9: 0.0873 | BU9: 0.0903 | BV9: 0.2388 | BW9: 0.1065 | BX9: 0.2359 | BY9: 0.1485 | BZ9: 0.1186 | CA9: 0.1236 | CB9: 0.2831 | CC9: 0.3232 | CD9: 0.2026 | CE9: 0.0858 | CF9: 0.0887 | CG9: 0.087 | CH9: 0.2633 | CI9: 0.123 | CJ9: 0.2329 | CK9: 0.1718 | CL9: 0.123 | CM9: 0.1218 | CN9: 0.2785 | CO9: 0.3463 | CP9: 0.1972 | CQ9: 0.087 | CR9: 0.0872 | CS9: 0.0861
A10: 0.18738426 | B10: 0.3123 | C10: 0.1939 | D10: 0.0874 | E10: 0.147 | F10: 0.1894 | G10: 0.2287 | H10: 0.1925 | I10: 0.144 | J10: 0.1726 | K10: 0.1538 | L10: 0.1678 | M10: 0.2067 | N10: 0.3044 | O10: 0.2099 | P10: 0.442 | Q10: 0.1464 | R10: 0.1737 | S10: 0.2729 | T10: 0.2068 | U10: 0.2093 | V10: 0.2077 | W10: 0.1646 | X10: 0.2065 | Y10: 0.2171 | Z10: 0.3029 | AA10: 0.2222 | AB10: 0.4501 | AC10: 0.1509 | AD10: 0.1716 | AE10: 0.3036 | AF10: 0.2183 | AG10: 0.1729 | AH10: 0.2116 | AI10: 0.1885 | AJ10: 0.1933 | AK10: 0.2252 | AL10: 0.2956 | AM10: 0.2106 | AN10: 0.4366 | AO10: 0.1685 | AP10: 0.2165 | AQ10: 0.364 | AR10: 0.2284 | AS10: 0.1695 | AT10: 0.208 | AU10: 0.1835 | AV10: 0.2418 | AW10: 0.2349 | AX10: 0.2546 | AY10: 0.1035 | AZ10: 0.2308 | BA10: 0.1509 | BB10: 0.118 | BC10: 0.1232 | BD10: 0.3107 | BE10: 0.3554 | BF10: 0.224 | BG10: 0.0855 | BH10: 0.0866 | BI10: 0.0876 | BJ10: 0.2625 | BK10: 0.1167 | BL10: 0.2435 | BM10: 0.1464 | BN10: 0.115 | BO10: 0.1255 | BP10: 0.3009 | BQ10: 0.3884 | BR10: 0.2097 | BS10: 0.0863 | BT10: 0.0876 | BU10: 0.0903 | BV10: 0.252 | BW10: 0.1067 | BX10: 0.2408 | BY10: 0.1547 | BZ10: 0.1193 | CA10: 0.1244 | CB10: 0.3113 | CC10: 0.3383 | CD10: 0.2099 | CE10: 0.0855 | CF10: 0.0891 | CG10: 0.0865 | CH10: 0.2827 | CI10: 0.1268 | CJ10: 0.24 | CK10: 0.176 | CL10: 0.1235 | CM10: 0.1233 | CN10: 0.3122 | CO10: 0.3747 | CP10: 0.2045 | CQ10: 0.0878 | CR10: 0.0871 | CS10: 0.0861
A11: 0.20821759 | B11: 0.3759 | C11: 0.2144 | D11: 0.0874 | E11: 0.1513 | F11: 0.1987 | G11: 0.2458 | H11: 0.1919 | I11: 0.1444 | J11: 0.1854 | K11: 0.1569 | L11: 0.174 | M11: 0.2358 | N11: 0.3236 | O11: 0.2217 | P11: 0.4589 | Q11: 0.1506 | R11: 0.1805 | S11: 0.2863 | T11: 0.2154 | U11: 0.2161 | V11: 0.2271 | W11: 0.1705 | X11: 0.2122 | Y11: 0.2454 | Z11: 0.3223 | AA11: 0.2359 | AB11: 0.47 | AC11: 0.1571 | AD11: 0.18 | AE11: 0.3185 | AF11: 0.2247 | AG11: 0.1772 | AH11: 0.2308 | AI11: 0.1937 | AJ11: 0.1991 | AK11: 0.2546 | AL11: 0.3149 | AM11: 0.2229 | AN11: 0.458 | AO11: 0.1765 | AP11: 0.231 | AQ11: 0.3789 | AR11: 0.2376 | AS11: 0.1752 | AT11: 0.2274 | AU11: 0.1894 | AV11: 0.2469 | AW11: 0.2639 | AX11: 0.2747 | AY11: 0.1043 | AZ11: 0.2381 | BA11: 0.1561 | BB11: 0.1181 | BC11: 0.1238 | BD11: 0.3329 | BE11: 0.3708 | BF11: 0.231 | BG11: 0.085 | BH11: 0.0867 | BI11: 0.0872 | BJ11: 0.2757 | BK11: 0.1203 | BL11: 0.2487 | BM11: 0.1519 | BN11: 0.1149 | BO11: 0.1256 | BP11: 0.3207 | BQ11: 0.4076 | BR11: 0.2149 | BS11: 0.0862 | BT11: 0.0874 | BU11: 0.0903 | BV11: 0.2645 | BW11: 0.1071 | BX11: 0.2482 | BY11: 0.1593 | BZ11: 0.1184 | CA11: 0.1248 | CB11: 0.3384 | CC11: 0.3543 | CD11: 0.2161 | CE11: 0.0863 | CF11: 0.0885 | CG11: 0.0863 | CH11: 0.2988 | CI11: 0.1297 | CJ11: 0.247 | CK11: 0.1802 | CL11: 0.1235 | CM11: 0.1228 | CN11: 0.3291 | CO11: 0.4003 | CP11: 0.2137 | CQ11: 0.0874 | CR11: 0.0876 | CS11: 0.086
A12: 0.22905093 | B12: 0.4078 | C12: 0.2305 | D12: 0.0878 | E12: 0.1535 | F12: 0.215 | G12: 0.2629 | H12: 0.2054 | I12: 0.1452 | J12: 0.1987 | K12: 0.1686 | L12: 0.1919 | M12: 0.265 | N12: 0.3661 | O12: 0.2353 | P12: 0.4901 | Q12: 0.1553 | R12: 0.1893 | S12: 0.3049 | T12: 0.2244 | U12: 0.2211 | V12: 0.2517 | W12: 0.1764 | X12: 0.2246 | Y12: 0.27 | Z12: 0.3774 | AA12: 0.2527 | AB12: 0.5048 | AC12: 0.1619 | AD12: 0.1882 | AE12: 0.3383 | AF12: 0.2322 | AG12: 0.1824 | AH12: 0.2555 | AI12: 0.2003 | AJ12: 0.2055 | AK12: 0.2825 | AL12: 0.3581 | AM12: 0.2386 | AN12: 0.4845 | AO12: 0.1837 | AP12: 0.245 | AQ12: 0.4023 | AR12: 0.2461 | AS12: 0.1783 | AT12: 0.2479 | AU12: 0.1955 | AV12: 0.2571 | AW12: 0.2894 | AX12: 0.2934 | AY12: 0.1058 | AZ12: 0.2473 | BA12: 0.1599 | BB12: 0.1193 | BC12: 0.1244 | BD12: 0.3636 | BE12: 0.3799 | BF12: 0.2402 | BG12: 0.0857 | BH12: 0.0864 | BI12: 0.0871 | BJ12: 0.2965 | BK12: 0.1169 | BL12: 0.2597 | BM12: 0.1555 | BN12: 0.1158 | BO12: 0.1266 | BP12: 0.351 | BQ12: 0.4266 | BR12: 0.2238 | BS12: 0.0859 | BT12: 0.0878 | BU12: 0.0904 | BV12: 0.2838 | BW12: 0.1073 | BX12: 0.2566 | BY12: 0.1651 | BZ12: 0.119 | CA12: 0.1263 | CB12: 0.3661 | CC12: 0.3629 | CD12: 0.2265 | CE12: 0.0862 | CF12: 0.0887 | CG12: 0.0862 | CH12: 0.3227 | CI12: 0.1293 | CJ12: 0.2563 | CK12: 0.1828 | CL12: 0.1255 | CM12: 0.1229 | CN12: 0.3662 | CO12: 0.4165 | CP12: 0.2246 | CQ12: 0.0877 | CR12: 0.087 | CS12: 0.0864
A13: 0.24988426 | B13: 0.4658 | C13: 0.2426 | D13: 0.0877 | E13: 0.1566 | F13: 0.2277 | G13: 0.2799 | H13: 0.2091 | I13: 0.1462 | J13: 0.2175 | K13: 0.1732 | L13: 0.2058 | M13: 0.2896 | N13: 0.4106 | O13: 0.2471 | P13: 0.5151 | Q13: 0.1602 | R13: 0.1988 | S13: 0.3198 | T13: 0.2321 | U13: 0.2256 | V13: 0.2723 | W13: 0.1812 | X13: 0.2325 | Y13: 0.2963 | Z13: 0.412 | AA13: 0.2652 | AB13: 0.5265 | AC13: 0.1683 | AD13: 0.196 | AE13: 0.3523 | AF13: 0.2381 | AG13: 0.1874 | AH13: 0.2766 | AI13: 0.206 | AJ13: 0.2093 | AK13: 0.3041 | AL13: 0.4086 | AM13: 0.2506 | AN13: 0.5105 | AO13: 0.1906 | AP13: 0.2563 | AQ13: 0.4146 | AR13: 0.2549 | AS13: 0.1832 | AT13: 0.2698 | AU13: 0.2006 | AV13: 0.2606 | AW13: 0.3129 | AX13: 0.3138 | AY13: 0.1066 | AZ13: 0.257 | BA13: 0.1645 | BB13: 0.1201 | BC13: 0.125 | BD13: 0.391 | BE13: 0.3984 | BF13: 0.2475 | BG13: 0.0854 | BH13: 0.0864 | BI13: 0.0876 | BJ13: 0.3119 | BK13: 0.1208 | BL13: 0.2707 | BM13: 0.162 | BN13: 0.1166 | BO13: 0.1277 | BP13: 0.3781 | BQ13: 0.4488 | BR13: 0.2295 | BS13: 0.0861 | BT13: 0.087 | BU13: 0.0908 | BV13: 0.3028 | BW13: 0.1078 | BX13: 0.2683 | BY13: 0.1693 | BZ13: 0.1185 | CA13: 0.1267 | CB13: 0.3985 | CC13: 0.373 | CD13: 0.2321 | CE13: 0.0859 | CF13: 0.0889 | CG13: 0.0863 | CH13: 0.3475 | CI13: 0.1326 | CJ13: 0.2634 | CK13: 0.1862 | CL13: 0.1265 | CM13: 0.1239 | CN13: 0.3903 | CO13: 0.434 | CP13: 0.2337 | CQ13: 0.0878 | CR13: 0.0871 | CS13: 0.086
... A233: 4.8332176 | B233: 0.097 | C233: 0.1787 | D233: 0.0877 | E233: 0.6729 | F233: 0.2646 | G233: 1.3666 | H233: 1.3323 | I233: 0.7345 | J233: 0.8893 | K233: 0.2835 | L233: 0.5406 | M233: 0.193 | N233: 0.2515 | O233: 0.3384 | P233: 0.7037 | Q233: 0.4922 | R233: 0.3405 | S233: 0.8935 | T233: 0.8257 | U233: 0.5773 | V233: 0.6921 | W233: 0.3749 | X233: 0.5391 | Y233: 0.3402 | Z233: 0.3367 | AA233: 0.3162 | AB233: 0.6947 | AC233: 0.4892 | AD233: 0.332 | AE233: 0.8461 | AF233: 0.7251 | AG233: 0.5224 | AH233: 0.6691 | AI233: 0.369 | AJ233: 0.5392 | AK233: 0.3313 | AL233: 0.3294 | AM233: 0.3201 | AN233: 0.7155 | AO233: 0.4868 | AP233: 0.3413 | AQ233: 0.7294 | AR233: 0.7671 | AS233: 0.5349 | AT233: 0.6909 | AU233: 0.3625 | AV233: 0.5454 | AW233: 0.3821 | AX233: 0.5599 | AY233: 0.1598 | AZ233: 0.5495 | BA233: 0.4137 | BB233: 0.2026 | BC233: 0.1966 | BD233: 0.5694 | BE233: 0.5522 | BF233: 0.4979 | BG233: 0.0849 | BH233: 0.0857 | BI233: 0.0883 | BJ233: 0.5543 | BK233: 0.1521 | BL233: 0.5438 | BM233: 0.3996 | BN233: 0.23 | BO233: 0.193 | BP233: 0.5741 | BQ233: 0.5503 | BR233: 0.5159 | BS233: 0.0858 | BT233: 0.0872 | BU233: 0.0911 | BV233: 0.5956 | BW233: 0.4284 | BX233: 0.5405 | BY233: 0.4678 | BZ233: 0.2626 | CA233: 0.1793 | CB233: 0.6023 | CC233: 0.5225 | CD233: 0.5212 | CE233: 0.0857 | CF233: 0.0884 | CG233: 0.0857 | CH233: 0.1262 | CI233: 0.1121 | CJ233: 0.7977 | CK233: 0.2946 | CL233: 0.181 | CM233: 0.1531 | CN233: 0.8432 | CO233: 0.7033 | CP233: 0.721 | CQ233: 0.0866 | CR233: 0.0868 | CS233: 0.0868

Sheet Sheet2
A1: Well | B1: Strain | E1: Time point
A2: A7 | B2: Bradyrhizobium_6478 | E2: A1 | F2: =VLOOKUP(E2,A:B,2,0) -> Variovorax_6146
A3: B7 | B3: Bradyrhizobium_6478 | E3: A2 | F3: =VLOOKUP(E3,A:B,2,0) -> Flavobacterium_6147
A4: C7 | B4: Bradyrhizobium_6478 | E4: A3 | F4: =VLOOKUP(E4,A:B,2,0) -> Microbacterium_6150
A5: D7 | B5: Bradyrhizobium_6478 | E5: A4 | F5: =VLOOKUP(E5,A:B,2,0) -> Mucilaginibacter_6152
A6: E7 | B6: Burkholderia_6699 | E6: A5 | F6: =VLOOKUP(E6,A:B,2,0) -> Curtobacterium_6155
A7: F7 | B7: Burkholderia_6699 | E7: A6 | F7: =VLOOKUP(E7,A:B,2,0) -> Rhodococcus_6477
A8: G7 | B8: Burkholderia_6699 | E8: A7 | F8: =VLOOKUP(E8,A:B,2,0) -> Bradyrhizobium_6478
A9: H7 | B9: Burkholderia_6699 | E9: A8 | F9: =VLOOKUP(E9,A:B,2,0) -> Cellulomonas_6483
A10: E2 | B10: Caulobacter_6537 | E10: A9 | F10: =VLOOKUP(E10,A:B,2,0) -> Luteibacter_6500
A11: F2 | B11: Caulobacter_6537 | E11: A10 | F11: =VLOOKUP(E11,A:B,2,0) -> Phenylobacterium_6508
A12: G2 | B12: Caulobacter_6537 | E12: A11 | F12: =VLOOKUP(E12,A:B,2,0) -> Mesorhizobium_6519
A13: H2 | B13: Caulobacter_6537 | E13: A12 | F13: =VLOOKUP(E13,A:B,2,0) -> Lysobacter_6525
... A89: D8 | B89: Cellulomonas_6483 | E89: H4 | F89: =VLOOKUP(E89,A:B,2,0) -> Cohnella_6695
E90: H5 | F90: =VLOOKUP(E90,A:B,2,0) -> Devosia_6593
E91: H6 | F91: =VLOOKUP(E91,A:B,2,0) -> Tardiphaga_6697
E92: H7 | F92: =VLOOKUP(E92,A:B,2,0) -> Burkholderia_6699
E93: H8 | F93: =VLOOKUP(E93,A:B,2,0) -> Rahnella_6700
E94: H9 | F94: =VLOOKUP(E94,A:B,2,0) -> Chitinophaga_spread
E95: H10 | F95: =VLOOKUP(E95,A:B,2,0) -> #N/A
E96: H11 | F96: =VLOOKUP(E96,A:B,2,0) -> #N/A
E97: H12 | F97: =VLOOKUP(E97,A:B,2,0) -> #N/A

Sheet Data
A1: Time (hours) | B1: Variovorax_6146 | C1: Flavobacterium_6147 | D1: Microbacterium_6150 | E1: Mucilaginibacter_6152 | F1: Curtobacterium_6155 | G1: Rhodococcus_6477 | H1: Bradyrhizobium_6478 | I1: Cellulomonas_6483 | J1: Luteibacter_6500 | K1: Phenylobacterium_6508 | L1: Mesorhizobium_6519 | M1: Lysobacter_6525 | N1: Variovorax_6146 | O1: Flavobacterium_6147 | P1: Microbacterium_6150 | Q1: Mucilaginibacter_6152 | R1: Curtobacterium_6155 | S1: Rhodococcus_6477 | T1: Bradyrhizobium_6478 | U1: Cellulomonas_6483 | V1: Luteibacter_6500 | W1: Phenylobacterium_6508 | X1: Mesorhizobium_6519 | Y1: Lysobacter_6525 | Z1: Variovorax_6146 | AA1: Flavobacterium_6147 | AB1: Microbacterium_6150 | AC1: Mucilaginibacter_6152 | AD1: Curtobacterium_6155 | AE1: Rhodococcus_6477 | AF1: Bradyrhizobium_6478 | AG1: Cellulomonas_6483 | AH1: Luteibacter_6500 | AI1: Phenylobacterium_6508 | AJ1: Mesorhizobium_6519 | AK1: Lysobacter_6525 | AL1: Variovorax_6146 | AM1: Flavobacterium_6147 | AN1: Microbacterium_6150 | AO1: Mucilaginibacter_6152 | AP1: Curtobacterium_6155 | AQ1: Rhodococcus_6477 | AR1: Bradyrhizobium_6478 | AS1: Cellulomonas_6483 | AT1: Luteibacter_6500 | AU1: Phenylobacterium_6508 | AV1: Mesorhizobium_6519 | AW1: Lysobacter_6525 | AX1: Pseudomonas2_6533 | AY1: Caulobacter_6537 | AZ1: Pseudomonas1_6551 | BA1: Cohnella_6695 | BB1: Devosia_6593 | BC1: Tardiphaga_6697 | BD1: Burkholderia_6699 | BE1: Rahnella_6700 | BF1: Chitinophaga_spread | BG1: Pseudomonas2_6533 | BH1: Caulobacter_6537 | BI1: Pseudomonas1_6551 | BJ1: Cohnella_6695 | BK1: Devosia_6593 | BL1: Tardiphaga_6697 | BM1: Burkholderia_6699 | BN1: Rahnella_6700 | BO1: Chitinophaga_spread | BP1: Pseudomonas2_6533 | BQ1: Caulobacter_6537 | BR1: Pseudomonas1_6551 | BS1: Cohnella_6695 | BT1: Devosia_6593 | BU1: Tardiphaga_6697 | BV1: Burkholderia_6699 | BW1: Rahnella_6700 | BX1: Chitinophaga_spread | BY1: Pseudomonas2_6533 | BZ1: Caulobacter_6537 | CA1: Pseudomonas1_6551 | CB1: Cohnella_6695 | CC1: Devosia_6593 | CD1: Tardiphaga_6697 | CE1: Burkholderia_6699 | CF1: Rahnella_6700 | CG1: Chitinophaga_spread
A2: =HOUR(Sheet1!A2) + MINUTE(Sheet1!A2)/60 + SECOND(Sheet1!A2)/3600 -> 0.49722222 | B2: =Sheet1!B2-AVERAGE(Sheet1!$BG2:$BI2) -> 0.074033333 | C2: =Sheet1!C2-AVERAGE(Sheet1!$BG2:$BI2) -> 0.042133333 | D2: =Sheet1!D2-AVERAGE(Sheet1!$BG2:$BI2) -> 0.00053333333 | E2: =Sheet1!E2-AVERAGE(Sheet1!$BG2:$BI2) -> 0.040433333 | F2: =Sheet1!F2-AVERAGE(Sheet1!$BG2:$BI2) -> 0.048033333 | G2: =Sheet1!G2-AVERAGE(Sheet1!$BG2:$BI2) -> 0.046033333 | H2: =Sheet1!H2-AVERAGE(Sheet1!$BG2:$BI2) -> 0.054733333 | I2: =Sheet1!I2-AVERAGE(Sheet1!$BG2:$BI2) -> 0.043533333 | ... BF2: =Sheet1!BF2-AVERAGE(Sheet1!$BG2:$BI2) -> 0.059233333 | BG2: =Sheet1!BJ2-AVERAGE(Sheet1!$BS2:$BU2) -> 0.072066667 | BH2: =Sheet1!BK2-AVERAGE(Sheet1!$BS2:$BU2) -> 0.017866667 | BI2: =Sheet1!BL2-AVERAGE(Sheet1!$BS2:$BU2) -> 0.056166667 | BJ2: =Sheet1!BM2-AVERAGE(Sheet1!$BS2:$BU2) -> 0.029566667 | BK2: =Sheet1!BN2-AVERAGE(Sheet1!$BS2:$BU2) -> 0.026666667 | BL2: =Sheet1!BO2-AVERAGE(Sheet1!$BS2:$BU2) -> 0.030766667 | BM2: =Sheet1!BP2-AVERAGE(Sheet1!$BS2:$BU2) -> 0.053366667 | BN2: =Sheet1!BQ2-AVERAGE(Sheet1!$BS2:$BU2) -> 0.092266667 | BO2: =Sheet1!BR2-AVERAGE(Sheet1!$BS2:$BU2) -> 0.051266667 | BP2: =Sheet1!BV2-AVERAGE(Sheet1!$CE2:$CG2) -> 0.0599 | BQ2: =Sheet1!BW2-AVERAGE(Sheet1!$CE2:$CG2) -> 0.0199 | BR2: =Sheet1!BX2-AVERAGE(Sheet1!$CE2:$CG2) -> 0.0547 | BS2: =Sheet1!BY2-AVERAGE(Sheet1!$CE2:$CG2) -> 0.0325 | BT2: =Sheet1!BZ2-AVERAGE(Sheet1!$CE2:$CG2) -> 0.0322 | BU2: =Sheet1!CA2-AVERAGE(Sheet1!$CE2:$CG2) -> 0.0315 | BV2: =Sheet1!CB2-AVERAGE(Sheet1!$CE2:$CG2) -> 0.0573 | BW2: =Sheet1!CC2-AVERAGE(Sheet1!$CE2:$CG2) -> 0.0926 | BX2: =Sheet1!CD2-AVERAGE(Sheet1!$CE2:$CG2) -> 0.0551 | BY2: =Sheet1!CH2-AVERAGE(Sheet1!$CQ2:$CS2) -> 0.069733333 | BZ2: =Sheet1!CI2-AVERAGE(Sheet1!$CQ2:$CS2) -> 0.026233333 | CA2: =Sheet1!CJ2-AVERAGE(Sheet1!$CQ2:$CS2) -> 0.054033333 | CB2: =Sheet1!CK2-AVERAGE(Sheet1!$CQ2:$CS2) -> 0.072033333 | CC2: =Sheet1!CL2-AVERAGE(Sheet1!$CQ2:$CS2) -> 0.035233333 | CD2: =Sheet1!CM2-AVERAGE(Sheet1!$CQ2:$CS2) -> 0.032633333 | CE2: =Sheet1!CN2-AVERAGE(Sheet1!$CQ2:$CS2) -> 0.055633333 | CF2: =Sheet1!CO2-AVERAGE(Sheet1!$CQ2:$CS2) -> 0.098533333 | CG2: =Sheet1!CP2-AVERAGE(Sheet1!$CQ2:$CS2) -> 0.051133333
A3: =HOUR(Sheet1!A3) + MINUTE(Sheet1!A3)/60 + SECOND(Sheet1!A3)/3600 -> 0.99722222 | B3: =Sheet1!B3-AVERAGE(Sheet1!$BG3:$BI3) -> 0.079633333 | C3: =Sheet1!C3-AVERAGE(Sheet1!$BG3:$BI3) -> 0.043833333 | D3: =Sheet1!D3-AVERAGE(Sheet1!$BG3:$BI3) -> 0.00073333333 | E3: =Sheet1!E3-AVERAGE(Sheet1!$BG3:$BI3) -> 0.040333333 | F3: =Sheet1!F3-AVERAGE(Sheet1!$BG3:$BI3) -> 0.051033333 | G3: =Sheet1!G3-AVERAGE(Sheet1!$BG3:$BI3) -> 0.054333333 | H3: =Sheet1!H3-AVERAGE(Sheet1!$BG3:$BI3) -> 0.062233333 | I3: =Sheet1!I3-AVERAGE(Sheet1!$BG3:$BI3) -> 0.046633333 | ... BF3: =Sheet1!BF3-AVERAGE(Sheet1!$BG3:$BI3) -> 0.070933333 | BG3: =Sheet1!BJ3-AVERAGE(Sheet1!$BS3:$BU3) -> 0.080466667 | BH3: =Sheet1!BK3-AVERAGE(Sheet1!$BS3:$BU3) -> 0.019266667 | BI3: =Sheet1!BL3-AVERAGE(Sheet1!$BS3:$BU3) -> 0.063166667 | BJ3: =Sheet1!BM3-AVERAGE(Sheet1!$BS3:$BU3) -> 0.031466667 | BK3: =Sheet1!BN3-AVERAGE(Sheet1!$BS3:$BU3) -> 0.026166667 | BL3: =Sheet1!BO3-AVERAGE(Sheet1!$BS3:$BU3) -> 0.031566667 | BM3: =Sheet1!BP3-AVERAGE(Sheet1!$BS3:$BU3) -> 0.068566667 | BN3: =Sheet1!BQ3-AVERAGE(Sheet1!$BS3:$BU3) -> 0.12116667 | BO3: =Sheet1!BR3-AVERAGE(Sheet1!$BS3:$BU3) -> 0.061866667 | BP3: =Sheet1!BV3-AVERAGE(Sheet1!$CE3:$CG3) -> 0.069733333 | BQ3: =Sheet1!BW3-AVERAGE(Sheet1!$CE3:$CG3) -> 0.019433333 | BR3: =Sheet1!BX3-AVERAGE(Sheet1!$CE3:$CG3) -> 0.062733333 | BS3: =Sheet1!BY3-AVERAGE(Sheet1!$CE3:$CG3) -> 0.036333333 | BT3: =Sheet1!BZ3-AVERAGE(Sheet1!$CE3:$CG3) -> 0.032633333 | BU3: =Sheet1!CA3-AVERAGE(Sheet1!$CE3:$CG3) -> 0.032133333 | BV3: =Sheet1!CB3-AVERAGE(Sheet1!$CE3:$CG3) -> 0.070633333 | BW3: =Sheet1!CC3-AVERAGE(Sheet1!$CE3:$CG3) -> 0.11353333 | BX3: =Sheet1!CD3-AVERAGE(Sheet1!$CE3:$CG3) -> 0.068033333 | BY3: =Sheet1!CH3-AVERAGE(Sheet1!$CQ3:$CS3) -> 0.083466667 | BZ3: =Sheet1!CI3-AVERAGE(Sheet1!$CQ3:$CS3) -> 0.026866667 | CA3: =Sheet1!CJ3-AVERAGE(Sheet1!$CQ3:$CS3) -> 0.061566667 | CB3: =Sheet1!CK3-AVERAGE(Sheet1!$CQ3:$CS3) -> 0.075766667 | CC3: =Sheet1!CL3-AVERAGE(Sheet1!$CQ3:$CS3) -> 0.036566667 | CD3: =Sheet1!CM3-AVERAGE(Sheet1!$CQ3:$CS3) -> 0.033166667 | CE3: =Sheet1!CN3-AVERAGE(Sheet1!$CQ3:$CS3) -> 0.068266667 | CF3: =Sheet1!CO3-AVERAGE(Sheet1!$CQ3:$CS3) -> 0.12716667 | CG3: =Sheet1!CP3-AVERAGE(Sheet1!$CQ3:$CS3) -> 0.057366667
A4: =HOUR(Sheet1!A4) + MINUTE(Sheet1!A4)/60 + SECOND(Sheet1!A4)/3600 -> 1.4972222 | B4: =Sheet1!B4-AVERAGE(Sheet1!$BG4:$BI4) -> 0.090066667 | C4: =Sheet1!C4-AVERAGE(Sheet1!$BG4:$BI4) -> 0.047966667 | D4: =Sheet1!D4-AVERAGE(Sheet1!$BG4:$BI4) -> 0.0010666667 | E4: =Sheet1!E4-AVERAGE(Sheet1!$BG4:$BI4) -> 0.041966667 | F4: =Sheet1!F4-AVERAGE(Sheet1!$BG4:$BI4) -> 0.054366667 | G4: =Sheet1!G4-AVERAGE(Sheet1!$BG4:$BI4) -> 0.062966667 | H4: =Sheet1!H4-AVERAGE(Sheet1!$BG4:$BI4) -> 0.068666667 | I4: =Sheet1!I4-AVERAGE(Sheet1!$BG4:$BI4) -> 0.049366667 | ... BF4: =Sheet1!BF4-AVERAGE(Sheet1!$BG4:$BI4) -> 0.083066667 | BG4: =Sheet1!BJ4-AVERAGE(Sheet1!$BS4:$BU4) -> 0.096666667 | BH4: =Sheet1!BK4-AVERAGE(Sheet1!$BS4:$BU4) -> 0.022866667 | BI4: =Sheet1!BL4-AVERAGE(Sheet1!$BS4:$BU4) -> 0.075666667 | BJ4: =Sheet1!BM4-AVERAGE(Sheet1!$BS4:$BU4) -> 0.034366667 | BK4: =Sheet1!BN4-AVERAGE(Sheet1!$BS4:$BU4) -> 0.027266667 | BL4: =Sheet1!BO4-AVERAGE(Sheet1!$BS4:$BU4) -> 0.033066667 | BM4: =Sheet1!BP4-AVERAGE(Sheet1!$BS4:$BU4) -> 0.084066667 | BN4: =Sheet1!BQ4-AVERAGE(Sheet1!$BS4:$BU4) -> 0.15536667 | BO4: =Sheet1!BR4-AVERAGE(Sheet1!$BS4:$BU4) -> 0.072966667 | BP4: =Sheet1!BV4-AVERAGE(Sheet1!$CE4:$CG4) -> 0.087 | BQ4: =Sheet1!BW4-AVERAGE(Sheet1!$CE4:$CG4) -> 0.0193 | BR4: =Sheet1!BX4-AVERAGE(Sheet1!$CE4:$CG4) -> 0.0755 | BS4: =Sheet1!BY4-AVERAGE(Sheet1!$CE4:$CG4) -> 0.0398 | BT4: =Sheet1!BZ4-AVERAGE(Sheet1!$CE4:$CG4) -> 0.0331 | BU4: =Sheet1!CA4-AVERAGE(Sheet1!$CE4:$CG4) -> 0.0328 | BV4: =Sheet1!CB4-AVERAGE(Sheet1!$CE4:$CG4) -> 0.0902 | BW4: =Sheet1!CC4-AVERAGE(Sheet1!$CE4:$CG4) -> 0.1436 | BX4: =Sheet1!CD4-AVERAGE(Sheet1!$CE4:$CG4) -> 0.0787 | BY4: =Sheet1!CH4-AVERAGE(Sheet1!$CQ4:$CS4) -> 0.10126667 | BZ4: =Sheet1!CI4-AVERAGE(Sheet1!$CQ4:$CS4) -> 0.028766667 | CA4: =Sheet1!CJ4-AVERAGE(Sheet1!$CQ4:$CS4) -> 0.074566667 | CB4: =Sheet1!CK4-AVERAGE(Sheet1!$CQ4:$CS4) -> 0.078466667 | CC4: =Sheet1!CL4-AVERAGE(Sheet1!$CQ4:$CS4) -> 0.036466667 | CD4: =Sheet1!CM4-AVERAGE(Sheet1!$CQ4:$CS4) -> 0.034666667 | CE4: =Sheet1!CN4-AVERAGE(Sheet1!$CQ4:$CS4) -> 0.081966667 | CF4: =Sheet1!CO4-AVERAGE(Sheet1!$CQ4:$CS4) -> 0.15336667 | CG4: =Sheet1!CP4-AVERAGE(Sheet1!$CQ4:$CS4) -> 0.064666667
A5: =HOUR(Sheet1!A5) + MINUTE(Sheet1!A5)/60 + SECOND(Sheet1!A5)/3600 -> 1.9972222 | B5: =Sheet1!B5-AVERAGE(Sheet1!$BG5:$BI5) -> 0.10566667 | C5: =Sheet1!C5-AVERAGE(Sheet1!$BG5:$BI5) -> 0.051766667 | D5: =Sheet1!D5-AVERAGE(Sheet1!$BG5:$BI5) -> 0.0011666667 | E5: =Sheet1!E5-AVERAGE(Sheet1!$BG5:$BI5) -> 0.044066667 | F5: =Sheet1!F5-AVERAGE(Sheet1!$BG5:$BI5) -> 0.057966667 | G5: =Sheet1!G5-AVERAGE(Sheet1!$BG5:$BI5) -> 0.075566667 | H5: =Sheet1!H5-AVERAGE(Sheet1!$BG5:$BI5) -> 0.073966667 | I5: =Sheet1!I5-AVERAGE(Sheet1!$BG5:$BI5) -> 0.051466667 | ... BF5: =Sheet1!BF5-AVERAGE(Sheet1!$BG5:$BI5) -> 0.093466667 | BG5: =Sheet1!BJ5-AVERAGE(Sheet1!$BS5:$BU5) -> 0.10806667 | BH5: =Sheet1!BK5-AVERAGE(Sheet1!$BS5:$BU5) -> 0.029166667 | BI5: =Sheet1!BL5-AVERAGE(Sheet1!$BS5:$BU5) -> 0.093766667 | BJ5: =Sheet1!BM5-AVERAGE(Sheet1!$BS5:$BU5) -> 0.037766667 | BK5: =Sheet1!BN5-AVERAGE(Sheet1!$BS5:$BU5) -> 0.026466667 | BL5: =Sheet1!BO5-AVERAGE(Sheet1!$BS5:$BU5) -> 0.032966667 | BM5: =Sheet1!BP5-AVERAGE(Sheet1!$BS5:$BU5) -> 0.10246667 | BN5: =Sheet1!BQ5-AVERAGE(Sheet1!$BS5:$BU5) -> 0.18316667 | BO5: =Sheet1!BR5-AVERAGE(Sheet1!$BS5:$BU5) -> 0.082666667 | BP5: =Sheet1!BV5-AVERAGE(Sheet1!$CE5:$CG5) -> 0.101 | BQ5: =Sheet1!BW5-AVERAGE(Sheet1!$CE5:$CG5) -> 0.0193 | BR5: =Sheet1!BX5-AVERAGE(Sheet1!$CE5:$CG5) -> 0.0945 | BS5: =Sheet1!BY5-AVERAGE(Sheet1!$CE5:$CG5) -> 0.0428 | BT5: =Sheet1!BZ5-AVERAGE(Sheet1!$CE5:$CG5) -> 0.0328 | BU5: =Sheet1!CA5-AVERAGE(Sheet1!$CE5:$CG5) -> 0.0338 | BV5: =Sheet1!CB5-AVERAGE(Sheet1!$CE5:$CG5) -> 0.1118 | BW5: =Sheet1!CC5-AVERAGE(Sheet1!$CE5:$CG5) -> 0.1669 | BX5: =Sheet1!CD5-AVERAGE(Sheet1!$CE5:$CG5) -> 0.0882 | BY5: =Sheet1!CH5-AVERAGE(Sheet1!$CQ5:$CS5) -> 0.1173 | BZ5: =Sheet1!CI5-AVERAGE(Sheet1!$CQ5:$CS5) -> 0.0284 | CA5: =Sheet1!CJ5-AVERAGE(Sheet1!$CQ5:$CS5) -> 0.0922 | CB5: =Sheet1!CK5-AVERAGE(Sheet1!$CQ5:$CS5) -> 0.0798 | CC5: =Sheet1!CL5-AVERAGE(Sheet1!$CQ5:$CS5) -> 0.0348 | CD5: =Sheet1!CM5-AVERAGE(Sheet1!$CQ5:$CS5) -> 0.034 | CE5: =Sheet1!CN5-AVERAGE(Sheet1!$CQ5:$CS5) -> 0.1011 | CF5: =Sheet1!CO5-AVERAGE(Sheet1!$CQ5:$CS5) -> 0.1741 | CG5: =Sheet1!CP5-AVERAGE(Sheet1!$CQ5:$CS5) -> 0.0753
A6: =HOUR(Sheet1!A6) + MINUTE(Sheet1!A6)/60 + SECOND(Sheet1!A6)/3600 -> 2.4972222 | B6: =Sheet1!B6-AVERAGE(Sheet1!$BG6:$BI6) -> 0.12396667 | C6: =Sheet1!C6-AVERAGE(Sheet1!$BG6:$BI6) -> 0.059966667 | D6: =Sheet1!D6-AVERAGE(Sheet1!$BG6:$BI6) -> 0.0012666667 | E6: =Sheet1!E6-AVERAGE(Sheet1!$BG6:$BI6) -> 0.046866667 | F6: =Sheet1!F6-AVERAGE(Sheet1!$BG6:$BI6) -> 0.063266667 | G6: =Sheet1!G6-AVERAGE(Sheet1!$BG6:$BI6) -> 0.086166667 | H6: =Sheet1!H6-AVERAGE(Sheet1!$BG6:$BI6) -> 0.080466667 | I6: =Sheet1!I6-AVERAGE(Sheet1!$BG6:$BI6) -> 0.053066667 | ... BF6: =Sheet1!BF6-AVERAGE(Sheet1!$BG6:$BI6) -> 0.10236667 | BG6: =Sheet1!BJ6-AVERAGE(Sheet1!$BS6:$BU6) -> 0.11656667 | BH6: =Sheet1!BK6-AVERAGE(Sheet1!$BS6:$BU6) -> 0.021466667 | BI6: =Sheet1!BL6-AVERAGE(Sheet1!$BS6:$BU6) -> 0.11136667 | BJ6: =Sheet1!BM6-AVERAGE(Sheet1!$BS6:$BU6) -> 0.039666667 | BK6: =Sheet1!BN6-AVERAGE(Sheet1!$BS6:$BU6) -> 0.026966667 | BL6: =Sheet1!BO6-AVERAGE(Sheet1!$BS6:$BU6) -> 0.033566667 | BM6: =Sheet1!BP6-AVERAGE(Sheet1!$BS6:$BU6) -> 0.12346667 | BN6: =Sheet1!BQ6-AVERAGE(Sheet1!$BS6:$BU6) -> 0.20816667 | BO6: =Sheet1!BR6-AVERAGE(Sheet1!$BS6:$BU6) -> 0.093066667 | BP6: =Sheet1!BV6-AVERAGE(Sheet1!$CE6:$CG6) -> 0.1165 | BQ6: =Sheet1!BW6-AVERAGE(Sheet1!$CE6:$CG6) -> 0.0195 | BR6: =Sheet1!BX6-AVERAGE(Sheet1!$CE6:$CG6) -> 0.1133 | BS6: =Sheet1!BY6-AVERAGE(Sheet1!$CE6:$CG6) -> 0.0473 | BT6: =Sheet1!BZ6-AVERAGE(Sheet1!$CE6:$CG6) -> 0.0323 | BU6: =Sheet1!CA6-AVERAGE(Sheet1!$CE6:$CG6) -> 0.0345 | BV6: =Sheet1!CB6-AVERAGE(Sheet1!$CE6:$CG6) -> 0.134 | BW6: =Sheet1!CC6-AVERAGE(Sheet1!$CE6:$CG6) -> 0.1849 | BX6: =Sheet1!CD6-AVERAGE(Sheet1!$CE6:$CG6) -> 0.0975 | BY6: =Sheet1!CH6-AVERAGE(Sheet1!$CQ6:$CS6) -> 0.13086667 | BZ6: =Sheet1!CI6-AVERAGE(Sheet1!$CQ6:$CS6) -> 0.029566667 | CA6: =Sheet1!CJ6-AVERAGE(Sheet1!$CQ6:$CS6) -> 0.10966667 | CB6: =Sheet1!CK6-AVERAGE(Sheet1!$CQ6:$CS6) -> 0.080466667 | CC6: =Sheet1!CL6-AVERAGE(Sheet1!$CQ6:$CS6) -> 0.033966667 | CD6: =Sheet1!CM6-AVERAGE(Sheet1!$CQ6:$CS6) -> 0.034766667 | CE6: =Sheet1!CN6-AVERAGE(Sheet1!$CQ6:$CS6) -> 0.12126667 | CF6: =Sheet1!CO6-AVERAGE(Sheet1!$CQ6:$CS6) -> 0.19786667 | CG6: =Sheet1!CP6-AVERAGE(Sheet1!$CQ6:$CS6) -> 0.084566667
A7: =HOUR(Sheet1!A7) + MINUTE(Sheet1!A7)/60 + SECOND(Sheet1!A7)/3600 -> 2.9972222 | B7: =Sheet1!B7-AVERAGE(Sheet1!$BG7:$BI7) -> 0.1499 | C7: =Sheet1!C7-AVERAGE(Sheet1!$BG7:$BI7) -> 0.07 | D7: =Sheet1!D7-AVERAGE(Sheet1!$BG7:$BI7) -> 0.0009 | E7: =Sheet1!E7-AVERAGE(Sheet1!$BG7:$BI7) -> 0.0512 | F7: =Sheet1!F7-AVERAGE(Sheet1!$BG7:$BI7) -> 0.0721 | G7: =Sheet1!G7-AVERAGE(Sheet1!$BG7:$BI7) -> 0.098 | H7: =Sheet1!H7-AVERAGE(Sheet1!$BG7:$BI7) -> 0.0881 | I7: =Sheet1!I7-AVERAGE(Sheet1!$BG7:$BI7) -> 0.0543 | ... BF7: =Sheet1!BF7-AVERAGE(Sheet1!$BG7:$BI7) -> 0.1114 | BG7: =Sheet1!BJ7-AVERAGE(Sheet1!$BS7:$BU7) -> 0.1256 | BH7: =Sheet1!BK7-AVERAGE(Sheet1!$BS7:$BU7) -> 0.0242 | BI7: =Sheet1!BL7-AVERAGE(Sheet1!$BS7:$BU7) -> 0.1268 | BJ7: =Sheet1!BM7-AVERAGE(Sheet1!$BS7:$BU7) -> 0.0443 | BK7: =Sheet1!BN7-AVERAGE(Sheet1!$BS7:$BU7) -> 0.0268 | BL7: =Sheet1!BO7-AVERAGE(Sheet1!$BS7:$BU7) -> 0.0351 | BM7: =Sheet1!BP7-AVERAGE(Sheet1!$BS7:$BU7) -> 0.1367 | BN7: =Sheet1!BQ7-AVERAGE(Sheet1!$BS7:$BU7) -> 0.2331 | BO7: =Sheet1!BR7-AVERAGE(Sheet1!$BS7:$BU7) -> 0.1006 | BP7: =Sheet1!BV7-AVERAGE(Sheet1!$CE7:$CG7) -> 0.1277 | BQ7: =Sheet1!BW7-AVERAGE(Sheet1!$CE7:$CG7) -> 0.0191 | BR7: =Sheet1!BX7-AVERAGE(Sheet1!$CE7:$CG7) -> 0.1284 | BS7: =Sheet1!BY7-AVERAGE(Sheet1!$CE7:$CG7) -> 0.0516 | BT7: =Sheet1!BZ7-AVERAGE(Sheet1!$CE7:$CG7) -> 0.0318 | BU7: =Sheet1!CA7-AVERAGE(Sheet1!$CE7:$CG7) -> 0.035 | BV7: =Sheet1!CB7-AVERAGE(Sheet1!$CE7:$CG7) -> 0.1515 | BW7: =Sheet1!CC7-AVERAGE(Sheet1!$CE7:$CG7) -> 0.2027 | BX7: =Sheet1!CD7-AVERAGE(Sheet1!$CE7:$CG7) -> 0.1028 | BY7: =Sheet1!CH7-AVERAGE(Sheet1!$CQ7:$CS7) -> 0.14413333 | BZ7: =Sheet1!CI7-AVERAGE(Sheet1!$CQ7:$CS7) -> 0.030033333 | CA7: =Sheet1!CJ7-AVERAGE(Sheet1!$CQ7:$CS7) -> 0.12533333 | CB7: =Sheet1!CK7-AVERAGE(Sheet1!$CQ7:$CS7) -> 0.080933333 | CC7: =Sheet1!CL7-AVERAGE(Sheet1!$CQ7:$CS7) -> 0.035333333 | CD7: =Sheet1!CM7-AVERAGE(Sheet1!$CQ7:$CS7) -> 0.035133333 | CE7: =Sheet1!CN7-AVERAGE(Sheet1!$CQ7:$CS7) -> 0.13843333 | CF7: =Sheet1!CO7-AVERAGE(Sheet1!$CQ7:$CS7) -> 0.22123333 | CG7: =Sheet1!CP7-AVERAGE(Sheet1!$CQ7:$CS7) -> 0.091633333
A8: =HOUR(Sheet1!A8) + MINUTE(Sheet1!A8)/60 + SECOND(Sheet1!A8)/3600 -> 3.4972222 | B8: =Sheet1!B8-AVERAGE(Sheet1!$BG8:$BI8) -> 0.17626667 | C8: =Sheet1!C8-AVERAGE(Sheet1!$BG8:$BI8) -> 0.076366667 | D8: =Sheet1!D8-AVERAGE(Sheet1!$BG8:$BI8) -> 0.0013666667 | E8: =Sheet1!E8-AVERAGE(Sheet1!$BG8:$BI8) -> 0.054966667 | F8: =Sheet1!F8-AVERAGE(Sheet1!$BG8:$BI8) -> 0.081466667 | G8: =Sheet1!G8-AVERAGE(Sheet1!$BG8:$BI8) -> 0.11266667 | H8: =Sheet1!H8-AVERAGE(Sheet1!$BG8:$BI8) -> 0.096066667 | I8: =Sheet1!I8-AVERAGE(Sheet1!$BG8:$BI8) -> 0.055666667 | ... BF8: =Sheet1!BF8-AVERAGE(Sheet1!$BG8:$BI8) -> 0.12136667 | BG8: =Sheet1!BJ8-AVERAGE(Sheet1!$BS8:$BU8) -> 0.14226667 | BH8: =Sheet1!BK8-AVERAGE(Sheet1!$BS8:$BU8) -> 0.028366667 | BI8: =Sheet1!BL8-AVERAGE(Sheet1!$BS8:$BU8) -> 0.13916667 | BJ8: =Sheet1!BM8-AVERAGE(Sheet1!$BS8:$BU8) -> 0.049166667 | BK8: =Sheet1!BN8-AVERAGE(Sheet1!$BS8:$BU8) -> 0.027566667 | BL8: =Sheet1!BO8-AVERAGE(Sheet1!$BS8:$BU8) -> 0.034466667 | BM8: =Sheet1!BP8-AVERAGE(Sheet1!$BS8:$BU8) -> 0.16366667 | BN8: =Sheet1!BQ8-AVERAGE(Sheet1!$BS8:$BU8) -> 0.25906667 | BO8: =Sheet1!BR8-AVERAGE(Sheet1!$BS8:$BU8) -> 0.10846667 | BP8: =Sheet1!BV8-AVERAGE(Sheet1!$CE8:$CG8) -> 0.13966667 | BQ8: =Sheet1!BW8-AVERAGE(Sheet1!$CE8:$CG8) -> 0.019166667 | BR8: =Sheet1!BX8-AVERAGE(Sheet1!$CE8:$CG8) -> 0.14016667 | BS8: =Sheet1!BY8-AVERAGE(Sheet1!$CE8:$CG8) -> 0.056566667 | BT8: =Sheet1!BZ8-AVERAGE(Sheet1!$CE8:$CG8) -> 0.032966667 | BU8: =Sheet1!CA8-AVERAGE(Sheet1!$CE8:$CG8) -> 0.035966667 | BV8: =Sheet1!CB8-AVERAGE(Sheet1!$CE8:$CG8) -> 0.16876667 | BW8: =Sheet1!CC8-AVERAGE(Sheet1!$CE8:$CG8) -> 0.22046667 | BX8: =Sheet1!CD8-AVERAGE(Sheet1!$CE8:$CG8) -> 0.10876667 | BY8: =Sheet1!CH8-AVERAGE(Sheet1!$CQ8:$CS8) -> 0.16163333 | BZ8: =Sheet1!CI8-AVERAGE(Sheet1!$CQ8:$CS8) -> 0.031333333 | CA8: =Sheet1!CJ8-AVERAGE(Sheet1!$CQ8:$CS8) -> 0.13653333 | CB8: =Sheet1!CK8-AVERAGE(Sheet1!$CQ8:$CS8) -> 0.083533333 | CC8: =Sheet1!CL8-AVERAGE(Sheet1!$CQ8:$CS8) -> 0.035533333 | CD8: =Sheet1!CM8-AVERAGE(Sheet1!$CQ8:$CS8) -> 0.034733333 | CE8: =Sheet1!CN8-AVERAGE(Sheet1!$CQ8:$CS8) -> 0.16053333 | CF8: =Sheet1!CO8-AVERAGE(Sheet1!$CQ8:$CS8) -> 0.24323333 | CG8: =Sheet1!CP8-AVERAGE(Sheet1!$CQ8:$CS8) -> 0.10133333
A9: =HOUR(Sheet1!A9) + MINUTE(Sheet1!A9)/60 + SECOND(Sheet1!A9)/3600 -> 3.9972222 | B9: =Sheet1!B9-AVERAGE(Sheet1!$BG9:$BI9) -> 0.20376667 | C9: =Sheet1!C9-AVERAGE(Sheet1!$BG9:$BI9) -> 0.093666667 | D9: =Sheet1!D9-AVERAGE(Sheet1!$BG9:$BI9) -> 0.0011666667 | E9: =Sheet1!E9-AVERAGE(Sheet1!$BG9:$BI9) -> 0.058966667 | F9: =Sheet1!F9-AVERAGE(Sheet1!$BG9:$BI9) -> 0.090466667 | G9: =Sheet1!G9-AVERAGE(Sheet1!$BG9:$BI9) -> 0.12696667 | H9: =Sheet1!H9-AVERAGE(Sheet1!$BG9:$BI9) -> 0.099366667 | I9: =Sheet1!I9-AVERAGE(Sheet1!$BG9:$BI9) -> 0.056166667 | ... BF9: =Sheet1!BF9-AVERAGE(Sheet1!$BG9:$BI9) -> 0.12886667 | BG9: =Sheet1!BJ9-AVERAGE(Sheet1!$BS9:$BU9) -> 0.15496667 | BH9: =Sheet1!BK9-AVERAGE(Sheet1!$BS9:$BU9) -> 0.028966667 | BI9: =Sheet1!BL9-AVERAGE(Sheet1!$BS9:$BU9) -> 0.14636667 | BJ9: =Sheet1!BM9-AVERAGE(Sheet1!$BS9:$BU9) -> 0.052966667 | BK9: =Sheet1!BN9-AVERAGE(Sheet1!$BS9:$BU9) -> 0.025666667 | BL9: =Sheet1!BO9-AVERAGE(Sheet1!$BS9:$BU9) -> 0.035966667 | BM9: =Sheet1!BP9-AVERAGE(Sheet1!$BS9:$BU9) -> 0.18886667 | BN9: =Sheet1!BQ9-AVERAGE(Sheet1!$BS9:$BU9) -> 0.27586667 | BO9: =Sheet1!BR9-AVERAGE(Sheet1!$BS9:$BU9) -> 0.11436667 | BP9: =Sheet1!BV9-AVERAGE(Sheet1!$CE9:$CG9) -> 0.15163333 | BQ9: =Sheet1!BW9-AVERAGE(Sheet1!$CE9:$CG9) -> 0.019333333 | BR9: =Sheet1!BX9-AVERAGE(Sheet1!$CE9:$CG9) -> 0.14873333 | BS9: =Sheet1!BY9-AVERAGE(Sheet1!$CE9:$CG9) -> 0.061333333 | BT9: =Sheet1!BZ9-AVERAGE(Sheet1!$CE9:$CG9) -> 0.031433333 | BU9: =Sheet1!CA9-AVERAGE(Sheet1!$CE9:$CG9) -> 0.036433333 | BV9: =Sheet1!CB9-AVERAGE(Sheet1!$CE9:$CG9) -> 0.19593333 | BW9: =Sheet1!CC9-AVERAGE(Sheet1!$CE9:$CG9) -> 0.23603333 | BX9: =Sheet1!CD9-AVERAGE(Sheet1!$CE9:$CG9) -> 0.11543333 | BY9: =Sheet1!CH9-AVERAGE(Sheet1!$CQ9:$CS9) -> 0.17653333 | BZ9: =Sheet1!CI9-AVERAGE(Sheet1!$CQ9:$CS9) -> 0.036233333 | CA9: =Sheet1!CJ9-AVERAGE(Sheet1!$CQ9:$CS9) -> 0.14613333 | CB9: =Sheet1!CK9-AVERAGE(Sheet1!$CQ9:$CS9) -> 0.085033333 | CC9: =Sheet1!CL9-AVERAGE(Sheet1!$CQ9:$CS9) -> 0.036233333 | CD9: =Sheet1!CM9-AVERAGE(Sheet1!$CQ9:$CS9) -> 0.035033333 | CE9: =Sheet1!CN9-AVERAGE(Sheet1!$CQ9:$CS9) -> 0.19173333 | CF9: =Sheet1!CO9-AVERAGE(Sheet1!$CQ9:$CS9) -> 0.25953333 | CG9: =Sheet1!CP9-AVERAGE(Sheet1!$CQ9:$CS9) -> 0.11043333
A10: =HOUR(Sheet1!A10) + MINUTE(Sheet1!A10)/60 + SECOND(Sheet1!A10)/3600 -> 4.4972222 | B10: =Sheet1!B10-AVERAGE(Sheet1!$BG10:$BI10) -> 0.22573333 | C10: =Sheet1!C10-AVERAGE(Sheet1!$BG10:$BI10) -> 0.10733333 | D10: =Sheet1!D10-AVERAGE(Sheet1!$BG10:$BI10) -> 0.00083333333 | E10: =Sheet1!E10-AVERAGE(Sheet1!$BG10:$BI10) -> 0.060433333 | F10: =Sheet1!F10-AVERAGE(Sheet1!$BG10:$BI10) -> 0.10283333 | G10: =Sheet1!G10-AVERAGE(Sheet1!$BG10:$BI10) -> 0.14213333 | H10: =Sheet1!H10-AVERAGE(Sheet1!$BG10:$BI10) -> 0.10593333 | I10: =Sheet1!I10-AVERAGE(Sheet1!$BG10:$BI10) -> 0.057433333 | ... BF10: =Sheet1!BF10-AVERAGE(Sheet1!$BG10:$BI10) -> 0.13743333 | BG10: =Sheet1!BJ10-AVERAGE(Sheet1!$BS10:$BU10) -> 0.17443333 | BH10: =Sheet1!BK10-AVERAGE(Sheet1!$BS10:$BU10) -> 0.028633333 | BI10: =Sheet1!BL10-AVERAGE(Sheet1!$BS10:$BU10) -> 0.15543333 | BJ10: =Sheet1!BM10-AVERAGE(Sheet1!$BS10:$BU10) -> 0.058333333 | BK10: =Sheet1!BN10-AVERAGE(Sheet1!$BS10:$BU10) -> 0.026933333 | BL10: =Sheet1!BO10-AVERAGE(Sheet1!$BS10:$BU10) -> 0.037433333 | BM10: =Sheet1!BP10-AVERAGE(Sheet1!$BS10:$BU10) -> 0.21283333 | BN10: =Sheet1!BQ10-AVERAGE(Sheet1!$BS10:$BU10) -> 0.30033333 | BO10: =Sheet1!BR10-AVERAGE(Sheet1!$BS10:$BU10) -> 0.12163333 | BP10: =Sheet1!BV10-AVERAGE(Sheet1!$CE10:$CG10) -> 0.16496667 | BQ10: =Sheet1!BW10-AVERAGE(Sheet1!$CE10:$CG10) -> 0.019666667 | BR10: =Sheet1!BX10-AVERAGE(Sheet1!$CE10:$CG10) -> 0.15376667 | BS10: =Sheet1!BY10-AVERAGE(Sheet1!$CE10:$CG10) -> 0.067666667 | BT10: =Sheet1!BZ10-AVERAGE(Sheet1!$CE10:$CG10) -> 0.032266667 | BU10: =Sheet1!CA10-AVERAGE(Sheet1!$CE10:$CG10) -> 0.037366667 | BV10: =Sheet1!CB10-AVERAGE(Sheet1!$CE10:$CG10) -> 0.22426667 | BW10: =Sheet1!CC10-AVERAGE(Sheet1!$CE10:$CG10) -> 0.25126667 | BX10: =Sheet1!CD10-AVERAGE(Sheet1!$CE10:$CG10) -> 0.12286667 | BY10: =Sheet1!CH10-AVERAGE(Sheet1!$CQ10:$CS10) -> 0.1957 | BZ10: =Sheet1!CI10-AVERAGE(Sheet1!$CQ10:$CS10) -> 0.0398 | CA10: =Sheet1!CJ10-AVERAGE(Sheet1!$CQ10:$CS10) -> 0.153 | CB10: =Sheet1!CK10-AVERAGE(Sheet1!$CQ10:$CS10) -> 0.089 | CC10: =Sheet1!CL10-AVERAGE(Sheet1!$CQ10:$CS10) -> 0.0365 | CD10: =Sheet1!CM10-AVERAGE(Sheet1!$CQ10:$CS10) -> 0.0363 | CE10: =Sheet1!CN10-AVERAGE(Sheet1!$CQ10:$CS10) -> 0.2252 | CF10: =Sheet1!CO10-AVERAGE(Sheet1!$CQ10:$CS10) -> 0.2877 | CG10: =Sheet1!CP10-AVERAGE(Sheet1!$CQ10:$CS10) -> 0.1175
A11: =HOUR(Sheet1!A11) + MINUTE(Sheet1!A11)/60 + SECOND(Sheet1!A11)/3600 -> 4.9972222 | B11: =Sheet1!B11-AVERAGE(Sheet1!$BG11:$BI11) -> 0.2896 | C11: =Sheet1!C11-AVERAGE(Sheet1!$BG11:$BI11) -> 0.1281 | D11: =Sheet1!D11-AVERAGE(Sheet1!$BG11:$BI11) -> 0.0011 | E11: =Sheet1!E11-AVERAGE(Sheet1!$BG11:$BI11) -> 0.065 | F11: =Sheet1!F11-AVERAGE(Sheet1!$BG11:$BI11) -> 0.1124 | G11: =Sheet1!G11-AVERAGE(Sheet1!$BG11:$BI11) -> 0.1595 | H11: =Sheet1!H11-AVERAGE(Sheet1!$BG11:$BI11) -> 0.1056 | I11: =Sheet1!I11-AVERAGE(Sheet1!$BG11:$BI11) -> 0.0581 | ... BF11: =Sheet1!BF11-AVERAGE(Sheet1!$BG11:$BI11) -> 0.1447 | BG11: =Sheet1!BJ11-AVERAGE(Sheet1!$BS11:$BU11) -> 0.18773333 | BH11: =Sheet1!BK11-AVERAGE(Sheet1!$BS11:$BU11) -> 0.032333333 | BI11: =Sheet1!BL11-AVERAGE(Sheet1!$BS11:$BU11) -> 0.16073333 | BJ11: =Sheet1!BM11-AVERAGE(Sheet1!$BS11:$BU11) -> 0.063933333 | BK11: =Sheet1!BN11-AVERAGE(Sheet1!$BS11:$BU11) -> 0.026933333 | BL11: =Sheet1!BO11-AVERAGE(Sheet1!$BS11:$BU11) -> 0.037633333 | BM11: =Sheet1!BP11-AVERAGE(Sheet1!$BS11:$BU11) -> 0.23273333 | BN11: =Sheet1!BQ11-AVERAGE(Sheet1!$BS11:$BU11) -> 0.31963333 | BO11: =Sheet1!BR11-AVERAGE(Sheet1!$BS11:$BU11) -> 0.12693333 | BP11: =Sheet1!BV11-AVERAGE(Sheet1!$CE11:$CG11) -> 0.17746667 | BQ11: =Sheet1!BW11-AVERAGE(Sheet1!$CE11:$CG11) -> 0.020066667 | BR11: =Sheet1!BX11-AVERAGE(Sheet1!$CE11:$CG11) -> 0.16116667 | BS11: =Sheet1!BY11-AVERAGE(Sheet1!$CE11:$CG11) -> 0.072266667 | BT11: =Sheet1!BZ11-AVERAGE(Sheet1!$CE11:$CG11) -> 0.031366667 | BU11: =Sheet1!CA11-AVERAGE(Sheet1!$CE11:$CG11) -> 0.037766667 | BV11: =Sheet1!CB11-AVERAGE(Sheet1!$CE11:$CG11) -> 0.25136667 | BW11: =Sheet1!CC11-AVERAGE(Sheet1!$CE11:$CG11) -> 0.26726667 | BX11: =Sheet1!CD11-AVERAGE(Sheet1!$CE11:$CG11) -> 0.12906667 | BY11: =Sheet1!CH11-AVERAGE(Sheet1!$CQ11:$CS11) -> 0.2118 | BZ11: =Sheet1!CI11-AVERAGE(Sheet1!$CQ11:$CS11) -> 0.0427 | CA11: =Sheet1!CJ11-AVERAGE(Sheet1!$CQ11:$CS11) -> 0.16 | CB11: =Sheet1!CK11-AVERAGE(Sheet1!$CQ11:$CS11) -> 0.0932 | CC11: =Sheet1!CL11-AVERAGE(Sheet1!$CQ11:$CS11) -> 0.0365 | CD11: =Sheet1!CM11-AVERAGE(Sheet1!$CQ11:$CS11) -> 0.0358 | CE11: =Sheet1!CN11-AVERAGE(Sheet1!$CQ11:$CS11) -> 0.2421 | CF11: =Sheet1!CO11-AVERAGE(Sheet1!$CQ11:$CS11) -> 0.3133 | CG11: =Sheet1!CP11-AVERAGE(Sheet1!$CQ11:$CS11) -> 0.1267
A12: =HOUR(Sheet1!A12) + MINUTE(Sheet1!A12)/60 + SECOND(Sheet1!A12)/3600 -> 5.4972222 | B12: =Sheet1!B12-AVERAGE(Sheet1!$BG12:$BI12) -> 0.3214 | C12: =Sheet1!C12-AVERAGE(Sheet1!$BG12:$BI12) -> 0.1441 | D12: =Sheet1!D12-AVERAGE(Sheet1!$BG12:$BI12) -> 0.0014 | E12: =Sheet1!E12-AVERAGE(Sheet1!$BG12:$BI12) -> 0.0671 | F12: =Sheet1!F12-AVERAGE(Sheet1!$BG12:$BI12) -> 0.1286 | G12: =Sheet1!G12-AVERAGE(Sheet1!$BG12:$BI12) -> 0.1765 | H12: =Sheet1!H12-AVERAGE(Sheet1!$BG12:$BI12) -> 0.119 | I12: =Sheet1!I12-AVERAGE(Sheet1!$BG12:$BI12) -> 0.0588 | ... BF12: =Sheet1!BF12-AVERAGE(Sheet1!$BG12:$BI12) -> 0.1538 | BG12: =Sheet1!BJ12-AVERAGE(Sheet1!$BS12:$BU12) -> 0.20846667 | BH12: =Sheet1!BK12-AVERAGE(Sheet1!$BS12:$BU12) -> 0.028866667 | BI12: =Sheet1!BL12-AVERAGE(Sheet1!$BS12:$BU12) -> 0.17166667 | BJ12: =Sheet1!BM12-AVERAGE(Sheet1!$BS12:$BU12) -> 0.067466667 | BK12: =Sheet1!BN12-AVERAGE(Sheet1!$BS12:$BU12) -> 0.027766667 | BL12: =Sheet1!BO12-AVERAGE(Sheet1!$BS12:$BU12) -> 0.038566667 | BM12: =Sheet1!BP12-AVERAGE(Sheet1!$BS12:$BU12) -> 0.26296667 | BN12: =Sheet1!BQ12-AVERAGE(Sheet1!$BS12:$BU12) -> 0.33856667 | BO12: =Sheet1!BR12-AVERAGE(Sheet1!$BS12:$BU12) -> 0.13576667 | BP12: =Sheet1!BV12-AVERAGE(Sheet1!$CE12:$CG12) -> 0.19676667 | BQ12: =Sheet1!BW12-AVERAGE(Sheet1!$CE12:$CG12) -> 0.020266667 | BR12: =Sheet1!BX12-AVERAGE(Sheet1!$CE12:$CG12) -> 0.16956667 | BS12: =Sheet1!BY12-AVERAGE(Sheet1!$CE12:$CG12) -> 0.078066667 | BT12: =Sheet1!BZ12-AVERAGE(Sheet1!$CE12:$CG12) -> 0.031966667 | BU12: =Sheet1!CA12-AVERAGE(Sheet1!$CE12:$CG12) -> 0.039266667 | BV12: =Sheet1!CB12-AVERAGE(Sheet1!$CE12:$CG12) -> 0.27906667 | BW12: =Sheet1!CC12-AVERAGE(Sheet1!$CE12:$CG12) -> 0.27586667 | BX12: =Sheet1!CD12-AVERAGE(Sheet1!$CE12:$CG12) -> 0.13946667 | BY12: =Sheet1!CH12-AVERAGE(Sheet1!$CQ12:$CS12) -> 0.23566667 | BZ12: =Sheet1!CI12-AVERAGE(Sheet1!$CQ12:$CS12) -> 0.042266667 | CA12: =Sheet1!CJ12-AVERAGE(Sheet1!$CQ12:$CS12) -> 0.16926667 | CB12: =Sheet1!CK12-AVERAGE(Sheet1!$CQ12:$CS12) -> 0.095766667 | CC12: =Sheet1!CL12-AVERAGE(Sheet1!$CQ12:$CS12) -> 0.038466667 | CD12: =Sheet1!CM12-AVERAGE(Sheet1!$CQ12:$CS12) -> 0.035866667 | CE12: =Sheet1!CN12-AVERAGE(Sheet1!$CQ12:$CS12) -> 0.27916667 | CF12: =Sheet1!CO12-AVERAGE(Sheet1!$CQ12:$CS12) -> 0.32946667 | CG12: =Sheet1!CP12-AVERAGE(Sheet1!$CQ12:$CS12) -> 0.13756667
A13: =HOUR(Sheet1!A13) + MINUTE(Sheet1!A13)/60 + SECOND(Sheet1!A13)/3600 -> 5.9972222 | B13: =Sheet1!B13-AVERAGE(Sheet1!$BG13:$BI13) -> 0.37933333 | C13: =Sheet1!C13-AVERAGE(Sheet1!$BG13:$BI13) -> 0.15613333 | D13: =Sheet1!D13-AVERAGE(Sheet1!$BG13:$BI13) -> 0.0012333333 | E13: =Sheet1!E13-AVERAGE(Sheet1!$BG13:$BI13) -> 0.070133333 | F13: =Sheet1!F13-AVERAGE(Sheet1!$BG13:$BI13) -> 0.14123333 | G13: =Sheet1!G13-AVERAGE(Sheet1!$BG13:$BI13) -> 0.19343333 | H13: =Sheet1!H13-AVERAGE(Sheet1!$BG13:$BI13) -> 0.12263333 | I13: =Sheet1!I13-AVERAGE(Sheet1!$BG13:$BI13) -> 0.059733333 | ... BF13: =Sheet1!BF13-AVERAGE(Sheet1!$BG13:$BI13) -> 0.16103333 | BG13: =Sheet1!BJ13-AVERAGE(Sheet1!$BS13:$BU13) -> 0.22393333 | BH13: =Sheet1!BK13-AVERAGE(Sheet1!$BS13:$BU13) -> 0.032833333 | BI13: =Sheet1!BL13-AVERAGE(Sheet1!$BS13:$BU13) -> 0.18273333 | BJ13: =Sheet1!BM13-AVERAGE(Sheet1!$BS13:$BU13) -> 0.074033333 | BK13: =Sheet1!BN13-AVERAGE(Sheet1!$BS13:$BU13) -> 0.028633333 | BL13: =Sheet1!BO13-AVERAGE(Sheet1!$BS13:$BU13) -> 0.039733333 | BM13: =Sheet1!BP13-AVERAGE(Sheet1!$BS13:$BU13) -> 0.29013333 | BN13: =Sheet1!BQ13-AVERAGE(Sheet1!$BS13:$BU13) -> 0.36083333 | BO13: =Sheet1!BR13-AVERAGE(Sheet1!$BS13:$BU13) -> 0.14153333 | BP13: =Sheet1!BV13-AVERAGE(Sheet1!$CE13:$CG13) -> 0.21576667 | BQ13: =Sheet1!BW13-AVERAGE(Sheet1!$CE13:$CG13) -> 0.020766667 | BR13: =Sheet1!BX13-AVERAGE(Sheet1!$CE13:$CG13) -> 0.18126667 | BS13: =Sheet1!BY13-AVERAGE(Sheet1!$CE13:$CG13) -> 0.082266667 | BT13: =Sheet1!BZ13-AVERAGE(Sheet1!$CE13:$CG13) -> 0.031466667 | BU13: =Sheet1!CA13-AVERAGE(Sheet1!$CE13:$CG13) -> 0.039666667 | BV13: =Sheet1!CB13-AVERAGE(Sheet1!$CE13:$CG13) -> 0.31146667 | BW13: =Sheet1!CC13-AVERAGE(Sheet1!$CE13:$CG13) -> 0.28596667 | BX13: =Sheet1!CD13-AVERAGE(Sheet1!$CE13:$CG13) -> 0.14506667 | BY13: =Sheet1!CH13-AVERAGE(Sheet1!$CQ13:$CS13) -> 0.26053333 | BZ13: =Sheet1!CI13-AVERAGE(Sheet1!$CQ13:$CS13) -> 0.045633333 | CA13: =Sheet1!CJ13-AVERAGE(Sheet1!$CQ13:$CS13) -> 0.17643333 | CB13: =Sheet1!CK13-AVERAGE(Sheet1!$CQ13:$CS13) -> 0.099233333 | CC13: =Sheet1!CL13-AVERAGE(Sheet1!$CQ13:$CS13) -> 0.039533333 | CD13: =Sheet1!CM13-AVERAGE(Sheet1!$CQ13:$CS13) -> 0.036933333 | CE13: =Sheet1!CN13-AVERAGE(Sheet1!$CQ13:$CS13) -> 0.30333333 | CF13: =Sheet1!CO13-AVERAGE(Sheet1!$CQ13:$CS13) -> 0.34703333 | CG13: =Sheet1!CP13-AVERAGE(Sheet1!$CQ13:$CS13) -> 0.14673333
... A49: =HOUR(Sheet1!A49) + MINUTE(Sheet1!A49)/60 + SECOND(Sheet1!A49)/3600 -> 23.997222 | B49: =Sheet1!B49-AVERAGE(Sheet1!$BG49:$BI49) -> 0.64876667 | C49: =Sheet1!C49-AVERAGE(Sheet1!$BG49:$BI49) -> 0.37506667 | D49: =Sheet1!D49-AVERAGE(Sheet1!$BG49:$BI49) -> 0.00096666667 | E49: =Sheet1!E49-AVERAGE(Sheet1!$BG49:$BI49) -> 0.35196667 | F49: =Sheet1!F49-AVERAGE(Sheet1!$BG49:$BI49) -> 0.43276667 | G49: =Sheet1!G49-AVERAGE(Sheet1!$BG49:$BI49) -> 0.47286667 | H49: =Sheet1!H49-AVERAGE(Sheet1!$BG49:$BI49) -> 0.29536667 | I49: =Sheet1!I49-AVERAGE(Sheet1!$BG49:$BI49) -> 0.12556667 | ... BF49: =Sheet1!BF49-AVERAGE(Sheet1!$BG49:$BI49) -> 0.26286667 | BG49: =Sheet1!BJ49-AVERAGE(Sheet1!$BS49:$BU49) -> 0.45116667 | BH49: =Sheet1!BK49-AVERAGE(Sheet1!$BS49:$BU49) -> 0.052666667 | BI49: =Sheet1!BL49-AVERAGE(Sheet1!$BS49:$BU49) -> 0.38646667 | BJ49: =Sheet1!BM49-AVERAGE(Sheet1!$BS49:$BU49) -> 0.30356667 | BK49: =Sheet1!BN49-AVERAGE(Sheet1!$BS49:$BU49) -> 0.028766667 | BL49: =Sheet1!BO49-AVERAGE(Sheet1!$BS49:$BU49) -> 0.077566667 | BM49: =Sheet1!BP49-AVERAGE(Sheet1!$BS49:$BU49) -> 0.71176667 | BN49: =Sheet1!BQ49-AVERAGE(Sheet1!$BS49:$BU49) -> 0.49406667 | BO49: =Sheet1!BR49-AVERAGE(Sheet1!$BS49:$BU49) -> 0.24506667 | BP49: =Sheet1!BV49-AVERAGE(Sheet1!$CE49:$CG49) -> 0.45223333 | BQ49: =Sheet1!BW49-AVERAGE(Sheet1!$CE49:$CG49) -> 0.34953333 | BR49: =Sheet1!BX49-AVERAGE(Sheet1!$CE49:$CG49) -> 0.38993333 | BS49: =Sheet1!BY49-AVERAGE(Sheet1!$CE49:$CG49) -> 0.30033333 | BT49: =Sheet1!BZ49-AVERAGE(Sheet1!$CE49:$CG49) -> 0.030533333 | BU49: =Sheet1!CA49-AVERAGE(Sheet1!$CE49:$CG49) -> 0.075033333 | BV49: =Sheet1!CB49-AVERAGE(Sheet1!$CE49:$CG49) -> 0.78493333 | BW49: =Sheet1!CC49-AVERAGE(Sheet1!$CE49:$CG49) -> 0.49793333 | BX49: =Sheet1!CD49-AVERAGE(Sheet1!$CE49:$CG49) -> 0.27343333 | BY49: =Sheet1!CH49-AVERAGE(Sheet1!$CQ49:$CS49) -> 0.52646667 | BZ49: =Sheet1!CI49-AVERAGE(Sheet1!$CQ49:$CS49) -> 0.068666667 | CA49: =Sheet1!CJ49-AVERAGE(Sheet1!$CQ49:$CS49) -> 0.43716667 | CB49: =Sheet1!CK49-AVERAGE(Sheet1!$CQ49:$CS49) -> 0.33106667 | CC49: =Sheet1!CL49-AVERAGE(Sheet1!$CQ49:$CS49) -> 0.038966667 | CD49: =Sheet1!CM49-AVERAGE(Sheet1!$CQ49:$CS49) -> 0.060066667 | CE49: =Sheet1!CN49-AVERAGE(Sheet1!$CQ49:$CS49) -> 0.75326667 | CF49: =Sheet1!CO49-AVERAGE(Sheet1!$CQ49:$CS49) -> 0.53126667 | CG49: =Sheet1!CP49-AVERAGE(Sheet1!$CQ49:$CS49) -> 0.24886667
A50: =HOUR(Sheet1!A50) + MINUTE(Sheet1!A50)/60 + SECOND(Sheet1!A50)/3600 + 24 -> 24.497222 | B50: =Sheet1!B50-AVERAGE(Sheet1!$BG50:$BI50) -> 0.64096667 | C50: =Sheet1!C50-AVERAGE(Sheet1!$BG50:$BI50) -> 0.37376667 | D50: =Sheet1!D50-AVERAGE(Sheet1!$BG50:$BI50) -> 0.0011666667 | E50: =Sheet1!E50-AVERAGE(Sheet1!$BG50:$BI50) -> 0.35656667 | F50: =Sheet1!F50-AVERAGE(Sheet1!$BG50:$BI50) -> 0.42566667 | G50: =Sheet1!G50-AVERAGE(Sheet1!$BG50:$BI50) -> 0.47716667 | H50: =Sheet1!H50-AVERAGE(Sheet1!$BG50:$BI50) -> 0.29576667 | I50: =Sheet1!I50-AVERAGE(Sheet1!$BG50:$BI50) -> 0.12606667 | ... BF50: =Sheet1!BF50-AVERAGE(Sheet1!$BG50:$BI50) -> 0.27106667 | BG50: =Sheet1!BJ50-AVERAGE(Sheet1!$BS50:$BU50) -> 0.4527 | BH50: =Sheet1!BK50-AVERAGE(Sheet1!$BS50:$BU50) -> 0.0544 | BI50: =Sheet1!BL50-AVERAGE(Sheet1!$BS50:$BU50) -> 0.3902 | BJ50: =Sheet1!BM50-AVERAGE(Sheet1!$BS50:$BU50) -> 0.3085 | BK50: =Sheet1!BN50-AVERAGE(Sheet1!$BS50:$BU50) -> 0.0299 | BL50: =Sheet1!BO50-AVERAGE(Sheet1!$BS50:$BU50) -> 0.0785 | BM50: =Sheet1!BP50-AVERAGE(Sheet1!$BS50:$BU50) -> 0.7796 | BN50: =Sheet1!BQ50-AVERAGE(Sheet1!$BS50:$BU50) -> 0.4921 | BO50: =Sheet1!BR50-AVERAGE(Sheet1!$BS50:$BU50) -> 0.2435 | BP50: =Sheet1!BV50-AVERAGE(Sheet1!$CE50:$CG50) -> 0.45986667 | BQ50: =Sheet1!BW50-AVERAGE(Sheet1!$CE50:$CG50) -> 0.36596667 | BR50: =Sheet1!BX50-AVERAGE(Sheet1!$CE50:$CG50) -> 0.39086667 | BS50: =Sheet1!BY50-AVERAGE(Sheet1!$CE50:$CG50) -> 0.30676667 | BT50: =Sheet1!BZ50-AVERAGE(Sheet1!$CE50:$CG50) -> 0.030266667 | BU50: =Sheet1!CA50-AVERAGE(Sheet1!$CE50:$CG50) -> 0.075966667 | BV50: =Sheet1!CB50-AVERAGE(Sheet1!$CE50:$CG50) -> 0.79156667 | BW50: =Sheet1!CC50-AVERAGE(Sheet1!$CE50:$CG50) -> 0.49326667 | BX50: =Sheet1!CD50-AVERAGE(Sheet1!$CE50:$CG50) -> 0.27756667 | BY50: =Sheet1!CH50-AVERAGE(Sheet1!$CQ50:$CS50) -> 0.52016667 | BZ50: =Sheet1!CI50-AVERAGE(Sheet1!$CQ50:$CS50) -> 0.072066667 | CA50: =Sheet1!CJ50-AVERAGE(Sheet1!$CQ50:$CS50) -> 0.44416667 | CB50: =Sheet1!CK50-AVERAGE(Sheet1!$CQ50:$CS50) -> 0.33786667 | CC50: =Sheet1!CL50-AVERAGE(Sheet1!$CQ50:$CS50) -> 0.038066667 | CD50: =Sheet1!CM50-AVERAGE(Sheet1!$CQ50:$CS50) -> 0.060466667 | CE50: =Sheet1!CN50-AVERAGE(Sheet1!$CQ50:$CS50) -> 0.75696667 | CF50: =Sheet1!CO50-AVERAGE(Sheet1!$CQ50:$CS50) -> 0.52776667 | CG50: =Sheet1!CP50-AVERAGE(Sheet1!$CQ50:$CS50) -> 0.24746667
A51: =HOUR(Sheet1!A51) + MINUTE(Sheet1!A51)/60 + SECOND(Sheet1!A51)/3600 + 24 -> 24.997222 | B51: =Sheet1!B51-AVERAGE(Sheet1!$BG51:$BI51) -> 0.62593333 | C51: =Sheet1!C51-AVERAGE(Sheet1!$BG51:$BI51) -> 0.37273333 | D51: =Sheet1!D51-AVERAGE(Sheet1!$BG51:$BI51) -> 0.0012333333 | E51: =Sheet1!E51-AVERAGE(Sheet1!$BG51:$BI51) -> 0.36133333 | F51: =Sheet1!F51-AVERAGE(Sheet1!$BG51:$BI51) -> 0.42563333 | G51: =Sheet1!G51-AVERAGE(Sheet1!$BG51:$BI51) -> 0.48203333 | H51: =Sheet1!H51-AVERAGE(Sheet1!$BG51:$BI51) -> 0.30093333 | I51: =Sheet1!I51-AVERAGE(Sheet1!$BG51:$BI51) -> 0.12623333 | ... BF51: =Sheet1!BF51-AVERAGE(Sheet1!$BG51:$BI51) -> 0.26473333 | BG51: =Sheet1!BJ51-AVERAGE(Sheet1!$BS51:$BU51) -> 0.44363333 | BH51: =Sheet1!BK51-AVERAGE(Sheet1!$BS51:$BU51) -> 0.054733333 | BI51: =Sheet1!BL51-AVERAGE(Sheet1!$BS51:$BU51) -> 0.38913333 | BJ51: =Sheet1!BM51-AVERAGE(Sheet1!$BS51:$BU51) -> 0.31173333 | BK51: =Sheet1!BN51-AVERAGE(Sheet1!$BS51:$BU51) -> 0.030033333 | BL51: =Sheet1!BO51-AVERAGE(Sheet1!$BS51:$BU51) -> 0.079933333 | BM51: =Sheet1!BP51-AVERAGE(Sheet1!$BS51:$BU51) -> 0.77813333 | BN51: =Sheet1!BQ51-AVERAGE(Sheet1!$BS51:$BU51) -> 0.49393333 | BO51: =Sheet1!BR51-AVERAGE(Sheet1!$BS51:$BU51) -> 0.24343333 | BP51: =Sheet1!BV51-AVERAGE(Sheet1!$CE51:$CG51) -> 0.46973333 | BQ51: =Sheet1!BW51-AVERAGE(Sheet1!$CE51:$CG51) -> 0.38143333 | BR51: =Sheet1!BX51-AVERAGE(Sheet1!$CE51:$CG51) -> 0.39403333 | BS51: =Sheet1!BY51-AVERAGE(Sheet1!$CE51:$CG51) -> 0.31123333 | BT51: =Sheet1!BZ51-AVERAGE(Sheet1!$CE51:$CG51) -> 0.030533333 | BU51: =Sheet1!CA51-AVERAGE(Sheet1!$CE51:$CG51) -> 0.076933333 | BV51: =Sheet1!CB51-AVERAGE(Sheet1!$CE51:$CG51) -> 0.79833333 | BW51: =Sheet1!CC51-AVERAGE(Sheet1!$CE51:$CG51) -> 0.49663333 | BX51: =Sheet1!CD51-AVERAGE(Sheet1!$CE51:$CG51) -> 0.27763333 | BY51: =Sheet1!CH51-AVERAGE(Sheet1!$CQ51:$CS51) -> 0.51783333 | BZ51: =Sheet1!CI51-AVERAGE(Sheet1!$CQ51:$CS51) -> 0.063833333 | CA51: =Sheet1!CJ51-AVERAGE(Sheet1!$CQ51:$CS51) -> 0.44573333 | CB51: =Sheet1!CK51-AVERAGE(Sheet1!$CQ51:$CS51) -> 0.34253333 | CC51: =Sheet1!CL51-AVERAGE(Sheet1!$CQ51:$CS51) -> 0.038833333 | CD51: =Sheet1!CM51-AVERAGE(Sheet1!$CQ51:$CS51) -> 0.060833333 | CE51: =Sheet1!CN51-AVERAGE(Sheet1!$CQ51:$CS51) -> 0.78393333 | CF51: =Sheet1!CO51-AVERAGE(Sheet1!$CQ51:$CS51) -> 0.52703333 | CG51: =Sheet1!CP51-AVERAGE(Sheet1!$CQ51:$CS51) -> 0.24933333
A52: =HOUR(Sheet1!A52) + MINUTE(Sheet1!A52)/60 + SECOND(Sheet1!A52)/3600 + 24 -> 25.497222 | B52: =Sheet1!B52-AVERAGE(Sheet1!$BG52:$BI52) -> 0.6262 | C52: =Sheet1!C52-AVERAGE(Sheet1!$BG52:$BI52) -> 0.3756 | D52: =Sheet1!D52-AVERAGE(Sheet1!$BG52:$BI52) -> 0.0013 | E52: =Sheet1!E52-AVERAGE(Sheet1!$BG52:$BI52) -> 0.3651 | F52: =Sheet1!F52-AVERAGE(Sheet1!$BG52:$BI52) -> 0.4233 | G52: =Sheet1!G52-AVERAGE(Sheet1!$BG52:$BI52) -> 0.4867 | H52: =Sheet1!H52-AVERAGE(Sheet1!$BG52:$BI52) -> 0.2997 | I52: =Sheet1!I52-AVERAGE(Sheet1!$BG52:$BI52) -> 0.1273 | ... BF52: =Sheet1!BF52-AVERAGE(Sheet1!$BG52:$BI52) -> 0.2686 | BG52: =Sheet1!BJ52-AVERAGE(Sheet1!$BS52:$BU52) -> 0.4407 | BH52: =Sheet1!BK52-AVERAGE(Sheet1!$BS52:$BU52) -> 0.0554 | BI52: =Sheet1!BL52-AVERAGE(Sheet1!$BS52:$BU52) -> 0.3933 | BJ52: =Sheet1!BM52-AVERAGE(Sheet1!$BS52:$BU52) -> 0.3162 | BK52: =Sheet1!BN52-AVERAGE(Sheet1!$BS52:$BU52) -> 0.0291 | BL52: =Sheet1!BO52-AVERAGE(Sheet1!$BS52:$BU52) -> 0.0807 | BM52: =Sheet1!BP52-AVERAGE(Sheet1!$BS52:$BU52) -> 0.7772 | BN52: =Sheet1!BQ52-AVERAGE(Sheet1!$BS52:$BU52) -> 0.4917 | BO52: =Sheet1!BR52-AVERAGE(Sheet1!$BS52:$BU52) -> 0.2481 | BP52: =Sheet1!BV52-AVERAGE(Sheet1!$CE52:$CG52) -> 0.4673 | BQ52: =Sheet1!BW52-AVERAGE(Sheet1!$CE52:$CG52) -> 0.3931 | BR52: =Sheet1!BX52-AVERAGE(Sheet1!$CE52:$CG52) -> 0.3937 | BS52: =Sheet1!BY52-AVERAGE(Sheet1!$CE52:$CG52) -> 0.3164 | BT52: =Sheet1!BZ52-AVERAGE(Sheet1!$CE52:$CG52) -> 0.0305 | BU52: =Sheet1!CA52-AVERAGE(Sheet1!$CE52:$CG52) -> 0.0781 | BV52: =Sheet1!CB52-AVERAGE(Sheet1!$CE52:$CG52) -> 0.8008 | BW52: =Sheet1!CC52-AVERAGE(Sheet1!$CE52:$CG52) -> 0.4934 | BX52: =Sheet1!CD52-AVERAGE(Sheet1!$CE52:$CG52) -> 0.2796 | BY52: =Sheet1!CH52-AVERAGE(Sheet1!$CQ52:$CS52) -> 0.52003333 | BZ52: =Sheet1!CI52-AVERAGE(Sheet1!$CQ52:$CS52) -> 0.068033333 | CA52: =Sheet1!CJ52-AVERAGE(Sheet1!$CQ52:$CS52) -> 0.44833333 | CB52: =Sheet1!CK52-AVERAGE(Sheet1!$CQ52:$CS52) -> 0.34753333 | CC52: =Sheet1!CL52-AVERAGE(Sheet1!$CQ52:$CS52) -> 0.038533333 | CD52: =Sheet1!CM52-AVERAGE(Sheet1!$CQ52:$CS52) -> 0.061233333 | CE52: =Sheet1!CN52-AVERAGE(Sheet1!$CQ52:$CS52) -> 0.81353333 | CF52: =Sheet1!CO52-AVERAGE(Sheet1!$CQ52:$CS52) -> 0.52563333 | CG52: =Sheet1!CP52-AVERAGE(Sheet1!$CQ52:$CS52) -> 0.24793333
