Workbook

Sheet OD590
A1: strain | B1: time | C1: timepoint | D1: water_1 | E1: Beta-Methyl-D-Glucoside_1 | F1: D-Galactonic-Acid-Gamma-Lactone_1 | G1: L-Arginine_1 | H1: water_2 | I1: Beta-Methyl-D-Glucoside_2 | J1: D-Galactonic-Acid-Gamma-Lactone_2 | K1: L-Arginine_2 | L1: water_3 | M1: Beta-Methyl-D-Glucoside_3 | N1: D-Galactonic-Acid-Gamma-Lactone_3 | O1: L-Arginine_3 | P1: Pyruvic-Acid-Methyl-Ester_1 | Q1: D-Xylose_1 | R1: D-Galacturonic-Acid_1 | S1: L-Asparagine_1 | T1: Pyruvic-Acid-Methyl-Ester_2 | U1: D-Xylose_2 | V1: D-Galacturonic-Acid_2 | W1: L-Asparagine_2 | X1: Pyruvic-Acid-Methyl-Ester_3 | Y1: D-Xylose_3 | Z1: D-Galacturonic-Acid_3 | AA1: L-Asparagine_3 | AB1: Tween-40_1 | AC1: I-Erythriol_1 | AD1: 2-Hydroxy-Benzoic-Acid_1 | AE1: Phenylalanine_1 | AF1: Tween-40_2 | AG1: I-Erythriol_2 | AH1: 2-Hydroxy-Benzoic-Acid_2 | AI1: Phenylalanine_2 | AJ1: Tween-40_3 | AK1: I-Erythriol_3 | AL1: 2-Hydroxy-Benzoic-Acid_3 | AM1: Phenylalanine_3 | AN1: Tween-80_1 | AO1: D-Mannitol_1 | AP1: 4-Hydroxy-Benzoic-Acid_1 | AQ1: L-Serine_1 | AR1: Tween-80_2 | AS1: D-Mannitol_2 | AT1: 4-Hydroxy-Benzoic-Acid_2 | AU1: L-Serine_2 | AV1: Tween-80_3 | AW1: D-Mannitol_3 | AX1: 4-Hydroxy-Benzoic-Acid_3 | AY1: L-Serine_3 | AZ1: Cyclodextrin_1 | BA1: N-Acetyl-D-Glucosamine_1 | BB1: Gamma-Amino-Butyric-Acid_1 | BC1: L-Threonine_1 | BD1: Cyclodextrin_2 | BE1: N-Acetyl-D-Glucosamine_2 | BF1: Gamma-Hydroxybutyric-Acid_2 | BG1: L-Threonine_2 | BH1: Cyclodextrin_3 | BI1: N-Acetyl-D-Glucosamine_3 | BJ1: Gamma-Hydroxybutyric-Acid_3 | BK1: L-Threonine_3 | BL1: Glycogen_1 | BM1: D-Glucosaminic-Acid_1 | BN1: Itaconic-Acid_1 | BO1: Glycyl-L-Glutamic-Acid_1 | BP1: Glycogen_2 | BQ1: D-Glucosaminic-Acid_2 | BR1: Itaconic-Acid_2 | BS1: Glycyl-L-Glutamic-Acid_2 | BT1: Glycogen_3 | BU1: D-Glucosaminic-Acid_3 | BV1: Itaconic-Acid_3 | BW1: Glycyl-L-Glutamic-Acid_3 | BX1: D-Cellobiose_1 | BY1: Glucose-1-Phosphate_1 | BZ1: Alpha-Ketobutyric-Acid_1 | CA1: Phenylethyl-amine_1 | CB1: D-Cellobiose_2 | CC1: Glucose-1-Phosphate_2 | CD1: Alpha-Ketobutyric-Acid_2 | CE1: Phenylethyl-amine_2 | CF1: D-Cellobiose_3 | CG1: Glucose-1-Phosphate_3 | CH1: Alpha-Ketobutyric-Acid_3 | CI1: Phenylethyl-amine_3 | CJ1: Alpha-D-Lactose_1 | CK1: D,L-Alpha-Glycerol-Phosphate_1 | CL1: D-Malic-Acid_1 | CM1: Putrescine_1 | CN1: Alpha-D-Lactose_2 | CO1: D,L-Alpha-Glycerol-Phosphate_2 | CP1: D-Malic-Acid_2 | CQ1: Putrescine_2 | CR1: Alpha-D-Lactose_3 | CS1: D,L-Alpha-Glycerol-Phosphate_3 | CT1: D-Malic-Acid_3 | CU1: Putrescine_3
A2: 6146 | B2: 8.1018519e-05 | C2: T0 | D2: 0.117 | E2: 0.125 | F2: 0.118 | G2: 0.116 | H2: 0.119 | I2: 0.119 | J2: 0.12 | K2: 0.116 | L2: 0.12 | M2: 0.206 | N2: 0.119 | O2: 0.122 | P2: 0.123 | Q2: 0.141 | R2: 0.118 | S2: 0.12 | T2: 0.117 | U2: 0.143 | V2: 0.116 | W2: 0.115 | X2: 0.119 | Y2: 0.146 | Z2: 0.115 | AA2: 0.115 | AB2: 0.169 | AC2: 0.117 | AD2: 0.12 | AE2: 0.119 | AF2: 0.191 | AG2: 0.117 | AH2: 0.121 | AI2: 0.115 | AJ2: 0.189 | AK2: 0.118 | AL2: 0.12 | AM2: 0.115 | AN2: 0.12 | AO2: 0.115 | AP2: 0.116 | AQ2: 0.115 | AR2: 0.12 | AS2: 0.117 | AT2: 0.114 | AU2: 0.182 | AV2: 0.123 | AW2: 0.113 | AX2: 0.115 | AY2: 0.171 | AZ2: 0.131 | BA2: 0.115 | BB2: 0.117 | BC2: 0.155 | BD2: 0.131 | BE2: 0.116 | BF2: 0.214 | BG2: 0.114 | BH2: 0.124 | BI2: 0.118 | BJ2: 0.186 | BK2: 0.115 | BL2: 0.121 | BM2: 0.119 | BN2: 0.118 | BO2: 0.121 | BP2: 0.122 | BQ2: 0.12 | BR2: 0.177 | BS2: 0.122 | BT2: 0.121 | BU2: 0.118 | BV2: 0.116 | BW2: 0.153 | BX2: 0.121 | BY2: 0.117 | BZ2: 0.114 | CA2: 0.119 | CB2: 0.118 | CC2: 0.116 | CD2: 0.116 | CE2: 0.134 | CF2: 0.117 | CG2: 0.116 | CH2: 0.116 | CI2: 0.124 | CJ2: 0.117 | CK2: 0.116 | CL2: 0.116 | CM2: 0.116 | CN2: 0.12 | CO2: 0.159 | CP2: 0.121 | CQ2: 0.118 | CR2: 0.116 | CS2: 0.118 | CT2: 0.118 | CU2: 0.118
A3: 6146 | B3: 0.78423611 | C3: T1 | D3: 0.151 | E3: 0.145 | F3: 0.2 | G3: 0.145 | H3: 0.14 | I3: 0.14 | J3: 0.182 | K3: 0.139 | L3: 0.154 | M3: 0.149 | N3: 0.164 | O3: 0.14 | P3: 0.256 | Q3: 0.151 | R3: 0.156 | S3: 0.251 | T3: 0.254 | U3: 0.151 | V3: 0.149 | W3: 0.292 | X3: 0.34 | Y3: 0.19 | Z3: 0.157 | AA3: 0.255 | AB3: 0.401 | AC3: 0.138 | AD3: 0.108 | AE3: 0.174 | AF3: 0.362 | AG3: 0.136 | AH3: 0.109 | AI3: 0.177 | AJ3: 0.402 | AK3: 0.154 | AL3: 0.145 | AM3: 0.165 | AN3: 0.277 | AO3: 0.325 | AP3: 0.172 | AQ3: 0.138 | AR3: 0.283 | AS3: 0.32 | AT3: 0.148 | AU3: 0.138 | AV3: 0.285 | AW3: 0.445 | AX3: 0.18 | AY3: 0.144 | AZ3: 0.144 | BA3: 0.157 | BB3: 0.179 | BC3: 0.138 | BD3: 0.147 | BE3: 0.172 | BF3: 0.187 | BG3: 0.129 | BH3: 0.149 | BI3: 0.186 | BJ3: 0.259 | BK3: 0.132 | BL3: 0.148 | BM3: 0.165 | BN3: 0.154 | BO3: 0.461 | BP3: 0.159 | BQ3: 0.165 | BR3: 0.147 | BS3: 0.473 | BT3: 0.158 | BU3: 0.148 | BV3: 0.158 | BW3: 0.308 | BX3: 0.152 | BY3: 0.138 | BZ3: 0.136 | CA3: 0.141 | CB3: 0.149 | CC3: 0.16 | CD3: 0.138 | CE3: 0.147 | CF3: 0.167 | CG3: 0.162 | CH3: 0.136 | CI3: 0.13 | CJ3: 0.137 | CK3: 0.142 | CL3: 0.187 | CM3: 0.167 | CN3: 0.139 | CO3: 0.146 | CP3: 0.184 | CQ3: 0.173 | CR3: 0.151 | CS3: 0.149 | CT3: 0.208 | CU3: 0.137
A4: 6146 | B4: 1.0240509 | C4: T2 | D4: 0.138 | E4: 0.144 | F4: 0.187 | G4: 0.138 | H4: 0.142 | I4: 0.141 | J4: 0.189 | K4: 0.138 | L4: 0.163 | M4: 0.14 | N4: 0.182 | O4: 0.142 | P4: 0.339 | Q4: 0.152 | R4: 0.154 | S4: 0.396 | T4: 0.359 | U4: 0.154 | V4: 0.156 | W4: 0.422 | X4: 0.366 | Y4: 0.174 | Z4: 0.153 | AA4: 0.362 | AB4: 0.483 | AC4: 0.136 | AD4: 0.107 | AE4: 0.202 | AF4: 0.486 | AG4: 0.136 | AH4: 0.109 | AI4: 0.192 | AJ4: 0.459 | AK4: 0.145 | AL4: 0.147 | AM4: 0.199 | AN4: 0.347 | AO4: 0.481 | AP4: 0.24 | AQ4: 0.141 | AR4: 0.377 | AS4: 0.482 | AT4: 0.171 | AU4: 0.147 | AV4: 0.379 | AW4: 0.446 | AX4: 0.223 | AY4: 0.139 | AZ4: 0.144 | BA4: 0.178 | BB4: 0.236 | BC4: 0.161 | BD4: 0.146 | BE4: 0.172 | BF4: 0.245 | BG4: 0.136 | BH4: 0.149 | BI4: 0.179 | BJ4: 0.235 | BK4: 0.136 | BL4: 0.149 | BM4: 0.147 | BN4: 0.149 | BO4: 0.499 | BP4: 0.154 | BQ4: 0.151 | BR4: 0.146 | BS4: 0.51 | BT4: 0.152 | BU4: 0.192 | BV4: 0.145 | BW4: 0.431 | BX4: 0.149 | BY4: 0.136 | BZ4: 0.144 | CA4: 0.133 | CB4: 0.15 | CC4: 0.135 | CD4: 0.149 | CE4: 0.134 | CF4: 0.195 | CG4: 0.177 | CH4: 0.147 | CI4: 0.129 | CJ4: 0.137 | CK4: 0.143 | CL4: 0.223 | CM4: 0.137 | CN4: 0.142 | CO4: 0.142 | CP4: 0.217 | CQ4: 0.14 | CR4: 0.138 | CS4: 0.14 | CT4: 0.216 | CU4: 0.138
A5: 6146 | B5: 1.7511806 | C5: T3 | D5: 0.143 | E5: 0.146 | F5: 0.263 | G5: 0.144 | H5: 0.145 | I5: 0.144 | J5: 0.269 | K5: 0.14 | L5: 0.173 | M5: 0.146 | N5: 0.263 | O5: 0.145 | P5: 0.929 | Q5: 0.198 | R5: 0.184 | S5: 0.811 | T5: 0.85 | U5: 0.165 | V5: 0.178 | W5: 0.837 | X5: 0.834 | Y5: 0.243 | Z5: 0.166 | AA5: 0.897 | AB5: 0.948 | AC5: 0.158 | AD5: 0.132 | AE5: 0.491 | AF5: 0.893 | AG5: 0.163 | AH5: 0.136 | AI5: 0.481 | AJ5: 0.875 | AK5: 0.163 | AL5: 0.159 | AM5: 0.479 | AN5: 0.668 | AO5: 0.968 | AP5: 0.333 | AQ5: 0.177 | AR5: 0.638 | AS5: 0.953 | AT5: 0.295 | AU5: 0.171 | AV5: 0.635 | AW5: 0.91 | AX5: 0.288 | AY5: 0.153 | AZ5: 0.147 | BA5: 0.463 | BB5: 0.697 | BC5: 0.164 | BD5: 0.179 | BE5: 0.504 | BF5: 0.716 | BG5: 0.187 | BH5: 0.186 | BI5: 0.517 | BJ5: 0.787 | BK5: 0.153 | BL5: 0.151 | BM5: 0.158 | BN5: 0.173 | BO5: 0.882 | BP5: 0.171 | BQ5: 0.193 | BR5: 0.205 | BS5: 0.914 | BT5: 0.19 | BU5: 0.206 | BV5: 0.217 | BW5: 0.886 | BX5: 0.151 | BY5: 0.14 | BZ5: 0.225 | CA5: 0.13 | CB5: 0.152 | CC5: 0.138 | CD5: 0.29 | CE5: 0.137 | CF5: 0.182 | CG5: 0.196 | CH5: 0.308 | CI5: 0.128 | CJ5: 0.142 | CK5: 0.148 | CL5: 0.646 | CM5: 0.142 | CN5: 0.145 | CO5: 0.147 | CP5: 0.641 | CQ5: 0.143 | CR5: 0.14 | CS5: 0.146 | CT5: 0.66 | CU5: 0.14
A6: 6146 | B6: 2.0846181 | C6: T4 | D6: 0.145 | E6: 0.146 | F6: 0.305 | G6: 0.142 | H6: 0.144 | I6: 0.143 | J6: 0.304 | K6: 0.141 | L6: 0.171 | M6: 0.144 | N6: 0.295 | O6: 0.143 | P6: 0.996 | Q6: 0.156 | R6: 0.16 | S6: 0.898 | T6: 0.942 | U6: 0.16 | V6: 0.166 | W6: 0.914 | X6: 0.898 | Y6: 0.227 | Z6: 0.159 | AA6: 0.999 | AB6: 1.016 | AC6: 0.142 | AD6: 0.104 | AE6: 0.582 | AF6: 1.125 | AG6: 0.142 | AH6: 0.105 | AI6: 0.531 | AJ6: 1.106 | AK6: 0.143 | AL6: 0.147 | AM6: 0.542 | AN6: 0.664 | AO6: 1.02 | AP6: 0.564 | AQ6: 0.154 | AR6: 0.669 | AS6: 0.996 | AT6: 0.318 | AU6: 0.156 | AV6: 0.673 | AW6: 0.942 | AX6: 0.357 | AY6: 0.153 | AZ6: 0.147 | BA6: 0.581 | BB6: 0.805 | BC6: 0.179 | BD6: 0.151 | BE6: 0.614 | BF6: 0.804 | BG6: 0.169 | BH6: 0.154 | BI6: 0.606 | BJ6: 0.857 | BK6: 0.165 | BL6: 0.154 | BM6: 0.163 | BN6: 0.19 | BO6: 0.923 | BP6: 0.154 | BQ6: 0.167 | BR6: 0.196 | BS6: 0.939 | BT6: 0.154 | BU6: 0.168 | BV6: 0.184 | BW6: 0.936 | BX6: 0.151 | BY6: 0.139 | BZ6: 0.301 | CA6: 0.128 | CB6: 0.153 | CC6: 0.138 | CD6: 0.378 | CE6: 0.13 | CF6: 0.149 | CG6: 0.14 | CH6: 0.32 | CI6: 0.127 | CJ6: 0.144 | CK6: 0.148 | CL6: 0.698 | CM6: 0.142 | CN6: 0.147 | CO6: 0.15 | CP6: 0.703 | CQ6: 0.145 | CR6: 0.142 | CS6: 0.148 | CT6: 0.718 | CU6: 0.14
A7: 6146 | B7: 2.7766898 | C7: T5 | D7: 0.146 | E7: 0.147 | F7: 0.648 | G7: 0.141 | H7: 0.149 | I7: 0.15 | J7: 0.629 | K7: 0.141 | L7: 0.176 | M7: 0.15 | N7: 0.579 | O7: 0.146 | P7: 1.257 | Q7: 0.156 | R7: 0.164 | S7: 1.062 | T7: 1.151 | U7: 0.159 | V7: 0.167 | W7: 1.052 | X7: 1.113 | Y7: 0.306 | Z7: 0.166 | AA7: 1.189 | AB7: 1.542 | AC7: 0.152 | AD7: 0.104 | AE7: 0.806 | AF7: 1.436 | AG7: 0.148 | AH7: 0.104 | AI7: 0.731 | AJ7: 1.41 | AK7: 0.149 | AL7: 0.143 | AM7: 0.857 | AN7: 0.669 | AO7: 1.118 | AP7: 0.626 | AQ7: 0.163 | AR7: 0.574 | AS7: 1.059 | AT7: 0.574 | AU7: 0.166 | AV7: 0.576 | AW7: 1.015 | AX7: 0.578 | AY7: 0.163 | AZ7: 0.193 | BA7: 0.767 | BB7: 0.987 | BC7: 0.213 | BD7: 0.157 | BE7: 0.772 | BF7: 0.993 | BG7: 0.222 | BH7: 0.155 | BI7: 0.765 | BJ7: 1.029 | BK7: 0.206 | BL7: 0.155 | BM7: 0.173 | BN7: 0.258 | BO7: 0.983 | BP7: 0.162 | BQ7: 0.179 | BR7: 0.257 | BS7: 0.996 | BT7: 0.159 | BU7: 0.184 | BV7: 0.247 | BW7: 1.077 | BX7: 0.155 | BY7: 0.143 | BZ7: 0.654 | CA7: 0.13 | CB7: 0.157 | CC7: 0.142 | CD7: 0.679 | CE7: 0.13 | CF7: 0.15 | CG7: 0.144 | CH7: 0.663 | CI7: 0.127 | CJ7: 0.161 | CK7: 0.157 | CL7: 1.028 | CM7: 0.147 | CN7: 0.155 | CO7: 0.152 | CP7: 1.027 | CQ7: 0.147 | CR7: 0.148 | CS7: 0.153 | CT7: 1.035 | CU7: 0.141
A8: 6146 | B8: 3.0177199 | C8: T6 | D8: 0.147 | E8: 0.147 | F8: 0.706 | G8: 0.143 | H8: 0.15 | I8: 0.15 | J8: 0.695 | K8: 0.144 | L8: 0.175 | M8: 0.15 | N8: 0.649 | O8: 0.156 | P8: 1.274 | Q8: 0.15 | R8: 0.164 | S8: 1.111 | T8: 1.173 | U8: 0.156 | V8: 0.171 | W8: 1.116 | X8: 1.142 | Y8: 0.358 | Z8: 0.169 | AA8: 1.249 | AB8: 1.667 | AC8: 0.152 | AD8: 0.103 | AE8: 0.839 | AF8: 1.639 | AG8: 0.149 | AH8: 0.103 | AI8: 0.765 | AJ8: 1.615 | AK8: 0.15 | AL8: 0.144 | AM8: 0.879 | AN8: 0.665 | AO8: 1.102 | AP8: 0.715 | AQ8: 0.167 | AR8: 0.568 | AS8: 1.064 | AT8: 0.653 | AU8: 0.166 | AV8: 0.593 | AW8: 1.096 | AX8: 0.659 | AY8: 0.168 | AZ8: 0.203 | BA8: 0.788 | BB8: 1.022 | BC8: 0.251 | BD8: 0.158 | BE8: 0.796 | BF8: 1.029 | BG8: 0.246 | BH8: 0.158 | BI8: 0.793 | BJ8: 1.053 | BK8: 0.226 | BL8: 0.154 | BM8: 0.176 | BN8: 0.287 | BO8: 0.981 | BP8: 0.161 | BQ8: 0.181 | BR8: 0.288 | BS8: 0.992 | BT8: 0.159 | BU8: 0.186 | BV8: 0.275 | BW8: 1.069 | BX8: 0.155 | BY8: 0.143 | BZ8: 0.678 | CA8: 0.13 | CB8: 0.159 | CC8: 0.144 | CD8: 0.695 | CE8: 0.13 | CF8: 0.157 | CG8: 0.146 | CH8: 0.685 | CI8: 0.128 | CJ8: 0.171 | CK8: 0.156 | CL8: 1.037 | CM8: 0.148 | CN8: 0.158 | CO8: 0.152 | CP8: 1.028 | CQ8: 0.147 | CR8: 0.152 | CS8: 0.155 | CT8: 1.045 | CU8: 0.154
A9: 6146 | B9: 5.9726157 | C9: T7 | D9: 0.159 | E9: 0.162 | F9: 1.161 | G9: 0.157 | H9: 0.168 | I9: 0.169 | J9: 1.286 | K9: 0.157 | L9: 0.183 | M9: 0.171 | N9: 1.157 | O9: 0.161 | P9: 1.143 | Q9: 0.142 | R9: 0.195 | S9: 1.754 | T9: 1.405 | U9: 0.177 | V9: 0.209 | W9: 1.331 | X9: 1.672 | Y9: 1.625 | Z9: 0.203 | AA9: 1.986 | AB9: 1.403 | AC9: 0.176 | AD9: 0.101 | AE9: 1.066 | AF9: 1.79 | AG9: 0.17 | AH9: 0.1 | AI9: 0.964 | AJ9: 2.42 | AK9: 0.181 | AL9: 0.134 | AM9: 1.044 | AN9: 0.641 | AO9: 0.817 | AP9: 0.789 | AQ9: 0.235 | AR9: 0.618 | AS9: 0.822 | AT9: 0.763 | AU9: 0.23 | AV9: 0.585 | AW9: 0.798 | AX9: 0.798 | AY9: 0.22 | AZ9: 0.256 | BA9: 0.839 | BB9: 1.148 | BC9: 1.313 | BD9: 0.187 | BE9: 0.817 | BF9: 1.108 | BG9: 1.321 | BH9: 0.183 | BI9: 0.846 | BJ9: 1.195 | BK9: 1.28 | BL9: 0.17 | BM9: 0.228 | BN9: 1.122 | BO9: 0.95 | BP9: 0.175 | BQ9: 0.234 | BR9: 1.135 | BS9: 0.796 | BT9: 0.173 | BU9: 0.239 | BV9: 1.182 | BW9: 0.674 | BX9: 0.179 | BY9: 0.156 | BZ9: 0.837 | CA9: 0.13 | CB9: 0.192 | CC9: 0.157 | CD9: 0.758 | CE9: 0.13 | CF9: 0.18 | CG9: 0.161 | CH9: 0.746 | CI9: 0.128 | CJ9: 1.395 | CK9: 0.176 | CL9: 1.424 | CM9: 0.161 | CN9: 1.143 | CO9: 0.172 | CP9: 1.47 | CQ9: 0.165 | CR9: 1.235 | CS9: 0.177 | CT9: 1.466 | CU9: 0.166
A10: 6146 | B10: 7.8131134 | C10: T8 | D10: 0.167 | E10: 0.168 | F10: 1.752 | G10: 0.163 | H10: 0.178 | I10: 0.18 | J10: 1.363 | K10: 0.162 | L10: 0.182 | M10: 0.187 | N10: 1.315 | O10: 0.195 | P10: 1.44 | Q10: 0.136 | R10: 0.234 | S10: 2.286 | T10: 1.131 | U10: 0.473 | V10: 0.247 | W10: 1.641 | X10: 1.256 | Y10: 2.096 | Z10: 0.238 | AA10: 1.79 | AB10: 1.814 | AC10: 0.182 | AD10: 0.1 | AE10: 1.26 | AF10: 2.52 | AG10: 0.177 | AH10: 0.099 | AI10: 1.241 | AJ10: 2.478 | AK10: 0.189 | AL10: 0.122 | AM10: 1.313 | AN10: 1.018 | AO10: 0.902 | AP10: 0.671 | AQ10: 0.297 | AR10: 0.61 | AS10: 0.827 | AT10: 0.727 | AU10: 0.288 | AV10: 0.715 | AW10: 0.837 | AX10: 0.769 | AY10: 0.262 | AZ10: 0.3 | BA10: 0.838 | BB10: 1.29 | BC10: 1.482 | BD10: 0.188 | BE10: 1.827 | BF10: 1.341 | BG10: 1.335 | BH10: 0.183 | BI10: 1.073 | BJ10: 1.408 | BK10: 1.556 | BL10: 0.168 | BM10: 0.27 | BN10: 1.227 | BO10: 0.59 | BP10: 0.173 | BQ10: 0.275 | BR10: 1.243 | BS10: 0.783 | BT10: 0.171 | BU10: 0.274 | BV10: 1.304 | BW10: 1.01 | BX10: 0.198 | BY10: 0.161 | BZ10: 0.765 | CA10: 0.142 | CB10: 0.211 | CC10: 0.159 | CD10: 1.052 | CE10: 0.123 | CF10: 0.195 | CG10: 0.162 | CH10: 0.785 | CI10: 0.121 | CJ10: 2.062 | CK10: 0.184 | CL10: 1.399 | CM10: 0.166 | CN10: 2.113 | CO10: 0.177 | CP10: 1.413 | CQ10: 0.165 | CR10: 1.849 | CS10: 0.18 | CT10: 1.49 | CU10: 0.191
A11: 6147 | B11: 8.1018519e-05 | C11: T0 | D11: 0.118 | E11: 0.115 | F11: 0.112 | G11: 0.113 | H11: 0.112 | I11: 0.116 | J11: 0.115 | K11: 0.118 | L11: 0.115 | M11: 0.116 | N11: 0.117 | O11: 0.114 | P11: 0.114 | Q11: 0.129 | R11: 0.117 | S11: 0.114 | T11: 0.116 | U11: 0.139 | V11: 0.119 | W11: 0.115 | X11: 0.112 | Y11: 0.139 | Z11: 0.117 | AA11: 0.118 | AB11: 0.194 | AC11: 0.111 | AD11: 0.12 | AE11: 0.125 | AF11: 0.206 | AG11: 0.111 | AH11: 0.12 | AI11: 0.115 | AJ11: 0.207 | AK11: 0.114 | AL11: 0.113 | AM11: 0.172 | AN11: 0.118 | AO11: 0.449 | AP11: 0.11 | AQ11: 0.113 | AR11: 0.119 | AS11: 0.114 | AT11: 0.117 | AU11: 0.117 | AV11: 0.121 | AW11: 0.17 | AX11: 0.115 | AY11: 0.113 | AZ11: 0.118 | BA11: 0.116 | BB11: 0.112 | BC11: 0.113 | BD11: 0.123 | BE11: 0.121 | BF11: 0.119 | BG11: 0.119 | BH11: 0.129 | BI11: 0.121 | BJ11: 0.114 | BK11: 0.119 | BL11: 0.12 | BM11: 0.113 | BN11: 0.111 | BO11: 0.116 | BP11: 0.121 | BQ11: 0.113 | BR11: 0.112 | BS11: 0.117 | BT11: 0.118 | BU11: 0.123 | BV11: 0.112 | BW11: 0.184 | BX11: 0.124 | BY11: 0.121 | BZ11: 0.113 | CA11: 0.136 | CB11: 0.116 | CC11: 0.117 | CD11: 0.112 | CE11: 0.12 | CF11: 0.118 | CG11: 0.115 | CH11: 0.112 | CI11: 0.122 | CJ11: 0.19 | CK11: 0.119 | CL11: 0.113 | CM11: 0.112 | CN11: 0.117 | CO11: 0.121 | CP11: 0.114 | CQ11: 0.728 | CR11: 0.117 | CS11: 0.122 | CT11: 0.119 | CU11: 0.115
A12: 6147 | B12: 0.78394676 | C12: T1 | D12: 0.135 | E12: 0.164 | F12: 0.118 | G12: 0.129 | H12: 0.129 | I12: 0.162 | J12: 0.125 | K12: 0.132 | L12: 0.126 | M12: 0.169 | N12: 0.127 | O12: 0.127 | P12: 0.121 | Q12: 0.135 | R12: 0.28 | S12: 0.116 | T12: 0.126 | U12: 0.147 | V12: 0.335 | W12: 0.124 | X12: 0.12 | Y12: 0.149 | Z12: 0.352 | AA12: 0.121 | AB12: 0.176 | AC12: 0.133 | AD12: 0.108 | AE12: 0.141 | AF12: 0.207 | AG12: 0.124 | AH12: 0.112 | AI12: 0.129 | AJ12: 0.2 | AK12: 0.128 | AL12: 0.11 | AM12: 0.128 | AN12: 0.136 | AO12: 0.149 | AP12: 0.119 | AQ12: 0.128 | AR12: 0.139 | AS12: 0.127 | AT12: 0.126 | AU12: 0.132 | AV12: 0.138 | AW12: 0.127 | AX12: 0.127 | AY12: 0.13 | AZ12: 0.208 | BA12: 0.159 | BB12: 0.124 | BC12: 0.117 | BD12: 0.211 | BE12: 0.172 | BF12: 0.127 | BG12: 0.129 | BH12: 0.223 | BI12: 0.161 | BJ12: 0.126 | BK12: 0.128 | BL12: 0.239 | BM12: 0.122 | BN12: 0.121 | BO12: 0.18 | BP12: 0.214 | BQ12: 0.132 | BR12: 0.123 | BS12: 0.208 | BT12: 0.214 | BU12: 0.136 | BV12: 0.129 | BW12: 0.181 | BX12: 0.168 | BY12: 0.138 | BZ12: 0.127 | CA12: 0.137 | CB12: 0.154 | CC12: 0.14 | CD12: 0.126 | CE12: 0.133 | CF12: 0.167 | CG12: 0.142 | CH12: 0.127 | CI12: 0.136 | CJ12: 0.147 | CK12: 0.141 | CL12: 0.121 | CM12: 0.127 | CN12: 0.146 | CO12: 0.146 | CP12: 0.124 | CQ12: 0.253 | CR12: 0.151 | CS12: 0.136 | CT12: 0.126 | CU12: 0.121
A13: 6147 | B13: 1.0233681 | C13: T2 | D13: 0.134 | E13: 0.164 | F13: 0.118 | G13: 0.133 | H13: 0.124 | I13: 0.156 | J13: 0.126 | K13: 0.136 | L13: 0.123 | M13: 0.164 | N13: 0.125 | O13: 0.129 | P13: 0.129 | Q13: 0.135 | R13: 0.286 | S13: 0.115 | T13: 0.122 | U13: 0.151 | V13: 0.288 | W13: 0.116 | X13: 0.12 | Y13: 0.145 | Z13: 0.336 | AA13: 0.121 | AB13: 0.187 | AC13: 0.127 | AD13: 0.108 | AE13: 0.139 | AF13: 0.22 | AG13: 0.124 | AH13: 0.113 | AI13: 0.129 | AJ13: 0.201 | AK13: 0.131 | AL13: 0.109 | AM13: 0.127 | AN13: 0.137 | AO13: 0.135 | AP13: 0.119 | AQ13: 0.124 | AR13: 0.14 | AS13: 0.123 | AT13: 0.127 | AU13: 0.132 | AV13: 0.139 | AW13: 0.129 | AX13: 0.122 | AY13: 0.121 | AZ13: 0.201 | BA13: 0.155 | BB13: 0.122 | BC13: 0.117 | BD13: 0.204 | BE13: 0.159 | BF13: 0.126 | BG13: 0.127 | BH13: 0.211 | BI13: 0.161 | BJ13: 0.122 | BK13: 0.121 | BL13: 0.229 | BM13: 0.135 | BN13: 0.122 | BO13: 0.172 | BP13: 0.21 | BQ13: 0.128 | BR13: 0.125 | BS13: 0.173 | BT13: 0.208 | BU13: 0.132 | BV13: 0.122 | BW13: 0.172 | BX13: 0.166 | BY13: 0.142 | BZ13: 0.129 | CA13: 0.133 | CB13: 0.149 | CC13: 0.146 | CD13: 0.132 | CE13: 0.13 | CF13: 0.158 | CG13: 0.138 | CH13: 0.126 | CI13: 0.131 | CJ13: 0.149 | CK13: 0.148 | CL13: 0.122 | CM13: 0.126 | CN13: 0.15 | CO13: 0.141 | CP13: 0.123 | CQ13: 0.194 | CR13: 0.142 | CS13: 0.137 | CT13: 0.125 | CU13: 0.121
... A127: 6551 | B127: 1.8000926 | C127: T3 | D127: 0.324 | E127: 0.352 | F127: 1.902 | G127: 1.163 | H127: 0.292 | I127: 0.144 | J127: 1.628 | K127: 1.188 | L127: 0.354 | M127: 0.38 | N127: 1.799 | O127: 1.167 | P127: 0.796 | Q127: 0.975 | R127: 1.424 | S127: 1.472 | T127: 2.006 | U127: 1.625 | V127: 1.321 | W127: 2.693 | X127: 2.124 | Y127: 1.282 | Z127: 1.565 | AA127: 3.005 | AB127: 1.32 | AC127: 0.345 | AD127: 0.342 | AE127: 0.362 | AF127: 1.702 | AG127: 0.342 | AH127: 0.31 | AI127: 0.352 | AJ127: 1.653 | AK127: 0.335 | AL127: 0.318 | AM127: 0.348 | AN127: 1.728 | AO127: 2.716 | AP127: 1.868 | AQ127: 0.358 | AR127: 1.699 | AS127: 3.443 | AT127: 2.278 | AU127: 0.365 | AV127: 1.801 | AW127: 3.479 | AX127: 1.442 | AY127: 0.296 | AZ127: 0.339 | BA127: 0.348 | BB127: 1.832 | BC127: 0.351 | BD127: 0.325 | BE127: 0.335 | BF127: 1.958 | BG127: 0.32 | BH127: 0.325 | BI127: 0.344 | BJ127: 1.955 | BK127: 0.282 | BL127: 0.343 | BM127: 1.286 | BN127: 2.655 | BO127: 0.354 | BP127: 0.353 | BQ127: 1.235 | BR127: 2.662 | BS127: 0.357 | BT127: 0.353 | BU127: 1.05 | BV127: 2.412 | BW127: 0.314 | BX127: 0.346 | BY127: 0.331 | BZ127: 0.341 | CA127: 0.344 | CB127: 0.351 | CC127: 0.341 | CD127: 0.339 | CE127: 0.349 | CF127: 0.356 | CG127: 0.337 | CH127: 0.333 | CI127: 0.298 | CJ127: 0.314 | CK127: 0.918 | CL127: 1.54 | CM127: 0.439 | CN127: 0.344 | CO127: 1.009 | CP127: 2.03 | CQ127: 0.517 | CR127: 0.349 | CS127: 0.805 | CT127: 1.503 | CU127: 0.266
A128: 6551 | B128: 2.0807986 | C128: T4 | D128: 0.132 | E128: 0.135 | F128: 1.685 | G128: 0.966 | H128: 0.135 | I128: 0.135 | J128: 1.599 | K128: 1.065 | L128: 0.122 | M128: 0.129 | N128: 1.546 | O128: 0.949 | P128: 1.229 | Q128: 0.98 | R128: 1.27 | S128: 1.21 | T128: 1.869 | U128: 1.491 | V128: 1.167 | W128: 2.83 | X128: 1.957 | Y128: 1.106 | Z128: 1.4 | AA128: 1.575 | AB128: 1.432 | AC128: 0.202 | AD128: 0.214 | AE128: 0.301 | AF128: 1.809 | AG128: 0.202 | AH128: 0.109 | AI128: 0.273 | AJ128: 1.819 | AK128: 0.242 | AL128: 0.106 | AM128: 0.134 | AN128: 1.719 | AO128: OVRFLW | AP128: 1.958 | AQ128: 0.295 | AR128: 1.891 | AS128: 3.64 | AT128: 2.336 | AU128: 0.303 | AV128: 1.922 | AW128: 3.669 | AX128: 1.383 | AY128: 0.151 | AZ128: 0.13 | BA128: 0.232 | BB128: 2.181 | BC128: 0.13 | BD128: 0.244 | BE128: 0.28 | BF128: 2.058 | BG128: 0.247 | BH128: 0.27 | BI128: 0.273 | BJ128: 1.894 | BK128: 0.12 | BL128: 0.14 | BM128: 1.222 | BN128: 2.572 | BO128: 0.289 | BP128: 0.279 | BQ128: 1.087 | BR128: 2.434 | BS128: 0.279 | BT128: 0.304 | BU128: 1.101 | BV128: 2.278 | BW128: 0.139 | BX128: 0.132 | BY128: 0.143 | BZ128: 0.219 | CA128: 0.177 | CB128: 0.165 | CC128: 0.249 | CD128: 0.198 | CE128: 0.18 | CF128: 0.216 | CG128: 0.141 | CH128: 0.132 | CI128: 0.125 | CJ128: 0.127 | CK128: 0.604 | CL128: 1.111 | CM128: 0.27 | CN128: 0.124 | CO128: 0.838 | CP128: 1.783 | CQ128: 0.293 | CR128: 0.125 | CS128: 0.561 | CT128: 1.273 | CU128: 0.348
A129: 6551 | B129: 2.7838657 | C129: T5 | D129: 0.15 | E129: 0.155 | F129: 1.645 | G129: 1.246 | H129: 0.133 | I129: 0.127 | J129: 1.555 | K129: 1.319 | L129: 0.119 | M129: 0.122 | N129: 1.52 | O129: 0.908 | P129: 1.304 | Q129: 2.162 | R129: 1.55 | S129: 1.248 | T129: 1.806 | U129: 2.005 | V129: 1.806 | W129: 3.006 | X129: 1.826 | Y129: 1.452 | Z129: 1.521 | AA129: 1.981 | AB129: 1.395 | AC129: 0.141 | AD129: 0.115 | AE129: 0.151 | AF129: 1.609 | AG129: 0.141 | AH129: 0.109 | AI129: 0.143 | AJ129: 1.431 | AK129: 0.138 | AL129: 0.107 | AM129: 0.13 | AN129: 1.652 | AO129: OVRFLW | AP129: 1.879 | AQ129: 0.166 | AR129: 1.781 | AS129: 3.781 | AT129: 2.571 | AU129: 0.168 | AV129: 1.871 | AW129: 3.827 | AX129: 1.426 | AY129: 0.153 | AZ129: 0.13 | BA129: 0.143 | BB129: 3.387 | BC129: 0.133 | BD129: 0.145 | BE129: 0.142 | BF129: 2.307 | BG129: 0.134 | BH129: 0.141 | BI129: 0.136 | BJ129: 2.814 | BK129: 0.116 | BL129: 0.14 | BM129: 1.454 | BN129: 2.329 | BO129: 0.154 | BP129: 0.164 | BQ129: 1.365 | BR129: 2.215 | BS129: 0.172 | BT129: 0.154 | BU129: 1.277 | BV129: 2.219 | BW129: 0.144 | BX129: 0.132 | BY129: 0.149 | BZ129: 0.137 | CA129: 0.144 | CB129: 0.143 | CC129: 0.144 | CD129: 0.124 | CE129: 0.127 | CF129: 0.144 | CG129: 0.137 | CH129: 0.142 | CI129: 0.124 | CJ129: 0.127 | CK129: 0.621 | CL129: 1.798 | CM129: 0.433 | CN129: 0.129 | CO129: 0.841 | CP129: 1.819 | CQ129: 0.373 | CR129: 0.122 | CS129: 0.573 | CT129: 1.372 | CU129: 0.566
A130: 6551 | B130: 3.0349074 | C130: T6 | D130: 0.196 | E130: 0.229 | F130: 1.722 | G130: 1.04 | H130: 0.17 | I130: 0.132 | J130: 1.576 | K130: 1.468 | L130: 0.191 | M130: 0.217 | N130: 1.629 | O130: 0.967 | P130: 1.536 | Q130: 1.948 | R130: 1.616 | S130: 1.389 | T130: 1.809 | U130: 2.327 | V130: 1.893 | W130: 2.917 | X130: 1.831 | Y130: 1.658 | Z130: 1.662 | AA130: 1.406 | AB130: 1.586 | AC130: 0.212 | AD130: 0.186 | AE130: 0.214 | AF130: 1.65 | AG130: 0.196 | AH130: 0.18 | AI130: 0.208 | AJ130: 1.533 | AK130: 0.193 | AL130: 0.196 | AM130: 0.138 | AN130: 1.594 | AO130: OVRFLW | AP130: 1.948 | AQ130: 0.238 | AR130: 1.869 | AS130: 3.818 | AT130: 2.543 | AU130: 0.25 | AV130: 1.924 | AW130: 3.882 | AX130: 1.904 | AY130: 0.167 | AZ130: 0.193 | BA130: 0.21 | BB130: 2.492 | BC130: 0.197 | BD130: 0.193 | BE130: 0.204 | BF130: 2.433 | BG130: 0.197 | BH130: 0.206 | BI130: 0.208 | BJ130: 3.061 | BK130: 0.119 | BL130: 0.197 | BM130: 1.151 | BN130: 2.34 | BO130: 0.225 | BP130: 0.243 | BQ130: 1.551 | BR130: 2.264 | BS130: 0.237 | BT130: 0.216 | BU130: 1.416 | BV130: 2.316 | BW130: 0.222 | BX130: 0.195 | BY130: 0.221 | BZ130: 0.209 | CA130: 0.211 | CB130: 0.215 | CC130: 0.207 | CD130: 0.206 | CE130: 0.205 | CF130: 0.222 | CG130: 0.239 | CH130: 0.25 | CI130: 0.255 | CJ130: 0.17 | CK130: 0.729 | CL130: 1.917 | CM130: 0.667 | CN130: 0.194 | CO130: 0.627 | CP130: 1.8 | CQ130: 0.633 | CR130: 0.221 | CS130: 0.743 | CT130: 1.271 | CU130: 1.125
A131: 6551 | B131: 5.9722338 | C131: T7 | D131: 0.139 | E131: 0.283 | F131: 1.569 | G131: 3.461 | H131: 0.138 | I131: 0.134 | J131: 1.446 | K131: 2.994 | L131: 0.19 | M131: 0.23 | N131: 1.589 | O131: 1.376 | P131: 1.368 | Q131: 2.553 | R131: 2.062 | S131: 2.221 | T131: 1.79 | U131: 2.963 | V131: 2.405 | W131: 2.646 | X131: 1.738 | Y131: 2.363 | Z131: 1.165 | AA131: 1.646 | AB131: 0.941 | AC131: 0.291 | AD131: 0.258 | AE131: 0.291 | AF131: 1.167 | AG131: 0.281 | AH131: 0.261 | AI131: 0.285 | AJ131: 1.583 | AK131: 0.268 | AL131: 0.257 | AM131: 0.138 | AN131: 0.998 | AO131: OVRFLW | AP131: 2.039 | AQ131: 0.396 | AR131: 1.559 | AS131: 3.669 | AT131: 2.805 | AU131: 0.446 | AV131: 1.427 | AW131: 3.775 | AX131: 0.888 | AY131: 0.252 | AZ131: 0.257 | BA131: 0.288 | BB131: 1.902 | BC131: 0.284 | BD131: 0.27 | BE131: 0.308 | BF131: 2.492 | BG131: 0.285 | BH131: 0.281 | BI131: 0.284 | BJ131: 1.969 | BK131: 0.117 | BL131: 0.245 | BM131: 0.859 | BN131: 2.718 | BO131: 0.337 | BP131: 0.291 | BQ131: 2.106 | BR131: 2.301 | BS131: 0.421 | BT131: 0.283 | BU131: 1.44 | BV131: 2.146 | BW131: 0.289 | BX131: 0.208 | BY131: 0.301 | BZ131: 0.287 | CA131: 0.274 | CB131: 0.284 | CC131: 0.325 | CD131: 0.293 | CE131: 0.281 | CF131: 0.308 | CG131: 0.311 | CH131: 0.329 | CI131: 0.294 | CJ131: 0.127 | CK131: 0.717 | CL131: 1.021 | CM131: 1.317 | CN131: 0.131 | CO131: 0.615 | CP131: 1.847 | CQ131: 1.268 | CR131: 0.178 | CS131: 0.729 | CT131: 0.93 | CU131: 0.888
A132: 6551 | B132: 7.8262269 | C132: T8 | D132: 0.22 | E132: 0.274 | F132: 1.593 | G132: OVRFLW | H132: 0.248 | I132: 0.157 | J132: 1.454 | K132: 2.984 | L132: 0.257 | M132: 0.262 | N132: 1.876 | O132: 1.285 | P132: 1.354 | Q132: 2.708 | R132: 2.015 | S132: 2.136 | T132: 1.613 | U132: 3.183 | V132: 2.332 | W132: 2.631 | X132: 1.673 | Y132: 2.497 | Z132: 1.304 | AA132: 1.7 | AB132: 1.011 | AC132: 0.266 | AD132: 0.235 | AE132: 0.269 | AF132: 1.734 | AG132: 0.271 | AH132: 0.228 | AI132: 0.252 | AJ132: 1.391 | AK132: 0.283 | AL132: 0.241 | AM132: 0.212 | AN132: 1.006 | AO132: 3.522 | AP132: 2.016 | AQ132: 0.459 | AR132: 2.511 | AS132: 3.558 | AT132: 1.911 | AU132: 0.555 | AV132: 2.375 | AW132: 3.663 | AX132: 2.103 | AY132: 0.438 | AZ132: 0.225 | BA132: 0.253 | BB132: 1.929 | BC132: 0.242 | BD132: 0.235 | BE132: 0.249 | BF132: 2.401 | BG132: 0.25 | BH132: 0.26 | BI132: 0.253 | BJ132: 1.67 | BK132: 0.171 | BL132: 0.267 | BM132: 0.976 | BN132: 0.622 | BO132: 0.333 | BP132: 0.253 | BQ132: 1.983 | BR132: 1.942 | BS132: 0.348 | BT132: 0.257 | BU132: 1.422 | BV132: 2.699 | BW132: 0.406 | BX132: 0.235 | BY132: 0.276 | BZ132: 0.26 | CA132: 0.244 | CB132: 0.253 | CC132: 0.268 | CD132: 0.257 | CE132: 0.242 | CF132: 0.256 | CG132: 0.268 | CH132: 0.275 | CI132: 0.27 | CJ132: 0.219 | CK132: 0.624 | CL132: 1.777 | CM132: 1.438 | CN132: 0.273 | CO132: 0.733 | CP132: 1.897 | CQ132: 1.375 | CR132: 0.288 | CS132: 0.738 | CT132: 1.057 | CU132: 0.758
A133: 6593 | B133: 8.1018519e-05 | C133: T0 | D133: 0.109 | E133: 0.22 | F133: 0.192 | G133: 0.161 | H133: 0.132 | I133: 0.11 | J133: 0.111 | K133: 0.114 | L133: 0.163 | M133: 0.114 | N133: 0.15 | O133: 0.115 | P133: 0.142 | Q133: 0.317 | R133: 0.265 | S133: 0.3 | T133: 0.21 | U133: 0.33 | V133: 0.273 | W133: 0.294 | X133: 0.286 | Y133: 0.32 | Z133: 0.267 | AA133: 0.108 | AB133: 0.163 | AC133: 0.293 | AD133: 0.213 | AE133: 0.298 | AF133: 0.32 | AG133: 0.316 | AH133: 0.309 | AI133: 0.309 | AJ133: 0.302 | AK133: 0.292 | AL133: 0.174 | AM133: 0.131 | AN133: 0.137 | AO133: 0.293 | AP133: 0.232 | AQ133: 0.265 | AR133: 0.319 | AS133: 0.309 | AT133: 0.309 | AU133: 0.299 | AV133: 0.314 | AW133: 0.283 | AX133: 0.227 | AY133: 0.109 | AZ133: 0.141 | BA133: 0.285 | BB133: 0.272 | BC133: 0.241 | BD133: 0.301 | BE133: 0.302 | BF133: 0.292 | BG133: 0.309 | BH133: 0.314 | BI133: 0.292 | BJ133: 0.297 | BK133: 0.11 | BL133: 0.113 | BM133: 0.28 | BN133: 0.292 | BO133: 0.267 | BP133: 0.28 | BQ133: 0.274 | BR133: 0.289 | BS133: 0.338 | BT133: 0.289 | BU133: 0.284 | BV133: 0.268 | BW133: 0.109 | BX133: 0.114 | BY133: 0.258 | BZ133: 0.269 | CA133: 0.228 | CB133: 0.26 | CC133: 0.269 | CD133: 0.263 | CE133: 0.289 | CF133: 0.284 | CG133: 0.274 | CH133: 0.241 | CI133: 0.122 | CJ133: 0.11 | CK133: 0.198 | CL133: 0.215 | CM133: 0.185 | CN133: 0.187 | CO133: 0.157 | CP133: 0.249 | CQ133: 0.209 | CR133: 0.226 | CS133: 0.211 | CT133: 0.219 | CU133: 0.113
A134: 6593 | B134: 0.78861111 | C134: T1 | D134: 0.108 | E134: 0.135 | F134: 0.118 | G134: 0.108 | H134: 0.112 | I134: 0.111 | J134: 0.112 | K134: 0.108 | L134: 0.107 | M134: 0.111 | N134: 0.141 | O134: 0.112 | P134: 0.114 | Q134: 0.156 | R134: 0.124 | S134: 0.113 | T134: 0.11 | U134: 0.133 | V134: 0.109 | W134: 0.119 | X134: 0.123 | Y134: 0.147 | Z134: 0.121 | AA134: 0.108 | AB134: 0.124 | AC134: 0.125 | AD134: 0.113 | AE134: 0.128 | AF134: 0.119 | AG134: 0.125 | AH134: 0.122 | AI134: 0.12 | AJ134: 0.129 | AK134: 0.118 | AL134: 0.115 | AM134: 0.105 | AN134: 0.119 | AO134: 0.138 | AP134: 0.115 | AQ134: 0.126 | AR134: 0.13 | AS134: 0.128 | AT134: 0.128 | AU134: 0.126 | AV134: 0.131 | AW134: 0.129 | AX134: 0.118 | AY134: 0.11 | AZ134: 0.117 | BA134: 0.134 | BB134: 0.128 | BC134: 0.126 | BD134: 0.132 | BE134: 0.122 | BF134: 0.129 | BG134: 0.121 | BH134: 0.132 | BI134: 0.122 | BJ134: 0.118 | BK134: 0.11 | BL134: 0.121 | BM134: 0.127 | BN134: 0.13 | BO134: 0.128 | BP134: 0.129 | BQ134: 0.121 | BR134: 0.126 | BS134: 0.134 | BT134: 0.133 | BU134: 0.127 | BV134: 0.131 | BW134: 0.11 | BX134: 0.119 | BY134: 0.129 | BZ134: 0.123 | CA134: 0.127 | CB134: 0.118 | CC134: 0.121 | CD134: 0.117 | CE134: 0.119 | CF134: 0.122 | CG134: 0.131 | CH134: 0.139 | CI134: 0.118 | CJ134: 0.116 | CK134: 0.131 | CL134: 0.124 | CM134: 0.113 | CN134: 0.11 | CO134: 0.111 | CP134: 0.111 | CQ134: 0.111 | CR134: 0.113 | CS134: 0.112 | CT134: 0.124 | CU134: 0.121
A135: 6593 | B135: 1.0293866 | C135: T2 | D135: 0.111 | E135: 0.106 | F135: 0.108 | G135: 0.104 | H135: 0.112 | I135: 0.111 | J135: 0.115 | K135: 0.104 | L135: 0.111 | M135: 0.116 | N135: 0.151 | O135: 0.112 | P135: 0.108 | Q135: 0.15 | R135: 0.115 | S135: 0.133 | T135: 0.116 | U135: 0.138 | V135: 0.113 | W135: 0.125 | X135: 0.131 | Y135: 0.156 | Z135: 0.142 | AA135: 0.11 | AB135: 0.112 | AC135: 0.126 | AD135: 0.126 | AE135: 0.134 | AF135: 0.141 | AG135: 0.128 | AH135: 0.14 | AI135: 0.135 | AJ135: 0.138 | AK135: 0.129 | AL135: 0.131 | AM135: 0.106 | AN135: 0.114 | AO135: 0.132 | AP135: 0.119 | AQ135: 0.135 | AR135: 0.135 | AS135: 0.135 | AT135: 0.131 | AU135: 0.129 | AV135: 0.134 | AW135: 0.134 | AX135: 0.122 | AY135: 0.104 | AZ135: 0.115 | BA135: 0.136 | BB135: 0.133 | BC135: 0.133 | BD135: 0.135 | BE135: 0.129 | BF135: 0.133 | BG135: 0.131 | BH135: 0.139 | BI135: 0.134 | BJ135: 0.129 | BK135: 0.112 | BL135: 0.123 | BM135: 0.144 | BN135: 0.136 | BO135: 0.132 | BP135: 0.137 | BQ135: 0.128 | BR135: 0.133 | BS135: 0.135 | BT135: 0.139 | BU135: 0.13 | BV135: 0.128 | BW135: 0.11 | BX135: 0.111 | BY135: 0.141 | BZ135: 0.136 | CA135: 0.13 | CB135: 0.133 | CC135: 0.134 | CD135: 0.142 | CE135: 0.133 | CF135: 0.125 | CG135: 0.125 | CH135: 0.12 | CI135: 0.113 | CJ135: 0.105 | CK135: 0.105 | CL135: 0.108 | CM135: 0.103 | CN135: 0.111 | CO135: 0.105 | CP135: 0.105 | CQ135: 0.103 | CR135: 0.104 | CS135: 0.102 | CT135: 0.109 | CU135: 0.112
A136: 6593 | B136: 1.8021065 | C136: T3 | D136: 0.212 | E136: 0.245 | F136: 0.234 | G136: 0.244 | H136: 0.222 | I136: 0.145 | J136: 0.173 | K136: 0.244 | L136: 0.281 | M136: 0.314 | N136: 0.366 | O136: 0.346 | P136: 0.214 | Q136: 0.284 | R136: 0.246 | S136: 0.253 | T136: 0.25 | U136: 0.259 | V136: 0.236 | W136: 0.253 | X136: 0.287 | Y136: 0.292 | Z136: 0.298 | AA136: 0.338 | AB136: 0.259 | AC136: 0.25 | AD136: 0.262 | AE136: 0.235 | AF136: 0.266 | AG136: 0.231 | AH136: 0.243 | AI136: 0.241 | AJ136: 0.283 | AK136: 0.242 | AL136: 0.315 | AM136: 0.33 | AN136: 0.281 | AO136: 0.244 | AP136: 0.229 | AQ136: 0.244 | AR136: 0.267 | AS136: 0.236 | AT136: 0.226 | AU136: 0.245 | AV136: 0.273 | AW136: 0.246 | AX136: 0.275 | AY136: 0.329 | AZ136: 0.145 | BA136: 0.245 | BB136: 0.234 | BC136: 0.23 | BD136: 0.269 | BE136: 0.238 | BF136: 0.219 | BG136: 0.23 | BH136: 0.236 | BI136: 0.235 | BJ136: 0.268 | BK136: 0.309 | BL136: 0.21 | BM136: 0.261 | BN136: 0.236 | BO136: 0.225 | BP136: 0.239 | BQ136: 0.207 | BR136: 0.229 | BS136: 0.222 | BT136: 0.263 | BU136: 0.254 | BV136: 0.247 | BW136: 0.258 | BX136: 0.244 | BY136: 0.257 | BZ136: 0.254 | CA136: 0.231 | CB136: 0.239 | CC136: 0.23 | CD136: 0.244 | CE136: 0.236 | CF136: 0.232 | CG136: 0.23 | CH136: 0.239 | CI136: 0.256 | CJ136: 0.249 | CK136: 0.259 | CL136: 0.252 | CM136: 0.273 | CN136: 0.274 | CO136: 0.243 | CP136: 0.238 | CQ136: 0.228 | CR136: 0.229 | CS136: 0.217 | CT136: 0.241 | CU136: 0.242
A137: 6593 | B137: 2.0800116 | C137: T4 | D137: 0.111 | E137: 0.111 | F137: 0.107 | G137: 0.105 | H137: 0.11 | I137: 0.112 | J137: 0.119 | K137: 0.099 | L137: 0.104 | M137: 0.113 | N137: 0.12 | O137: 0.112 | P137: 0.109 | Q137: 0.142 | R137: 0.106 | S137: 0.115 | T137: 0.101 | U137: 0.126 | V137: 0.102 | W137: 0.111 | X137: 0.113 | Y137: 0.13 | Z137: 0.11 | AA137: 0.105 | AB137: 0.115 | AC137: 0.125 | AD137: 0.112 | AE137: 0.12 | AF137: 0.125 | AG137: 0.121 | AH137: 0.114 | AI137: 0.122 | AJ137: 0.122 | AK137: 0.125 | AL137: 0.121 | AM137: 0.111 | AN137: 0.114 | AO137: 0.124 | AP137: 0.11 | AQ137: 0.13 | AR137: 0.122 | AS137: 0.126 | AT137: 0.118 | AU137: 0.119 | AV137: 0.122 | AW137: 0.131 | AX137: 0.105 | AY137: 0.109 | AZ137: 0.112 | BA137: 0.12 | BB137: 0.123 | BC137: 0.123 | BD137: 0.151 | BE137: 0.118 | BF137: 0.122 | BG137: 0.123 | BH137: 0.123 | BI137: 0.131 | BJ137: 0.12 | BK137: 0.107 | BL137: 0.154 | BM137: 0.114 | BN137: 0.125 | BO137: 0.126 | BP137: 0.134 | BQ137: 0.111 | BR137: 0.126 | BS137: 0.122 | BT137: 0.142 | BU137: 0.124 | BV137: 0.125 | BW137: 0.104 | BX137: 0.114 | BY137: 0.12 | BZ137: 0.118 | CA137: 0.116 | CB137: 0.114 | CC137: 0.108 | CD137: 0.114 | CE137: 0.113 | CF137: 0.116 | CG137: 0.116 | CH137: 0.116 | CI137: 0.106 | CJ137: 0.11 | CK137: 0.11 | CL137: 0.099 | CM137: 0.108 | CN137: 0.109 | CO137: 0.104 | CP137: 0.099 | CQ137: 0.112 | CR137: 0.107 | CS137: 0.102 | CT137: 0.115 | CU137: 0.118
A138: 6593 | B138: 2.7859375 | C138: T5 | D138: 0.13 | E138: 0.149 | F138: 0.15 | G138: 0.138 | H138: 0.122 | I138: 0.118 | J138: 0.119 | K138: 0.111 | L138: 0.135 | M138: 0.166 | N138: 0.155 | O138: 0.116 | P138: 0.134 | Q138: 0.179 | R138: 0.159 | S138: 0.143 | T138: 0.129 | U138: 0.175 | V138: 0.136 | W138: 0.141 | X138: 0.167 | Y138: 0.181 | Z138: 0.149 | AA138: 0.114 | AB138: 0.152 | AC138: 0.172 | AD138: 0.146 | AE138: 0.142 | AF138: 0.158 | AG138: 0.144 | AH138: 0.143 | AI138: 0.144 | AJ138: 0.157 | AK138: 0.156 | AL138: 0.162 | AM138: 0.118 | AN138: 0.138 | AO138: 0.17 | AP138: 0.141 | AQ138: 0.152 | AR138: 0.155 | AS138: 0.149 | AT138: 0.143 | AU138: 0.15 | AV138: 0.158 | AW138: 0.152 | AX138: 0.158 | AY138: 0.135 | AZ138: 0.121 | BA138: 0.144 | BB138: 0.153 | BC138: 0.147 | BD138: 0.151 | BE138: 0.147 | BF138: 0.156 | BG138: 0.147 | BH138: 0.153 | BI138: 0.159 | BJ138: 0.153 | BK138: 0.146 | BL138: 0.159 | BM138: 0.15 | BN138: 0.147 | BO138: 0.148 | BP138: 0.168 | BQ138: 0.138 | BR138: 0.144 | BS138: 0.159 | BT138: 0.171 | BU138: 0.162 | BV138: 0.161 | BW138: 0.15 | BX138: 0.151 | BY138: 0.172 | BZ138: 0.152 | CA138: 0.145 | CB138: 0.152 | CC138: 0.146 | CD138: 0.153 | CE138: 0.14 | CF138: 0.152 | CG138: 0.169 | CH138: 0.161 | CI138: 0.168 | CJ138: 0.12 | CK138: 0.148 | CL138: 0.131 | CM138: 0.138 | CN138: 0.132 | CO138: 0.124 | CP138: 0.109 | CQ138: 0.136 | CR138: 0.146 | CS138: 0.153 | CT138: 0.183 | CU138: 0.21
A139: 6593 | B139: 3.043588 | C139: T6 | D139: 0.308 | E139: 0.291 | F139: 0.259 | G139: 0.215 | H139: 0.188 | I139: 0.164 | J139: 0.137 | K139: 0.19 | L139: 0.191 | M139: 0.227 | N139: 0.213 | O139: 0.153 | P139: 0.287 | Q139: 0.286 | R139: 0.242 | S139: 0.228 | T139: 0.22 | U139: 0.232 | V139: 0.222 | W139: 0.207 | X139: 0.232 | Y139: 0.207 | Z139: 0.224 | AA139: 0.158 | AB139: 0.289 | AC139: 0.227 | AD139: 0.239 | AE139: 0.233 | AF139: 0.235 | AG139: 0.213 | AH139: 0.212 | AI139: 0.218 | AJ139: 0.22 | AK139: 0.22 | AL139: 0.224 | AM139: 0.157 | AN139: 0.286 | AO139: 0.222 | AP139: 0.207 | AQ139: 0.202 | AR139: 0.241 | AS139: 0.203 | AT139: 0.206 | AU139: 0.206 | AV139: 0.23 | AW139: 0.207 | AX139: 0.197 | AY139: 0.186 | AZ139: 0.213 | BA139: 0.21 | BB139: 0.208 | BC139: 0.209 | BD139: 0.203 | BE139: 0.208 | BF139: 0.195 | BG139: 0.202 | BH139: 0.216 | BI139: 0.214 | BJ139: 0.213 | BK139: 0.205 | BL139: 0.224 | BM139: 0.233 | BN139: 0.222 | BO139: 0.225 | BP139: 0.252 | BQ139: 0.185 | BR139: 0.227 | BS139: 0.202 | BT139: 0.232 | BU139: 0.213 | BV139: 0.223 | BW139: 0.21 | BX139: 0.234 | BY139: 0.229 | BZ139: 0.231 | CA139: 0.193 | CB139: 0.206 | CC139: 0.198 | CD139: 0.207 | CE139: 0.192 | CF139: 0.204 | CG139: 0.231 | CH139: 0.232 | CI139: 0.209 | CJ139: 0.216 | CK139: 0.235 | CL139: 0.23 | CM139: 0.233 | CN139: 0.239 | CO139: 0.238 | CP139: 0.231 | CQ139: 0.213 | CR139: 0.232 | CS139: 0.222 | CT139: 0.22 | CU139: 0.208
A140: 6593 | B140: 5.9715394 | C140: T7 | D140: 0.137 | E140: 0.231 | F140: 0.132 | G140: 0.101 | H140: 0.108 | I140: 0.108 | J140: 0.107 | K140: 0.093 | L140: 0.101 | M140: 0.168 | N140: 0.156 | O140: 0.11 | P140: 0.179 | Q140: 0.265 | R140: 0.236 | S140: 0.234 | T140: 0.213 | U140: 0.222 | V140: 0.197 | W140: 0.204 | X140: 0.202 | Y140: 0.208 | Z140: 0.191 | AA140: 0.096 | AB140: 0.178 | AC140: 0.263 | AD140: 0.23 | AE140: 0.237 | AF140: 0.231 | AG140: 0.224 | AH140: 0.265 | AI140: 0.211 | AJ140: 0.219 | AK140: 0.206 | AL140: 0.212 | AM140: 0.099 | AN140: 0.137 | AO140: 0.226 | AP140: 0.206 | AQ140: 0.245 | AR140: 0.241 | AS140: 0.221 | AT140: 0.224 | AU140: 0.218 | AV140: 0.234 | AW140: 0.248 | AX140: 0.212 | AY140: 0.104 | AZ140: 0.114 | BA140: 0.249 | BB140: 0.232 | BC140: 0.234 | BD140: 0.223 | BE140: 0.228 | BF140: 0.23 | BG140: 0.217 | BH140: 0.235 | BI140: 0.249 | BJ140: 0.223 | BK140: 0.1 | BL140: 0.111 | BM140: 0.244 | BN140: 0.233 | BO140: 0.232 | BP140: 0.236 | BQ140: 0.214 | BR140: 0.217 | BS140: 0.211 | BT140: 0.241 | BU140: 0.233 | BV140: 0.244 | BW140: 0.177 | BX140: 0.112 | BY140: 0.234 | BZ140: 0.24 | CA140: 0.205 | CB140: 0.223 | CC140: 0.228 | CD140: 0.227 | CE140: 0.208 | CF140: 0.236 | CG140: 0.242 | CH140: 0.237 | CI140: 0.102 | CJ140: 0.108 | CK140: 0.182 | CL140: 0.175 | CM140: 0.166 | CN140: 0.173 | CO140: 0.154 | CP140: 0.134 | CQ140: 0.137 | CR140: 0.162 | CS140: 0.145 | CT140: 0.153 | CU140: 0.108
A141: 6593 | B141: 7.8257176 | C141: T8 | D141: 0.148 | E141: 0.162 | F141: 0.154 | G141: 0.133 | H141: 0.136 | I141: 0.109 | J141: 0.117 | K141: 0.114 | L141: 0.124 | M141: 0.161 | N141: 0.168 | O141: 0.109 | P141: 0.183 | Q141: 0.187 | R141: 0.192 | S141: 0.161 | T141: 0.152 | U141: 0.174 | V141: 0.167 | W141: 0.19 | X141: 0.199 | Y141: 0.204 | Z141: 0.159 | AA141: 0.103 | AB141: 0.189 | AC141: 0.205 | AD141: 0.157 | AE141: 0.161 | AF141: 0.168 | AG141: 0.163 | AH141: 0.159 | AI141: 0.163 | AJ141: 0.169 | AK141: 0.176 | AL141: 0.176 | AM141: 0.107 | AN141: 0.187 | AO141: 0.189 | AP141: 0.161 | AQ141: 0.189 | AR141: 0.166 | AS141: 0.165 | AT141: 0.163 | AU141: 0.162 | AV141: 0.174 | AW141: 0.2 | AX141: 0.165 | AY141: 0.105 | AZ141: 0.155 | BA141: 0.193 | BB141: 0.191 | BC141: 0.167 | BD141: 0.152 | BE141: 0.162 | BF141: 0.171 | BG141: 0.169 | BH141: 0.158 | BI141: 0.199 | BJ141: 0.167 | BK141: 0.105 | BL141: 0.137 | BM141: 0.17 | BN141: 0.166 | BO141: 0.175 | BP141: 0.172 | BQ141: 0.159 | BR141: 0.161 | BS141: 0.165 | BT141: 0.176 | BU141: 0.174 | BV141: 0.179 | BW141: 0.162 | BX141: 0.141 | BY141: 0.164 | BZ141: 0.175 | CA141: 0.161 | CB141: 0.167 | CC141: 0.157 | CD141: 0.161 | CE141: 0.151 | CF141: 0.17 | CG141: 0.171 | CH141: 0.192 | CI141: 0.191 | CJ141: 0.112 | CK141: 0.162 | CL141: 0.152 | CM141: 0.14 | CN141: 0.118 | CO141: 0.106 | CP141: 0.108 | CQ141: 0.108 | CR141: 0.142 | CS141: 0.157 | CT141: 0.192 | CU141: 0.213
A142: 6695 | B142: 8.1018519e-05 | C142: T0 | D142: 0.115 | E142: 0.118 | F142: 0.111 | G142: 0.113 | H142: 0.111 | I142: 0.117 | J142: 0.128 | K142: 0.115 | L142: 0.114 | M142: 0.213 | N142: 0.299 | O142: 0.207 | P142: 0.113 | Q142: 0.127 | R142: 0.112 | S142: 0.189 | T142: 0.116 | U142: 0.167 | V142: 0.126 | W142: 0.17 | X142: 0.242 | Y142: 0.287 | Z142: 0.302 | AA142: 0.224 | AB142: 0.123 | AC142: 0.11 | AD142: 0.157 | AE142: 0.215 | AF142: 0.246 | AG142: 0.208 | AH142: 0.132 | AI142: 0.217 | AJ142: 0.266 | AK142: 0.248 | AL142: 0.114 | AM142: 0.126 | AN142: 0.115 | AO142: 0.191 | AP142: 0.109 | AQ142: 0.211 | AR142: 0.225 | AS142: 0.229 | AT142: 0.216 | AU142: 0.231 | AV142: 0.268 | AW142: 0.248 | AX142: 0.175 | AY142: 0.114 | AZ142: 0.132 | BA142: 0.212 | BB142: 0.212 | BC142: 0.303 | BD142: 0.231 | BE142: 0.221 | BF142: 0.211 | BG142: 0.221 | BH142: 0.242 | BI142: 0.216 | BJ142: 0.316 | BK142: 0.115 | BL142: 0.119 | BM142: 0.213 | BN142: 0.214 | BO142: 0.218 | BP142: 0.212 | BQ142: 0.214 | BR142: 0.118 | BS142: 0.214 | BT142: 0.18 | BU142: 0.235 | BV142: 0.233 | BW142: 0.113 | BX142: 0.115 | BY142: 0.285 | BZ142: 0.221 | CA142: 0.122 | CB142: 0.204 | CC142: 0.207 | CD142: 0.216 | CE142: 0.257 | CF142: 0.215 | CG142: 0.225 | CH142: 0.221 | CI142: 0.12 | CJ142: 0.115 | CK142: 0.112 | CL142: 0.116 | CM142: 0.116 | CN142: 0.115 | CO142: 0.112 | CP142: 0.113 | CQ142: 0.114 | CR142: 0.112 | CS142: 0.113 | CT142: 0.116 | CU142: 0.117
A143: 6695 | B143: 0.78829861 | C143: T1 | D143: 0.117 | E143: 0.127 | F143: 0.102 | G143: 0.102 | H143: 0.113 | I143: 0.123 | J143: 0.113 | K143: 0.118 | L143: 0.117 | M143: 0.125 | N143: 0.126 | O143: 0.21 | P143: 0.12 | Q143: 0.156 | R143: 0.113 | S143: 0.133 | T143: 0.137 | U143: 0.147 | V143: 0.12 | W143: 0.121 | X143: 0.136 | Y143: 0.152 | Z143: 0.114 | AA143: 0.103 | AB143: 0.113 | AC143: 0.131 | AD143: 0.128 | AE143: 0.142 | AF143: 0.147 | AG143: 0.125 | AH143: 0.115 | AI143: 0.12 | AJ143: 0.135 | AK143: 0.129 | AL143: 0.128 | AM143: 0.11 | AN143: 0.111 | AO143: 0.129 | AP143: 0.118 | AQ143: 0.126 | AR143: 0.119 | AS143: 0.127 | AT143: 0.128 | AU143: 0.128 | AV143: 0.132 | AW143: 0.135 | AX143: 0.122 | AY143: 0.12 | AZ143: 0.146 | BA143: 0.129 | BB143: 0.119 | BC143: 0.118 | BD143: 0.145 | BE143: 0.119 | BF143: 0.126 | BG143: 0.135 | BH143: 0.16 | BI143: 0.127 | BJ143: 0.124 | BK143: 0.098 | BL143: 0.127 | BM143: 0.126 | BN143: 0.139 | BO143: 0.12 | BP143: 0.132 | BQ143: 0.13 | BR143: 0.111 | BS143: 0.131 | BT143: 0.148 | BU143: 0.142 | BV143: 0.136 | BW143: 0.119 | BX143: 0.117 | BY143: 0.125 | BZ143: 0.135 | CA143: 0.124 | CB143: 0.121 | CC143: 0.123 | CD143: 0.136 | CE143: 0.121 | CF143: 0.143 | CG143: 0.143 | CH143: 0.168 | CI143: 0.109 | CJ143: 0.113 | CK143: 0.109 | CL143: 0.114 | CM143: 0.113 | CN143: 0.104 | CO143: 0.107 | CP143: 0.111 | CQ143: 0.117 | CR143: 0.122 | CS143: 0.148 | CT143: 0.207 | CU143: 0.14
A144: 6695 | B144: 1.0267708 | C144: T2 | D144: 0.117 | E144: 0.137 | F144: 0.118 | G144: 0.114 | H144: 0.124 | I144: 0.126 | J144: 0.129 | K144: 0.122 | L144: 0.129 | M144: 0.132 | N144: 0.111 | O144: 0.202 | P144: 0.125 | Q144: 0.164 | R144: 0.124 | S144: 0.14 | T144: 0.15 | U144: 0.167 | V144: 0.145 | W144: 0.147 | X144: 0.16 | Y144: 0.17 | Z144: 0.136 | AA144: 0.113 | AB144: 0.138 | AC144: 0.14 | AD144: 0.137 | AE144: 0.151 | AF144: 0.156 | AG144: 0.137 | AH144: 0.145 | AI144: 0.146 | AJ144: 0.156 | AK144: 0.141 | AL144: 0.14 | AM144: 0.11 | AN144: 0.14 | AO144: 0.141 | AP144: 0.129 | AQ144: 0.137 | AR144: 0.138 | AS144: 0.136 | AT144: 0.133 | AU144: 0.137 | AV144: 0.146 | AW144: 0.146 | AX144: 0.142 | AY144: 0.118 | AZ144: 0.145 | BA144: 0.143 | BB144: 0.124 | BC144: 0.133 | BD144: 0.16 | BE144: 0.125 | BF144: 0.134 | BG144: 0.142 | BH144: 0.171 | BI144: 0.133 | BJ144: 0.141 | BK144: 0.095 | BL144: 0.126 | BM144: 0.14 | BN144: 0.148 | BO144: 0.129 | BP144: 0.141 | BQ144: 0.137 | BR144: 0.133 | BS144: 0.131 | BT144: 0.156 | BU144: 0.148 | BV144: 0.146 | BW144: 0.125 | BX144: 0.117 | BY144: 0.143 | BZ144: 0.15 | CA144: 0.138 | CB144: 0.139 | CC144: 0.137 | CD144: 0.151 | CE144: 0.132 | CF144: 0.139 | CG144: 0.163 | CH144: 0.172 | CI144: 0.166 | CJ144: 0.112 | CK144: 0.109 | CL144: 0.113 | CM144: 0.113 | CN144: 0.102 | CO144: 0.104 | CP144: 0.104 | CQ144: 0.116 | CR144: 0.137 | CS144: 0.158 | CT144: 0.201 | CU144: 0.159
... A167: 6699 | B167: 5.970706 | C167: T7 | D167: 0.148 | E167: 0.28 | F167: 0.999 | G167: 3.25 | H167: 0.139 | I167: 0.29 | J167: 1.21 | K167: 1.585 | L167: 0.141 | M167: 0.298 | N167: 0.986 | O167: 1.197 | P167: 2.412 | Q167: 1.44 | R167: 1.317 | S167: 2.543 | T167: 1.775 | U167: 1.973 | V167: 1.034 | W167: 2.55 | X167: 1.888 | Y167: 1.257 | Z167: 1.095 | AA167: 1.732 | AB167: 1.702 | AC167: 1.045 | AD167: 0.167 | AE167: 2.568 | AF167: 2.506 | AG167: 1.306 | AH167: 0.18 | AI167: 2.555 | AJ167: 3.125 | AK167: 0.982 | AL167: 0.158 | AM167: 1.938 | AN167: 1.119 | AO167: 3.202 | AP167: 1.325 | AQ167: 1.081 | AR167: 1.642 | AS167: 3.508 | AT167: 2.709 | AU167: 0.969 | AV167: 1.85 | AW167: 3.408 | AX167: 1.162 | AY167: 0.822 | AZ167: 0.144 | BA167: 2.339 | BB167: 2.202 | BC167: 2.73 | BD167: 0.201 | BE167: 2.595 | BF167: 2.795 | BG167: 2.664 | BH167: 0.211 | BI167: 2.438 | BJ167: 2.231 | BK167: 1.976 | BL167: 0.151 | BM167: 2.221 | BN167: 0.164 | BO167: 1.321 | BP167: 0.188 | BQ167: 1.526 | BR167: 0.178 | BS167: 1.431 | BT167: 0.209 | BU167: 1.938 | BV167: 0.146 | BW167: 1.401 | BX167: 2.513 | BY167: 0.191 | BZ167: 0.862 | CA167: 0.122 | CB167: 2.597 | CC167: 0.171 | CD167: 1.54 | CE167: 0.193 | CF167: 2.249 | CG167: 0.156 | CH167: 0.592 | CI167: 0.142 | CJ167: 0.151 | CK167: 1.083 | CL167: 2.622 | CM167: 0.143 | CN167: 0.148 | CO167: 1.016 | CP167: 1.574 | CQ167: 0.144 | CR167: 0.147 | CS167: 1.113 | CT167: 1.814 | CU167: 0.149
A168: 6699 | B168: 7.8251968 | C168: T8 | D168: 0.145 | E168: 1.107 | F168: 1.036 | G168: 3.64 | H168: 0.188 | I168: 1.173 | J168: 1.454 | K168: 1.676 | L168: 0.177 | M168: 1.202 | N168: 1.267 | O168: 1.736 | P168: 3.613 | Q168: 2.329 | R168: 2.587 | S168: 2.065 | T168: 2.231 | U168: 2.433 | V168: 2.023 | W168: 2.121 | X168: 1.529 | Y168: 1.752 | Z168: 1.698 | AA168: 2.109 | AB168: 3.616 | AC168: 1.971 | AD168: 0.167 | AE168: 2.287 | AF168: 2.232 | AG168: 2.712 | AH168: 0.164 | AI168: 2.813 | AJ168: 1.958 | AK168: 2.002 | AL168: 0.178 | AM168: 3.371 | AN168: 1.151 | AO168: 3.779 | AP168: 1.564 | AQ168: 0.983 | AR168: 1.163 | AS168: 3.452 | AT168: 2.114 | AU168: 0.86 | AV168: 1.52 | AW168: OVRFLW | AX168: 1.789 | AY168: 2.485 | AZ168: 0.143 | BA168: 3.029 | BB168: 2.165 | BC168: 2.214 | BD168: 0.188 | BE168: 2.622 | BF168: 2.827 | BG168: 2.226 | BH168: 0.196 | BI168: 2.324 | BJ168: 1.975 | BK168: 2.582 | BL168: 0.128 | BM168: 1.284 | BN168: 0.206 | BO168: 1.853 | BP168: 0.198 | BQ168: 3.067 | BR168: 0.185 | BS168: 1.99 | BT168: 0.202 | BU168: 2.376 | BV168: 0.219 | BW168: 1.823 | BX168: 2.575 | BY168: 0.278 | BZ168: 1.51 | CA168: 0.197 | CB168: 2.619 | CC168: 0.205 | CD168: 1.357 | CE168: 0.384 | CF168: 2.262 | CG168: 0.235 | CH168: 1.118 | CI168: 0.294 | CJ168: 0.161 | CK168: 0.947 | CL168: 1.851 | CM168: 0.208 | CN168: 0.162 | CO168: 0.84 | CP168: 2.106 | CQ168: 0.16 | CR168: 0.219 | CS168: 0.939 | CT168: 1.388 | CU168: 0.251
A169: 6700 | B169: 8.1018519e-05 | C169: T0 | D169: 0.109 | E169: 0.107 | F169: 0.107 | G169: 0.11 | H169: 0.105 | I169: 0.109 | J169: 0.107 | K169: 0.107 | L169: 0.107 | M169: 0.109 | N169: 0.107 | O169: 0.11 | P169: 0.11 | Q169: 0.129 | R169: 0.107 | S169: 0.107 | T169: 0.11 | U169: 0.128 | V169: 0.107 | W169: 0.106 | X169: 0.111 | Y169: 0.129 | Z169: 0.108 | AA169: 0.123 | AB169: 0.156 | AC169: 0.11 | AD169: 0.114 | AE169: 0.124 | AF169: 0.172 | AG169: 0.107 | AH169: 0.114 | AI169: 0.111 | AJ169: 0.203 | AK169: 0.105 | AL169: 0.116 | AM169: 0.11 | AN169: 0.124 | AO169: 0.111 | AP169: 0.108 | AQ169: 0.113 | AR169: 0.117 | AS169: 0.138 | AT169: 0.116 | AU169: 0.111 | AV169: 0.122 | AW169: 0.11 | AX169: 0.107 | AY169: 0.106 | AZ169: 0.111 | BA169: 0.111 | BB169: 0.108 | BC169: 0.11 | BD169: 0.122 | BE169: 0.11 | BF169: 0.11 | BG169: 0.111 | BH169: 0.124 | BI169: 0.109 | BJ169: 0.109 | BK169: 0.107 | BL169: 0.113 | BM169: 0.106 | BN169: 0.11 | BO169: 0.108 | BP169: 0.111 | BQ169: 0.107 | BR169: 0.162 | BS169: 0.111 | BT169: 0.115 | BU169: 0.106 | BV169: 0.109 | BW169: 0.107 | BX169: 0.116 | BY169: 0.111 | BZ169: 0.111 | CA169: 0.12 | CB169: 0.112 | CC169: 0.108 | CD169: 0.114 | CE169: 0.125 | CF169: 0.108 | CG169: 0.105 | CH169: 0.11 | CI169: 0.138 | CJ169: 0.11 | CK169: 0.113 | CL169: 0.11 | CM169: 0.108 | CN169: 0.11 | CO169: 0.113 | CP169: 0.113 | CQ169: 0.111 | CR169: 0.107 | CS169: 0.11 | CT169: 0.107 | CU169: 0.111
A170: 6700 | B170: 0.78790509 | C170: T1 | D170: 0.121 | E170: 1.003 | F170: 0.121 | G170: 0.123 | H170: 0.119 | I170: 0.991 | J170: 0.12 | K170: 0.118 | L170: 0.124 | M170: 1.169 | N170: 0.121 | O170: 0.122 | P170: 0.235 | Q170: 0.531 | R170: 1.25 | S170: 0.134 | T170: 0.239 | U170: 0.544 | V170: 1.314 | W170: 0.127 | X170: 0.285 | Y170: 0.632 | Z170: 1.413 | AA170: 0.153 | AB170: 0.254 | AC170: 0.116 | AD170: 0.111 | AE170: 0.14 | AF170: 0.286 | AG170: 0.115 | AH170: 0.118 | AI170: 0.128 | AJ170: 0.288 | AK170: 0.119 | AL170: 0.11 | AM170: 0.119 | AN170: 0.182 | AO170: 1.222 | AP170: 0.117 | AQ170: 0.173 | AR170: 0.178 | AS170: 1.152 | AT170: 0.126 | AU170: 0.177 | AV170: 0.186 | AW170: 0.976 | AX170: 0.115 | AY170: 0.161 | AZ170: 0.124 | BA170: 1.525 | BB170: 0.129 | BC170: 0.124 | BD170: 0.134 | BE170: 1.562 | BF170: 0.124 | BG170: 0.137 | BH170: 0.136 | BI170: 1.602 | BJ170: 0.124 | BK170: 0.12 | BL170: 0.145 | BM170: 0.14 | BN170: 0.132 | BO170: 0.165 | BP170: 0.155 | BQ170: 0.13 | BR170: 0.136 | BS170: 0.146 | BT170: 0.154 | BU170: 0.128 | BV170: 0.123 | BW170: 0.142 | BX170: 0.247 | BY170: 0.356 | BZ170: 0.124 | CA170: 0.124 | CB170: 0.328 | CC170: 0.348 | CD170: 0.117 | CE170: 0.122 | CF170: 0.274 | CG170: 0.314 | CH170: 0.114 | CI170: 0.12 | CJ170: 1.17 | CK170: 0.843 | CL170: 0.118 | CM170: 0.119 | CN170: 1.098 | CO170: 0.825 | CP170: 0.121 | CQ170: 0.125 | CR170: 1.013 | CS170: 0.748 | CT170: 0.117 | CU170: 0.121
A171: 6700 | B171: 1.0177546 | C171: T2 | D171: 0.123 | E171: 1.764 | F171: 0.118 | G171: 0.115 | H171: 0.115 | I171: 1.693 | J171: 0.124 | K171: 0.126 | L171: 0.128 | M171: 1.932 | N171: 0.193 | O171: 0.137 | P171: 0.348 | Q171: 1.324 | R171: 1.754 | S171: 0.211 | T171: 0.413 | U171: 1.226 | V171: 1.834 | W171: 0.176 | X171: 0.455 | Y171: 1.287 | Z171: 2.038 | AA171: 0.208 | AB171: 0.444 | AC171: 0.141 | AD171: 0.137 | AE171: 0.177 | AF171: 0.408 | AG171: 0.143 | AH171: 0.146 | AI171: 0.152 | AJ171: 0.438 | AK171: 0.146 | AL171: 0.161 | AM171: 0.157 | AN171: 0.218 | AO171: 1.375 | AP171: 0.144 | AQ171: 0.227 | AR171: 0.261 | AS171: 1.484 | AT171: 0.145 | AU171: 0.226 | AV171: 0.248 | AW171: 1.826 | AX171: 0.148 | AY171: 0.207 | AZ171: 0.127 | BA171: 1.812 | BB171: 0.155 | BC171: 0.153 | BD171: 0.16 | BE171: 2.066 | BF171: 0.143 | BG171: 0.16 | BH171: 0.152 | BI171: 1.847 | BJ171: 0.157 | BK171: 0.133 | BL171: 0.151 | BM171: 0.144 | BN171: 0.154 | BO171: 0.206 | BP171: 0.182 | BQ171: 0.16 | BR171: 0.165 | BS171: 0.196 | BT171: 0.174 | BU171: 0.152 | BV171: 0.154 | BW171: 0.18 | BX171: 0.294 | BY171: 0.62 | BZ171: 0.153 | CA171: 0.153 | CB171: 0.553 | CC171: 0.706 | CD171: 0.123 | CE171: 0.143 | CF171: 0.485 | CG171: 0.66 | CH171: 0.14 | CI171: 0.146 | CJ171: 1.902 | CK171: 0.934 | CL171: 0.122 | CM171: 0.122 | CN171: 1.87 | CO171: 0.818 | CP171: 0.125 | CQ171: 0.128 | CR171: 1.996 | CS171: 0.781 | CT171: 0.123 | CU171: 0.125
A172: 6700 | B172: 1.8020486 | C172: T3 | D172: 0.184 | E172: 2.85 | F172: 0.256 | G172: 0.258 | H172: 0.284 | I172: 2.673 | J172: 0.304 | K172: 0.3 | L172: 0.301 | M172: 2.586 | N172: 0.296 | O172: 0.261 | P172: 1.306 | Q172: 2.822 | R172: 2.837 | S172: 0.355 | T172: 1.232 | U172: 2.74 | V172: 2.377 | W172: 0.343 | X172: 1.466 | Y172: 2.736 | Z172: 2.251 | AA172: 0.278 | AB172: 0.705 | AC172: 0.26 | AD172: 0.263 | AE172: 0.32 | AF172: 0.806 | AG172: 0.261 | AH172: 0.281 | AI172: 0.278 | AJ172: 0.76 | AK172: 0.265 | AL172: 0.285 | AM172: 0.307 | AN172: 0.773 | AO172: 2.719 | AP172: 0.257 | AQ172: 0.866 | AR172: 0.751 | AS172: 2.788 | AT172: 0.251 | AU172: 0.872 | AV172: 0.704 | AW172: 2.887 | AX172: 0.27 | AY172: 0.788 | AZ172: 0.243 | BA172: 2.671 | BB172: 0.268 | BC172: 0.288 | BD172: 0.291 | BE172: 2.754 | BF172: 0.235 | BG172: 0.275 | BH172: 0.256 | BI172: 2.422 | BJ172: 0.284 | BK172: 0.289 | BL172: 0.275 | BM172: 0.323 | BN172: 0.291 | BO172: 0.45 | BP172: 0.354 | BQ172: 0.311 | BR172: 0.318 | BS172: 0.509 | BT172: 0.295 | BU172: 0.277 | BV172: 0.271 | BW172: 0.418 | BX172: 1.228 | BY172: 1.674 | BZ172: 0.286 | CA172: 0.299 | CB172: 1.515 | CC172: 1.723 | CD172: 0.306 | CE172: 0.267 | CF172: 1.387 | CG172: 1.683 | CH172: 0.259 | CI172: 0.285 | CJ172: 2.831 | CK172: 1.308 | CL172: 0.287 | CM172: 0.21 | CN172: 2.753 | CO172: 0.936 | CP172: 0.137 | CQ172: 0.136 | CR172: 2.991 | CS172: 1.045 | CT172: 0.188 | CU172: 0.268
A173: 6700 | B173: 2.077338 | C173: T4 | D173: 0.119 | E173: 2.786 | F173: 0.128 | G173: 0.126 | H173: 0.126 | I173: 2.477 | J173: 0.139 | K173: 0.128 | L173: 0.132 | M173: 2.412 | N173: 0.13 | O173: 0.129 | P173: 1.167 | Q173: 2.744 | R173: 2.731 | S173: 0.192 | T173: 1.28 | U173: 2.772 | V173: 2.474 | W173: 0.223 | X173: 1.395 | Y173: 2.707 | Z173: 2.184 | AA173: 0.159 | AB173: 0.603 | AC173: 0.12 | AD173: 0.213 | AE173: 0.271 | AF173: 0.782 | AG173: 0.256 | AH173: 0.272 | AI173: 0.259 | AJ173: 0.772 | AK173: 0.212 | AL173: 0.114 | AM173: 0.127 | AN173: 0.655 | AO173: 2.743 | AP173: 0.159 | AQ173: 1.006 | AR173: 0.804 | AS173: 2.705 | AT173: 0.257 | AU173: 1.005 | AV173: 0.784 | AW173: 2.683 | AX173: 0.123 | AY173: 0.643 | AZ173: 0.131 | BA173: 2.633 | BB173: 0.241 | BC173: 0.265 | BD173: 0.171 | BE173: 3.111 | BF173: 0.24 | BG173: 0.274 | BH173: 0.249 | BI173: 2.44 | BJ173: 0.136 | BK173: 0.13 | BL173: 0.184 | BM173: 0.141 | BN173: 0.211 | BO173: 0.444 | BP173: 0.245 | BQ173: 0.264 | BR173: 0.159 | BS173: 0.471 | BT173: 0.27 | BU173: 0.156 | BV173: 0.14 | BW173: 0.286 | BX173: 1.359 | BY173: 1.483 | BZ173: 0.122 | CA173: 0.126 | CB173: 1.652 | CC173: 1.538 | CD173: 0.116 | CE173: 0.13 | CF173: 1.545 | CG173: 1.531 | CH173: 0.132 | CI173: 0.145 | CJ173: 2.663 | CK173: 1.141 | CL173: 0.14 | CM173: 0.128 | CN173: 2.749 | CO173: 0.937 | CP173: 0.14 | CQ173: 0.134 | CR173: 3.005 | CS173: 1.029 | CT173: 0.154 | CU173: 0.152
A174: 6700 | B174: 2.7833565 | C174: T5 | D174: 0.123 | E174: 2.923 | F174: 0.146 | G174: 0.138 | H174: 0.128 | I174: 2.912 | J174: 0.153 | K174: 0.131 | L174: 0.131 | M174: 2.509 | N174: 0.131 | O174: 0.133 | P174: 1.554 | Q174: 2.961 | R174: 2.965 | S174: 0.22 | T174: 1.713 | U174: 2.993 | V174: 2.771 | W174: 0.223 | X174: 1.572 | Y174: 2.732 | Z174: 2.228 | AA174: 0.184 | AB174: 0.957 | AC174: 0.128 | AD174: 0.113 | AE174: 0.158 | AF174: 1.046 | AG174: 0.128 | AH174: 0.115 | AI174: 0.139 | AJ174: 0.953 | AK174: 0.118 | AL174: 0.11 | AM174: 0.135 | AN174: 1.065 | AO174: 2.751 | AP174: 0.121 | AQ174: 1.281 | AR174: 0.926 | AS174: 2.844 | AT174: 0.134 | AU174: 1.281 | AV174: 0.935 | AW174: 2.758 | AX174: 0.121 | AY174: 1.157 | AZ174: 0.13 | BA174: 2.898 | BB174: 0.139 | BC174: 0.148 | BD174: 0.153 | BE174: 3.181 | BF174: 0.134 | BG174: 0.156 | BH174: 0.144 | BI174: 2.775 | BJ174: 0.136 | BK174: 0.141 | BL174: 0.173 | BM174: 0.142 | BN174: 0.136 | BO174: 0.496 | BP174: 0.16 | BQ174: 0.149 | BR174: 0.149 | BS174: 0.792 | BT174: 0.164 | BU174: 0.154 | BV174: 0.138 | BW174: 0.982 | BX174: 2.672 | BY174: 1.689 | BZ174: 0.113 | CA174: 0.125 | CB174: 2.542 | CC174: 1.577 | CD174: 0.117 | CE174: 0.129 | CF174: 2.398 | CG174: 1.612 | CH174: 0.131 | CI174: 0.133 | CJ174: 2.669 | CK174: 1.205 | CL174: 0.152 | CM174: 0.131 | CN174: 2.876 | CO174: 1.01 | CP174: 0.153 | CQ174: 0.135 | CR174: 2.704 | CS174: 1.095 | CT174: 0.15 | CU174: 0.149
A175: 6700 | B175: 3.0397917 | C175: T6 | D175: 0.125 | E175: 3.358 | F175: 0.164 | G175: 0.153 | H175: 0.157 | I175: 2.529 | J175: 0.204 | K175: 0.203 | L175: 0.232 | M175: 2.625 | N175: 0.266 | O175: 0.264 | P175: 1.536 | Q175: 2.995 | R175: 3.183 | S175: 0.328 | T175: 1.921 | U175: 3.084 | V175: 3.411 | W175: 0.267 | X175: 1.627 | Y175: 2.822 | Z175: 2.66 | AA175: 0.31 | AB175: 0.947 | AC175: 0.173 | AD175: 0.159 | AE175: 0.222 | AF175: 1.194 | AG175: 0.165 | AH175: 0.165 | AI175: 0.185 | AJ175: 1.183 | AK175: 0.169 | AL175: 0.18 | AM175: 0.222 | AN175: 1.071 | AO175: 2.92 | AP175: 0.178 | AQ175: 1.467 | AR175: 1.032 | AS175: 2.967 | AT175: 0.167 | AU175: 1.461 | AV175: 1.014 | AW175: 2.875 | AX175: 0.182 | AY175: 1.315 | AZ175: 0.132 | BA175: 3.121 | BB175: 0.193 | BC175: 0.186 | BD175: 0.18 | BE175: 3.296 | BF175: 0.158 | BG175: 0.198 | BH175: 0.178 | BI175: 2.613 | BJ175: 0.179 | BK175: 0.203 | BL175: 0.132 | BM175: 0.222 | BN175: 0.176 | BO175: 0.983 | BP175: 0.234 | BQ175: 0.188 | BR175: 0.19 | BS175: 1.027 | BT175: 0.199 | BU175: 0.196 | BV175: 0.182 | BW175: 1.048 | BX175: 2.385 | BY175: 1.914 | BZ175: 0.174 | CA175: 0.176 | CB175: 2.702 | CC175: 1.597 | CD175: 0.12 | CE175: 0.16 | CF175: 2.491 | CG175: 1.651 | CH175: 0.158 | CI175: 0.194 | CJ175: 2.725 | CK175: 1.25 | CL175: 0.174 | CM175: 0.132 | CN175: 2.728 | CO175: 1.015 | CP175: 0.159 | CQ175: 0.136 | CR175: 2.713 | CS175: 1.079 | CT175: 0.15 | CU175: 0.132
...

Sheet strain_names
A1: strain_number | B1: name
A2: 6146 | B2: Variovorax
A3: 6147 | B3: Flavobacterium
A4: 6150 | B4: Microbacterium
A5: 6152 | B5: Mucilaginibacter
A6: 6477 | B6: Rhodococcus
A7: 6483 | B7: Cellulomonas
A8: 6500 | B8: Luteibacter
A9: 6519 | B9: Mesorhizobium
A10: 6533 | B10: Pseudomonas2
A11: 6551 | B11: Pseudomonas1
A12: 6699 | B12: Burkholderia
A13: 6700 | B13: Rahnella
A14: spr | B14: Chitinophaga
A15: 6155 | B15: Curtobacterium
A16: 6478 | B16: Bradyrhizobium
A17: 6508 | B17: Phenylobacterium
A18: 6525 | B18: Lysobacter
A19: 6537 | B19: Caulobacter
A20: 6593 | B20: Devosia
A21: 6695 | B21: Cohnella
A22: 6697 | B22: Tardiphaga

Sheet Parameters from R
